nohup: ignoring input
[16-Aug-25 03:43:07 - INFO] - ZeMusic.core.mongo - يتم رفع البيانات...
[16-Aug-25 03:43:07 - INFO] - ZeMusic.core.mongo - تم رفع البيانات.
[16-Aug-25 03:43:07 - INFO] - ZeMusic.core.dir - تم اكتمال التحميل.
[16-Aug-25 03:43:07 - INFO] - ZeMusic.core.git - Git Client Found [VPS DEPLOYER]
[16-Aug-25 03:43:07 - INFO] - ZeMusic.misc - Local Database Initialized.
[16-Aug-25 03:43:07 - INFO] - ZeMusic.core.bot - يتم تشغيل البوت..
[16-Aug-25 03:43:07 - INFO] - __main__ - 🚀 بدء إعداد PostgreSQL تلقائياً...
[16-Aug-25 03:43:07 - INFO] - __main__ - 🔍 التحقق من تثبيت PostgreSQL...
[16-Aug-25 03:43:07 - INFO] - __main__ - ⚡ بدء تشغيل PostgreSQL...
[16-Aug-25 03:43:07 - INFO] - __main__ - ✅ تم بدء تشغيل PostgreSQL
[16-Aug-25 03:43:07 - INFO] - __main__ - 🔐 إعداد كلمة مرور للمستخدم postgres...
[16-Aug-25 03:43:07 - INFO] - __main__ - ℹ️ كلمة مرور PostgreSQL موجودة بالفعل
[16-Aug-25 03:43:07 - INFO] - __main__ - 🗄️ التحقق من وجود قاعدة البيانات...
[16-Aug-25 03:43:07 - INFO] - __main__ - ℹ️ قاعدة البيانات zemusic_bot موجودة بالفعل
[16-Aug-25 03:43:07 - INFO] - __main__ - ⚙️ إعداد قاعدة بيانات PostgreSQL...
[16-Aug-25 03:43:07 - INFO] - ZeMusic.database.setup - بدء إعداد قاعدة البيانات...
[16-Aug-25 03:43:07 - INFO] - ZeMusic.database.setup - قاعدة البيانات موجودة بالفعل
[16-Aug-25 03:43:07 - INFO] - ZeMusic.core.postgres - يتم الاتصال بقاعدة بيانات PostgreSQL...
[16-Aug-25 03:43:08 - INFO] - ZeMusic.core.postgres - تم الاتصال بنجاح - PostgreSQL: PostgreSQL 17.5 (Ubuntu 17.5-0ubuntu0.25.04.1) on x86_64-pc-linux-gnu, compiled by gcc (Ubuntu 14.2.0-19ubuntu2) 14.2.0, 64-bit
[16-Aug-25 03:43:08 - INFO] - ZeMusic.database.setup - CREATE TABLE
CREATE TABLE
CREATE TABLE
CREATE TABLE
CREATE TABLE
CREATE TABLE
CREATE TABLE
CREATE TABLE
CREATE TABLE
CREATE TABLE
CREATE TABLE
CREATE TABLE
CREATE TABLE
CREATE TABLE
CREATE INDEX
CREATE INDEX
CREATE INDEX
CREATE INDEX
CREATE INDEX
CREATE INDEX
CREATE INDEX
CREATE INDEX
CREATE INDEX
CREATE INDEX
CREATE INDEX
CREATE INDEX
CREATE INDEX
CREATE INDEX
CREATE INDEX
CREATE INDEX
CREATE INDEX
CREATE INDEX
CREATE INDEX
CREATE INDEX
CREATE INDEX
CREATE INDEX
CREATE INDEX
CREATE INDEX
CREATE INDEX
INSERT 0 0
INSERT 0 0
CREATE FUNCTION
CREATE FUNCTION
CREATE FUNCTION
[16-Aug-25 03:43:08 - INFO] - ZeMusic.database.setup - تم تنفيذ ملف SQL بنجاح: /workspace/database_schema.sql
[16-Aug-25 03:43:08 - INFO] - ZeMusic.database.setup - تم إنشاء جدول audio_cache بنجاح
[16-Aug-25 03:43:08 - INFO] - ZeMusic.database.setup - تم إنشاء جدول search_history بنجاح
[16-Aug-25 03:43:08 - INFO] - ZeMusic.database.setup - تم إنشاء جدول download_stats بنجاح
[16-Aug-25 03:43:08 - INFO] - ZeMusic.database.setup - تم إنشاء جدول cache_metrics بنجاح
[16-Aug-25 03:43:08 - INFO] - ZeMusic.database.setup - تم إنشاء جدول popular_content بنجاح
[16-Aug-25 03:43:08 - INFO] - ZeMusic.database.setup - تم إنشاء جميع جداول التحميل بنجاح
[16-Aug-25 03:43:08 - INFO] - ZeMusic.database.setup - تم إدراج البيانات الأولية بنجاح
[16-Aug-25 03:43:08 - INFO] - ZeMusic.database.setup - تم التحقق من سلامة قاعدة البيانات بنجاح
[16-Aug-25 03:43:08 - INFO] - ZeMusic.database.setup - تم إعداد قاعدة البيانات بنجاح! ✅
[16-Aug-25 03:43:08 - INFO] - ZeMusic.database.migrations - لا توجد تحديثات معلقة
[16-Aug-25 03:43:08 - INFO] - __main__ - ✅ تم إعداد PostgreSQL بنجاح
[16-Aug-25 03:43:08 - INFO] - ZeMusic.misc - تم رفع البيانات.
[16-Aug-25 03:43:10 - INFO] - ZeMusic.core.bot - تم تسغيل 𝐋𝐎𝐋  بنجاح..
[16-Aug-25 03:43:10 - INFO] - ZeMusic.plugins - تنزيل معلومات السورس...
[16-Aug-25 03:43:10 - INFO] - ZeMusic.core.userbot - جلب معلومات السورس...
[16-Aug-25 03:43:12 - INFO] - ZeMusic.core.userbot - تم تشغيل المساعد <a href=tg://user?id=5929114274>الحساب المساعد ♫</a> على سورس الملك
[16-Aug-25 03:43:12 - INFO] - ZeMusic.core.call - Starting PyTgCalls Client...

[16-Aug-25 03:43:39 - ERROR] - asyncio - Task exception was never retrieved
future: <Task finished name='Task-301' coro=<Client.handle_updates() done, defined at /workspace/venv/lib/python3.13/site-packages/pyrogram/client.py:535> exception=ValueError('Peer id invalid: -1002725376687')>
Traceback (most recent call last):
  File "/workspace/venv/lib/python3.13/site-packages/pyrogram/methods/advanced/resolve_peer.py", line 62, in resolve_peer
    return await self.storage.get_peer_by_id(peer_id)
           ^^^^^^^^^^^^^^^^^^^^^^^^^^^^^^^^^^^^^^^^^^
  File "/workspace/venv/lib/python3.13/site-packages/pyrogram/storage/sqlite_storage.py", line 142, in get_peer_by_id
    raise KeyError(f"ID not found: {peer_id}")
KeyError: 'ID not found: -1002725376687'

During handling of the above exception, another exception occurred:

Traceback (most recent call last):
  File "/workspace/venv/lib/python3.13/site-packages/pyrogram/client.py", line 569, in handle_updates
    channel=await self.resolve_peer(utils.get_channel_id(channel_id)),
            ^^^^^^^^^^^^^^^^^^^^^^^^^^^^^^^^^^^^^^^^^^^^^^^^^^^^^^^^^
  File "/workspace/venv/lib/python3.13/site-packages/pyrogram/methods/advanced/resolve_peer.py", line 89, in resolve_peer
    peer_type = utils.get_peer_type(peer_id)
  File "/workspace/venv/lib/python3.13/site-packages/pyrogram/utils.py", line 246, in get_peer_type
    raise ValueError(f"Peer id invalid: {peer_id}")
ValueError: Peer id invalid: -1002725376687
[16-Aug-25 03:43:43 - INFO] - ZeMusic.core.call - تم تهيئة PyTgCalls بدون decorators
[16-Aug-25 03:43:43 - INFO] - ZeMusic - جاري تشغيل البوت
تم التنصيب على سورس الملك بنجاح
قناة السورس https://t.me/EF_19
[16-Aug-25 03:43:51 - ERROR] - asyncio - Task exception was never retrieved
future: <Task finished name='Task-317' coro=<Client.handle_updates() done, defined at /workspace/venv/lib/python3.13/site-packages/pyrogram/client.py:535> exception=ValueError('Peer id invalid: -1002475315714')>
Traceback (most recent call last):
  File "/workspace/venv/lib/python3.13/site-packages/pyrogram/methods/advanced/resolve_peer.py", line 62, in resolve_peer
    return await self.storage.get_peer_by_id(peer_id)
           ^^^^^^^^^^^^^^^^^^^^^^^^^^^^^^^^^^^^^^^^^^
  File "/workspace/venv/lib/python3.13/site-packages/pyrogram/storage/sqlite_storage.py", line 142, in get_peer_by_id
    raise KeyError(f"ID not found: {peer_id}")
KeyError: 'ID not found: -1002475315714'

During handling of the above exception, another exception occurred:

Traceback (most recent call last):
  File "/workspace/venv/lib/python3.13/site-packages/pyrogram/client.py", line 569, in handle_updates
    channel=await self.resolve_peer(utils.get_channel_id(channel_id)),
            ^^^^^^^^^^^^^^^^^^^^^^^^^^^^^^^^^^^^^^^^^^^^^^^^^^^^^^^^^
  File "/workspace/venv/lib/python3.13/site-packages/pyrogram/methods/advanced/resolve_peer.py", line 89, in resolve_peer
    peer_type = utils.get_peer_type(peer_id)
  File "/workspace/venv/lib/python3.13/site-packages/pyrogram/utils.py", line 246, in get_peer_type
    raise ValueError(f"Peer id invalid: {peer_id}")
ValueError: Peer id invalid: -1002475315714
[16-Aug-25 03:44:18 - ERROR] - asyncio - Task exception was never retrieved
future: <Task finished name='Task-350' coro=<Client.handle_updates() done, defined at /workspace/venv/lib/python3.13/site-packages/pyrogram/client.py:535> exception=ValueError('Peer id invalid: -1002725376687')>
Traceback (most recent call last):
  File "/workspace/venv/lib/python3.13/site-packages/pyrogram/methods/advanced/resolve_peer.py", line 62, in resolve_peer
    return await self.storage.get_peer_by_id(peer_id)
           ^^^^^^^^^^^^^^^^^^^^^^^^^^^^^^^^^^^^^^^^^^
  File "/workspace/venv/lib/python3.13/site-packages/pyrogram/storage/sqlite_storage.py", line 142, in get_peer_by_id
    raise KeyError(f"ID not found: {peer_id}")
KeyError: 'ID not found: -1002725376687'

During handling of the above exception, another exception occurred:

Traceback (most recent call last):
  File "/workspace/venv/lib/python3.13/site-packages/pyrogram/client.py", line 569, in handle_updates
    channel=await self.resolve_peer(utils.get_channel_id(channel_id)),
            ^^^^^^^^^^^^^^^^^^^^^^^^^^^^^^^^^^^^^^^^^^^^^^^^^^^^^^^^^
  File "/workspace/venv/lib/python3.13/site-packages/pyrogram/methods/advanced/resolve_peer.py", line 89, in resolve_peer
    peer_type = utils.get_peer_type(peer_id)
  File "/workspace/venv/lib/python3.13/site-packages/pyrogram/utils.py", line 246, in get_peer_type
    raise ValueError(f"Peer id invalid: {peer_id}")
ValueError: Peer id invalid: -1002725376687
[16-Aug-25 03:44:21 - ERROR] - asyncio - Task exception was never retrieved
future: <Task finished name='Task-355' coro=<Client.handle_updates() done, defined at /workspace/venv/lib/python3.13/site-packages/pyrogram/client.py:535> exception=ValueError('Peer id invalid: -1002725376687')>
Traceback (most recent call last):
  File "/workspace/venv/lib/python3.13/site-packages/pyrogram/methods/advanced/resolve_peer.py", line 62, in resolve_peer
    return await self.storage.get_peer_by_id(peer_id)
           ^^^^^^^^^^^^^^^^^^^^^^^^^^^^^^^^^^^^^^^^^^
  File "/workspace/venv/lib/python3.13/site-packages/pyrogram/storage/sqlite_storage.py", line 142, in get_peer_by_id
    raise KeyError(f"ID not found: {peer_id}")
KeyError: 'ID not found: -1002725376687'

During handling of the above exception, another exception occurred:

Traceback (most recent call last):
  File "/workspace/venv/lib/python3.13/site-packages/pyrogram/client.py", line 569, in handle_updates
    channel=await self.resolve_peer(utils.get_channel_id(channel_id)),
            ^^^^^^^^^^^^^^^^^^^^^^^^^^^^^^^^^^^^^^^^^^^^^^^^^^^^^^^^^
  File "/workspace/venv/lib/python3.13/site-packages/pyrogram/methods/advanced/resolve_peer.py", line 89, in resolve_peer
    peer_type = utils.get_peer_type(peer_id)
  File "/workspace/venv/lib/python3.13/site-packages/pyrogram/utils.py", line 246, in get_peer_type
    raise ValueError(f"Peer id invalid: {peer_id}")
ValueError: Peer id invalid: -1002725376687
[16-Aug-25 03:44:22 - ERROR] - asyncio - Task exception was never retrieved
future: <Task finished name='Task-358' coro=<Client.handle_updates() done, defined at /workspace/venv/lib/python3.13/site-packages/pyrogram/client.py:535> exception=ValueError('Peer id invalid: -1002725376687')>
Traceback (most recent call last):
  File "/workspace/venv/lib/python3.13/site-packages/pyrogram/methods/advanced/resolve_peer.py", line 62, in resolve_peer
    return await self.storage.get_peer_by_id(peer_id)
           ^^^^^^^^^^^^^^^^^^^^^^^^^^^^^^^^^^^^^^^^^^
  File "/workspace/venv/lib/python3.13/site-packages/pyrogram/storage/sqlite_storage.py", line 142, in get_peer_by_id
    raise KeyError(f"ID not found: {peer_id}")
KeyError: 'ID not found: -1002725376687'

During handling of the above exception, another exception occurred:

Traceback (most recent call last):
  File "/workspace/venv/lib/python3.13/site-packages/pyrogram/client.py", line 569, in handle_updates
    channel=await self.resolve_peer(utils.get_channel_id(channel_id)),
            ^^^^^^^^^^^^^^^^^^^^^^^^^^^^^^^^^^^^^^^^^^^^^^^^^^^^^^^^^
  File "/workspace/venv/lib/python3.13/site-packages/pyrogram/methods/advanced/resolve_peer.py", line 89, in resolve_peer
    peer_type = utils.get_peer_type(peer_id)
  File "/workspace/venv/lib/python3.13/site-packages/pyrogram/utils.py", line 246, in get_peer_type
    raise ValueError(f"Peer id invalid: {peer_id}")
ValueError: Peer id invalid: -1002725376687
[16-Aug-25 03:44:22 - ERROR] - asyncio - Task exception was never retrieved
future: <Task finished name='Task-360' coro=<Client.handle_updates() done, defined at /workspace/venv/lib/python3.13/site-packages/pyrogram/client.py:535> exception=ValueError('Peer id invalid: -1002725376687')>
Traceback (most recent call last):
  File "/workspace/venv/lib/python3.13/site-packages/pyrogram/methods/advanced/resolve_peer.py", line 62, in resolve_peer
    return await self.storage.get_peer_by_id(peer_id)
           ^^^^^^^^^^^^^^^^^^^^^^^^^^^^^^^^^^^^^^^^^^
  File "/workspace/venv/lib/python3.13/site-packages/pyrogram/storage/sqlite_storage.py", line 142, in get_peer_by_id
    raise KeyError(f"ID not found: {peer_id}")
KeyError: 'ID not found: -1002725376687'

During handling of the above exception, another exception occurred:

Traceback (most recent call last):
  File "/workspace/venv/lib/python3.13/site-packages/pyrogram/client.py", line 569, in handle_updates
    channel=await self.resolve_peer(utils.get_channel_id(channel_id)),
            ^^^^^^^^^^^^^^^^^^^^^^^^^^^^^^^^^^^^^^^^^^^^^^^^^^^^^^^^^
  File "/workspace/venv/lib/python3.13/site-packages/pyrogram/methods/advanced/resolve_peer.py", line 89, in resolve_peer
    peer_type = utils.get_peer_type(peer_id)
  File "/workspace/venv/lib/python3.13/site-packages/pyrogram/utils.py", line 246, in get_peer_type
    raise ValueError(f"Peer id invalid: {peer_id}")
ValueError: Peer id invalid: -1002725376687
[16-Aug-25 03:44:46 - ERROR] - asyncio - Task exception was never retrieved
future: <Task finished name='Task-391' coro=<Client.handle_updates() done, defined at /workspace/venv/lib/python3.13/site-packages/pyrogram/client.py:535> exception=ValueError('Peer id invalid: -1002430970946')>
Traceback (most recent call last):
  File "/workspace/venv/lib/python3.13/site-packages/pyrogram/methods/advanced/resolve_peer.py", line 62, in resolve_peer
    return await self.storage.get_peer_by_id(peer_id)
           ^^^^^^^^^^^^^^^^^^^^^^^^^^^^^^^^^^^^^^^^^^
  File "/workspace/venv/lib/python3.13/site-packages/pyrogram/storage/sqlite_storage.py", line 142, in get_peer_by_id
    raise KeyError(f"ID not found: {peer_id}")
KeyError: 'ID not found: -1002430970946'

During handling of the above exception, another exception occurred:

Traceback (most recent call last):
  File "/workspace/venv/lib/python3.13/site-packages/pyrogram/client.py", line 569, in handle_updates
    channel=await self.resolve_peer(utils.get_channel_id(channel_id)),
            ^^^^^^^^^^^^^^^^^^^^^^^^^^^^^^^^^^^^^^^^^^^^^^^^^^^^^^^^^
  File "/workspace/venv/lib/python3.13/site-packages/pyrogram/methods/advanced/resolve_peer.py", line 89, in resolve_peer
    peer_type = utils.get_peer_type(peer_id)
  File "/workspace/venv/lib/python3.13/site-packages/pyrogram/utils.py", line 246, in get_peer_type
    raise ValueError(f"Peer id invalid: {peer_id}")
ValueError: Peer id invalid: -1002430970946
[16-Aug-25 03:44:47 - ERROR] - asyncio - Task exception was never retrieved
future: <Task finished name='Task-393' coro=<Client.handle_updates() done, defined at /workspace/venv/lib/python3.13/site-packages/pyrogram/client.py:535> exception=ValueError('Peer id invalid: -1002430970946')>
Traceback (most recent call last):
  File "/workspace/venv/lib/python3.13/site-packages/pyrogram/methods/advanced/resolve_peer.py", line 62, in resolve_peer
    return await self.storage.get_peer_by_id(peer_id)
           ^^^^^^^^^^^^^^^^^^^^^^^^^^^^^^^^^^^^^^^^^^
  File "/workspace/venv/lib/python3.13/site-packages/pyrogram/storage/sqlite_storage.py", line 142, in get_peer_by_id
    raise KeyError(f"ID not found: {peer_id}")
KeyError: 'ID not found: -1002430970946'

During handling of the above exception, another exception occurred:

Traceback (most recent call last):
  File "/workspace/venv/lib/python3.13/site-packages/pyrogram/client.py", line 569, in handle_updates
    channel=await self.resolve_peer(utils.get_channel_id(channel_id)),
            ^^^^^^^^^^^^^^^^^^^^^^^^^^^^^^^^^^^^^^^^^^^^^^^^^^^^^^^^^
  File "/workspace/venv/lib/python3.13/site-packages/pyrogram/methods/advanced/resolve_peer.py", line 89, in resolve_peer
    peer_type = utils.get_peer_type(peer_id)
  File "/workspace/venv/lib/python3.13/site-packages/pyrogram/utils.py", line 246, in get_peer_type
    raise ValueError(f"Peer id invalid: {peer_id}")
ValueError: Peer id invalid: -1002430970946
[16-Aug-25 03:44:51 - ERROR] - asyncio - Task exception was never retrieved
future: <Task finished name='Task-399' coro=<Client.handle_updates() done, defined at /workspace/venv/lib/python3.13/site-packages/pyrogram/client.py:535> exception=ValueError('Peer id invalid: -1002725376687')>
Traceback (most recent call last):
  File "/workspace/venv/lib/python3.13/site-packages/pyrogram/methods/advanced/resolve_peer.py", line 62, in resolve_peer
    return await self.storage.get_peer_by_id(peer_id)
           ^^^^^^^^^^^^^^^^^^^^^^^^^^^^^^^^^^^^^^^^^^
  File "/workspace/venv/lib/python3.13/site-packages/pyrogram/storage/sqlite_storage.py", line 142, in get_peer_by_id
    raise KeyError(f"ID not found: {peer_id}")
KeyError: 'ID not found: -1002725376687'

During handling of the above exception, another exception occurred:

Traceback (most recent call last):
  File "/workspace/venv/lib/python3.13/site-packages/pyrogram/client.py", line 569, in handle_updates
    channel=await self.resolve_peer(utils.get_channel_id(channel_id)),
            ^^^^^^^^^^^^^^^^^^^^^^^^^^^^^^^^^^^^^^^^^^^^^^^^^^^^^^^^^
  File "/workspace/venv/lib/python3.13/site-packages/pyrogram/methods/advanced/resolve_peer.py", line 89, in resolve_peer
    peer_type = utils.get_peer_type(peer_id)
  File "/workspace/venv/lib/python3.13/site-packages/pyrogram/utils.py", line 246, in get_peer_type
    raise ValueError(f"Peer id invalid: {peer_id}")
ValueError: Peer id invalid: -1002725376687
[16-Aug-25 03:44:51 - ERROR] - asyncio - Task exception was never retrieved
future: <Task finished name='Task-401' coro=<Client.handle_updates() done, defined at /workspace/venv/lib/python3.13/site-packages/pyrogram/client.py:535> exception=ValueError('Peer id invalid: -1002725376687')>
Traceback (most recent call last):
  File "/workspace/venv/lib/python3.13/site-packages/pyrogram/methods/advanced/resolve_peer.py", line 62, in resolve_peer
    return await self.storage.get_peer_by_id(peer_id)
           ^^^^^^^^^^^^^^^^^^^^^^^^^^^^^^^^^^^^^^^^^^
  File "/workspace/venv/lib/python3.13/site-packages/pyrogram/storage/sqlite_storage.py", line 142, in get_peer_by_id
    raise KeyError(f"ID not found: {peer_id}")
KeyError: 'ID not found: -1002725376687'

During handling of the above exception, another exception occurred:

Traceback (most recent call last):
  File "/workspace/venv/lib/python3.13/site-packages/pyrogram/client.py", line 569, in handle_updates
    channel=await self.resolve_peer(utils.get_channel_id(channel_id)),
            ^^^^^^^^^^^^^^^^^^^^^^^^^^^^^^^^^^^^^^^^^^^^^^^^^^^^^^^^^
  File "/workspace/venv/lib/python3.13/site-packages/pyrogram/methods/advanced/resolve_peer.py", line 89, in resolve_peer
    peer_type = utils.get_peer_type(peer_id)
  File "/workspace/venv/lib/python3.13/site-packages/pyrogram/utils.py", line 246, in get_peer_type
    raise ValueError(f"Peer id invalid: {peer_id}")
ValueError: Peer id invalid: -1002725376687
[16-Aug-25 03:44:53 - ERROR] - asyncio - Task exception was never retrieved
future: <Task finished name='Task-407' coro=<Client.handle_updates() done, defined at /workspace/venv/lib/python3.13/site-packages/pyrogram/client.py:535> exception=ValueError('Peer id invalid: -1002430970946')>
Traceback (most recent call last):
  File "/workspace/venv/lib/python3.13/site-packages/pyrogram/methods/advanced/resolve_peer.py", line 62, in resolve_peer
    return await self.storage.get_peer_by_id(peer_id)
           ^^^^^^^^^^^^^^^^^^^^^^^^^^^^^^^^^^^^^^^^^^
  File "/workspace/venv/lib/python3.13/site-packages/pyrogram/storage/sqlite_storage.py", line 142, in get_peer_by_id
    raise KeyError(f"ID not found: {peer_id}")
KeyError: 'ID not found: -1002430970946'

During handling of the above exception, another exception occurred:

Traceback (most recent call last):
  File "/workspace/venv/lib/python3.13/site-packages/pyrogram/client.py", line 569, in handle_updates
    channel=await self.resolve_peer(utils.get_channel_id(channel_id)),
            ^^^^^^^^^^^^^^^^^^^^^^^^^^^^^^^^^^^^^^^^^^^^^^^^^^^^^^^^^
  File "/workspace/venv/lib/python3.13/site-packages/pyrogram/methods/advanced/resolve_peer.py", line 89, in resolve_peer
    peer_type = utils.get_peer_type(peer_id)
  File "/workspace/venv/lib/python3.13/site-packages/pyrogram/utils.py", line 246, in get_peer_type
    raise ValueError(f"Peer id invalid: {peer_id}")
ValueError: Peer id invalid: -1002430970946
[16-Aug-25 03:44:56 - ERROR] - asyncio - Task exception was never retrieved
future: <Task finished name='Task-411' coro=<Client.handle_updates() done, defined at /workspace/venv/lib/python3.13/site-packages/pyrogram/client.py:535> exception=ValueError('Peer id invalid: -1002725376687')>
Traceback (most recent call last):
  File "/workspace/venv/lib/python3.13/site-packages/pyrogram/methods/advanced/resolve_peer.py", line 62, in resolve_peer
    return await self.storage.get_peer_by_id(peer_id)
           ^^^^^^^^^^^^^^^^^^^^^^^^^^^^^^^^^^^^^^^^^^
  File "/workspace/venv/lib/python3.13/site-packages/pyrogram/storage/sqlite_storage.py", line 142, in get_peer_by_id
    raise KeyError(f"ID not found: {peer_id}")
KeyError: 'ID not found: -1002725376687'

During handling of the above exception, another exception occurred:

Traceback (most recent call last):
  File "/workspace/venv/lib/python3.13/site-packages/pyrogram/client.py", line 569, in handle_updates
    channel=await self.resolve_peer(utils.get_channel_id(channel_id)),
            ^^^^^^^^^^^^^^^^^^^^^^^^^^^^^^^^^^^^^^^^^^^^^^^^^^^^^^^^^
  File "/workspace/venv/lib/python3.13/site-packages/pyrogram/methods/advanced/resolve_peer.py", line 89, in resolve_peer
    peer_type = utils.get_peer_type(peer_id)
  File "/workspace/venv/lib/python3.13/site-packages/pyrogram/utils.py", line 246, in get_peer_type
    raise ValueError(f"Peer id invalid: {peer_id}")
ValueError: Peer id invalid: -1002725376687
[16-Aug-25 03:44:56 - ERROR] - asyncio - Task exception was never retrieved
future: <Task finished name='Task-415' coro=<Client.handle_updates() done, defined at /workspace/venv/lib/python3.13/site-packages/pyrogram/client.py:535> exception=ValueError('Peer id invalid: -1002725376687')>
Traceback (most recent call last):
  File "/workspace/venv/lib/python3.13/site-packages/pyrogram/methods/advanced/resolve_peer.py", line 62, in resolve_peer
    return await self.storage.get_peer_by_id(peer_id)
           ^^^^^^^^^^^^^^^^^^^^^^^^^^^^^^^^^^^^^^^^^^
  File "/workspace/venv/lib/python3.13/site-packages/pyrogram/storage/sqlite_storage.py", line 142, in get_peer_by_id
    raise KeyError(f"ID not found: {peer_id}")
KeyError: 'ID not found: -1002725376687'

During handling of the above exception, another exception occurred:

Traceback (most recent call last):
  File "/workspace/venv/lib/python3.13/site-packages/pyrogram/client.py", line 569, in handle_updates
    channel=await self.resolve_peer(utils.get_channel_id(channel_id)),
            ^^^^^^^^^^^^^^^^^^^^^^^^^^^^^^^^^^^^^^^^^^^^^^^^^^^^^^^^^
  File "/workspace/venv/lib/python3.13/site-packages/pyrogram/methods/advanced/resolve_peer.py", line 89, in resolve_peer
    peer_type = utils.get_peer_type(peer_id)
  File "/workspace/venv/lib/python3.13/site-packages/pyrogram/utils.py", line 246, in get_peer_type
    raise ValueError(f"Peer id invalid: {peer_id}")
ValueError: Peer id invalid: -1002725376687
[16-Aug-25 03:44:58 - ERROR] - asyncio - Task exception was never retrieved
future: <Task finished name='Task-418' coro=<Client.handle_updates() done, defined at /workspace/venv/lib/python3.13/site-packages/pyrogram/client.py:535> exception=ValueError('Peer id invalid: -1002430970946')>
Traceback (most recent call last):
  File "/workspace/venv/lib/python3.13/site-packages/pyrogram/methods/advanced/resolve_peer.py", line 62, in resolve_peer
    return await self.storage.get_peer_by_id(peer_id)
           ^^^^^^^^^^^^^^^^^^^^^^^^^^^^^^^^^^^^^^^^^^
  File "/workspace/venv/lib/python3.13/site-packages/pyrogram/storage/sqlite_storage.py", line 142, in get_peer_by_id
    raise KeyError(f"ID not found: {peer_id}")
KeyError: 'ID not found: -1002430970946'

During handling of the above exception, another exception occurred:

Traceback (most recent call last):
  File "/workspace/venv/lib/python3.13/site-packages/pyrogram/client.py", line 569, in handle_updates
    channel=await self.resolve_peer(utils.get_channel_id(channel_id)),
            ^^^^^^^^^^^^^^^^^^^^^^^^^^^^^^^^^^^^^^^^^^^^^^^^^^^^^^^^^
  File "/workspace/venv/lib/python3.13/site-packages/pyrogram/methods/advanced/resolve_peer.py", line 89, in resolve_peer
    peer_type = utils.get_peer_type(peer_id)
  File "/workspace/venv/lib/python3.13/site-packages/pyrogram/utils.py", line 246, in get_peer_type
    raise ValueError(f"Peer id invalid: {peer_id}")
ValueError: Peer id invalid: -1002430970946
[16-Aug-25 03:44:58 - ERROR] - asyncio - Task exception was never retrieved
future: <Task finished name='Task-420' coro=<Client.handle_updates() done, defined at /workspace/venv/lib/python3.13/site-packages/pyrogram/client.py:535> exception=ValueError('Peer id invalid: -1002725376687')>
Traceback (most recent call last):
  File "/workspace/venv/lib/python3.13/site-packages/pyrogram/methods/advanced/resolve_peer.py", line 62, in resolve_peer
    return await self.storage.get_peer_by_id(peer_id)
           ^^^^^^^^^^^^^^^^^^^^^^^^^^^^^^^^^^^^^^^^^^
  File "/workspace/venv/lib/python3.13/site-packages/pyrogram/storage/sqlite_storage.py", line 142, in get_peer_by_id
    raise KeyError(f"ID not found: {peer_id}")
KeyError: 'ID not found: -1002725376687'

During handling of the above exception, another exception occurred:

Traceback (most recent call last):
  File "/workspace/venv/lib/python3.13/site-packages/pyrogram/client.py", line 569, in handle_updates
    channel=await self.resolve_peer(utils.get_channel_id(channel_id)),
            ^^^^^^^^^^^^^^^^^^^^^^^^^^^^^^^^^^^^^^^^^^^^^^^^^^^^^^^^^
  File "/workspace/venv/lib/python3.13/site-packages/pyrogram/methods/advanced/resolve_peer.py", line 89, in resolve_peer
    peer_type = utils.get_peer_type(peer_id)
  File "/workspace/venv/lib/python3.13/site-packages/pyrogram/utils.py", line 246, in get_peer_type
    raise ValueError(f"Peer id invalid: {peer_id}")
ValueError: Peer id invalid: -1002725376687
[16-Aug-25 03:44:58 - ERROR] - asyncio - Task exception was never retrieved
future: <Task finished name='Task-422' coro=<Client.handle_updates() done, defined at /workspace/venv/lib/python3.13/site-packages/pyrogram/client.py:535> exception=ValueError('Peer id invalid: -1002725376687')>
Traceback (most recent call last):
  File "/workspace/venv/lib/python3.13/site-packages/pyrogram/methods/advanced/resolve_peer.py", line 62, in resolve_peer
    return await self.storage.get_peer_by_id(peer_id)
           ^^^^^^^^^^^^^^^^^^^^^^^^^^^^^^^^^^^^^^^^^^
  File "/workspace/venv/lib/python3.13/site-packages/pyrogram/storage/sqlite_storage.py", line 142, in get_peer_by_id
    raise KeyError(f"ID not found: {peer_id}")
KeyError: 'ID not found: -1002725376687'

During handling of the above exception, another exception occurred:

Traceback (most recent call last):
  File "/workspace/venv/lib/python3.13/site-packages/pyrogram/client.py", line 569, in handle_updates
    channel=await self.resolve_peer(utils.get_channel_id(channel_id)),
            ^^^^^^^^^^^^^^^^^^^^^^^^^^^^^^^^^^^^^^^^^^^^^^^^^^^^^^^^^
  File "/workspace/venv/lib/python3.13/site-packages/pyrogram/methods/advanced/resolve_peer.py", line 89, in resolve_peer
    peer_type = utils.get_peer_type(peer_id)
  File "/workspace/venv/lib/python3.13/site-packages/pyrogram/utils.py", line 246, in get_peer_type
    raise ValueError(f"Peer id invalid: {peer_id}")
ValueError: Peer id invalid: -1002725376687
[16-Aug-25 03:45:00 - ERROR] - asyncio - Task exception was never retrieved
future: <Task finished name='Task-425' coro=<Client.handle_updates() done, defined at /workspace/venv/lib/python3.13/site-packages/pyrogram/client.py:535> exception=ValueError('Peer id invalid: -1002725376687')>
Traceback (most recent call last):
  File "/workspace/venv/lib/python3.13/site-packages/pyrogram/methods/advanced/resolve_peer.py", line 62, in resolve_peer
    return await self.storage.get_peer_by_id(peer_id)
           ^^^^^^^^^^^^^^^^^^^^^^^^^^^^^^^^^^^^^^^^^^
  File "/workspace/venv/lib/python3.13/site-packages/pyrogram/storage/sqlite_storage.py", line 142, in get_peer_by_id
    raise KeyError(f"ID not found: {peer_id}")
KeyError: 'ID not found: -1002725376687'

During handling of the above exception, another exception occurred:

Traceback (most recent call last):
  File "/workspace/venv/lib/python3.13/site-packages/pyrogram/client.py", line 569, in handle_updates
    channel=await self.resolve_peer(utils.get_channel_id(channel_id)),
            ^^^^^^^^^^^^^^^^^^^^^^^^^^^^^^^^^^^^^^^^^^^^^^^^^^^^^^^^^
  File "/workspace/venv/lib/python3.13/site-packages/pyrogram/methods/advanced/resolve_peer.py", line 89, in resolve_peer
    peer_type = utils.get_peer_type(peer_id)
  File "/workspace/venv/lib/python3.13/site-packages/pyrogram/utils.py", line 246, in get_peer_type
    raise ValueError(f"Peer id invalid: {peer_id}")
ValueError: Peer id invalid: -1002725376687
[16-Aug-25 03:45:00 - ERROR] - asyncio - Task exception was never retrieved
future: <Task finished name='Task-427' coro=<Client.handle_updates() done, defined at /workspace/venv/lib/python3.13/site-packages/pyrogram/client.py:535> exception=ValueError('Peer id invalid: -1002725376687')>
Traceback (most recent call last):
  File "/workspace/venv/lib/python3.13/site-packages/pyrogram/methods/advanced/resolve_peer.py", line 62, in resolve_peer
    return await self.storage.get_peer_by_id(peer_id)
           ^^^^^^^^^^^^^^^^^^^^^^^^^^^^^^^^^^^^^^^^^^
  File "/workspace/venv/lib/python3.13/site-packages/pyrogram/storage/sqlite_storage.py", line 142, in get_peer_by_id
    raise KeyError(f"ID not found: {peer_id}")
KeyError: 'ID not found: -1002725376687'

During handling of the above exception, another exception occurred:

Traceback (most recent call last):
  File "/workspace/venv/lib/python3.13/site-packages/pyrogram/client.py", line 569, in handle_updates
    channel=await self.resolve_peer(utils.get_channel_id(channel_id)),
            ^^^^^^^^^^^^^^^^^^^^^^^^^^^^^^^^^^^^^^^^^^^^^^^^^^^^^^^^^
  File "/workspace/venv/lib/python3.13/site-packages/pyrogram/methods/advanced/resolve_peer.py", line 89, in resolve_peer
    peer_type = utils.get_peer_type(peer_id)
  File "/workspace/venv/lib/python3.13/site-packages/pyrogram/utils.py", line 246, in get_peer_type
    raise ValueError(f"Peer id invalid: {peer_id}")
ValueError: Peer id invalid: -1002725376687
[16-Aug-25 03:45:00 - ERROR] - asyncio - Task exception was never retrieved
future: <Task finished name='Task-429' coro=<Client.handle_updates() done, defined at /workspace/venv/lib/python3.13/site-packages/pyrogram/client.py:535> exception=ValueError('Peer id invalid: -1002430970946')>
Traceback (most recent call last):
  File "/workspace/venv/lib/python3.13/site-packages/pyrogram/methods/advanced/resolve_peer.py", line 62, in resolve_peer
    return await self.storage.get_peer_by_id(peer_id)
           ^^^^^^^^^^^^^^^^^^^^^^^^^^^^^^^^^^^^^^^^^^
  File "/workspace/venv/lib/python3.13/site-packages/pyrogram/storage/sqlite_storage.py", line 142, in get_peer_by_id
    raise KeyError(f"ID not found: {peer_id}")
KeyError: 'ID not found: -1002430970946'

During handling of the above exception, another exception occurred:

Traceback (most recent call last):
  File "/workspace/venv/lib/python3.13/site-packages/pyrogram/client.py", line 569, in handle_updates
    channel=await self.resolve_peer(utils.get_channel_id(channel_id)),
            ^^^^^^^^^^^^^^^^^^^^^^^^^^^^^^^^^^^^^^^^^^^^^^^^^^^^^^^^^
  File "/workspace/venv/lib/python3.13/site-packages/pyrogram/methods/advanced/resolve_peer.py", line 89, in resolve_peer
    peer_type = utils.get_peer_type(peer_id)
  File "/workspace/venv/lib/python3.13/site-packages/pyrogram/utils.py", line 246, in get_peer_type
    raise ValueError(f"Peer id invalid: {peer_id}")
ValueError: Peer id invalid: -1002430970946
[16-Aug-25 03:45:07 - ERROR] - asyncio - Task exception was never retrieved
future: <Task finished name='Task-440' coro=<Client.handle_updates() done, defined at /workspace/venv/lib/python3.13/site-packages/pyrogram/client.py:535> exception=ValueError('Peer id invalid: -1002725376687')>
Traceback (most recent call last):
  File "/workspace/venv/lib/python3.13/site-packages/pyrogram/methods/advanced/resolve_peer.py", line 62, in resolve_peer
    return await self.storage.get_peer_by_id(peer_id)
           ^^^^^^^^^^^^^^^^^^^^^^^^^^^^^^^^^^^^^^^^^^
  File "/workspace/venv/lib/python3.13/site-packages/pyrogram/storage/sqlite_storage.py", line 142, in get_peer_by_id
    raise KeyError(f"ID not found: {peer_id}")
KeyError: 'ID not found: -1002725376687'

During handling of the above exception, another exception occurred:

Traceback (most recent call last):
  File "/workspace/venv/lib/python3.13/site-packages/pyrogram/client.py", line 569, in handle_updates
    channel=await self.resolve_peer(utils.get_channel_id(channel_id)),
            ^^^^^^^^^^^^^^^^^^^^^^^^^^^^^^^^^^^^^^^^^^^^^^^^^^^^^^^^^
  File "/workspace/venv/lib/python3.13/site-packages/pyrogram/methods/advanced/resolve_peer.py", line 89, in resolve_peer
    peer_type = utils.get_peer_type(peer_id)
  File "/workspace/venv/lib/python3.13/site-packages/pyrogram/utils.py", line 246, in get_peer_type
    raise ValueError(f"Peer id invalid: {peer_id}")
ValueError: Peer id invalid: -1002725376687
[16-Aug-25 03:45:08 - ERROR] - asyncio - Task exception was never retrieved
future: <Task finished name='Task-442' coro=<Client.handle_updates() done, defined at /workspace/venv/lib/python3.13/site-packages/pyrogram/client.py:535> exception=ValueError('Peer id invalid: -1002725376687')>
Traceback (most recent call last):
  File "/workspace/venv/lib/python3.13/site-packages/pyrogram/methods/advanced/resolve_peer.py", line 62, in resolve_peer
    return await self.storage.get_peer_by_id(peer_id)
           ^^^^^^^^^^^^^^^^^^^^^^^^^^^^^^^^^^^^^^^^^^
  File "/workspace/venv/lib/python3.13/site-packages/pyrogram/storage/sqlite_storage.py", line 142, in get_peer_by_id
    raise KeyError(f"ID not found: {peer_id}")
KeyError: 'ID not found: -1002725376687'

During handling of the above exception, another exception occurred:

Traceback (most recent call last):
  File "/workspace/venv/lib/python3.13/site-packages/pyrogram/client.py", line 569, in handle_updates
    channel=await self.resolve_peer(utils.get_channel_id(channel_id)),
            ^^^^^^^^^^^^^^^^^^^^^^^^^^^^^^^^^^^^^^^^^^^^^^^^^^^^^^^^^
  File "/workspace/venv/lib/python3.13/site-packages/pyrogram/methods/advanced/resolve_peer.py", line 89, in resolve_peer
    peer_type = utils.get_peer_type(peer_id)
  File "/workspace/venv/lib/python3.13/site-packages/pyrogram/utils.py", line 246, in get_peer_type
    raise ValueError(f"Peer id invalid: {peer_id}")
ValueError: Peer id invalid: -1002725376687
[16-Aug-25 03:45:13 - ERROR] - asyncio - Task exception was never retrieved
future: <Task finished name='Task-451' coro=<Client.handle_updates() done, defined at /workspace/venv/lib/python3.13/site-packages/pyrogram/client.py:535> exception=ValueError('Peer id invalid: -1002725376687')>
Traceback (most recent call last):
  File "/workspace/venv/lib/python3.13/site-packages/pyrogram/methods/advanced/resolve_peer.py", line 62, in resolve_peer
    return await self.storage.get_peer_by_id(peer_id)
           ^^^^^^^^^^^^^^^^^^^^^^^^^^^^^^^^^^^^^^^^^^
  File "/workspace/venv/lib/python3.13/site-packages/pyrogram/storage/sqlite_storage.py", line 142, in get_peer_by_id
    raise KeyError(f"ID not found: {peer_id}")
KeyError: 'ID not found: -1002725376687'

During handling of the above exception, another exception occurred:

Traceback (most recent call last):
  File "/workspace/venv/lib/python3.13/site-packages/pyrogram/client.py", line 569, in handle_updates
    channel=await self.resolve_peer(utils.get_channel_id(channel_id)),
            ^^^^^^^^^^^^^^^^^^^^^^^^^^^^^^^^^^^^^^^^^^^^^^^^^^^^^^^^^
  File "/workspace/venv/lib/python3.13/site-packages/pyrogram/methods/advanced/resolve_peer.py", line 89, in resolve_peer
    peer_type = utils.get_peer_type(peer_id)
  File "/workspace/venv/lib/python3.13/site-packages/pyrogram/utils.py", line 246, in get_peer_type
    raise ValueError(f"Peer id invalid: {peer_id}")
ValueError: Peer id invalid: -1002725376687
[16-Aug-25 03:45:14 - ERROR] - asyncio - Task exception was never retrieved
future: <Task finished name='Task-453' coro=<Client.handle_updates() done, defined at /workspace/venv/lib/python3.13/site-packages/pyrogram/client.py:535> exception=ValueError('Peer id invalid: -1002725376687')>
Traceback (most recent call last):
  File "/workspace/venv/lib/python3.13/site-packages/pyrogram/methods/advanced/resolve_peer.py", line 62, in resolve_peer
    return await self.storage.get_peer_by_id(peer_id)
           ^^^^^^^^^^^^^^^^^^^^^^^^^^^^^^^^^^^^^^^^^^
  File "/workspace/venv/lib/python3.13/site-packages/pyrogram/storage/sqlite_storage.py", line 142, in get_peer_by_id
    raise KeyError(f"ID not found: {peer_id}")
KeyError: 'ID not found: -1002725376687'

During handling of the above exception, another exception occurred:

Traceback (most recent call last):
  File "/workspace/venv/lib/python3.13/site-packages/pyrogram/client.py", line 569, in handle_updates
    channel=await self.resolve_peer(utils.get_channel_id(channel_id)),
            ^^^^^^^^^^^^^^^^^^^^^^^^^^^^^^^^^^^^^^^^^^^^^^^^^^^^^^^^^
  File "/workspace/venv/lib/python3.13/site-packages/pyrogram/methods/advanced/resolve_peer.py", line 89, in resolve_peer
    peer_type = utils.get_peer_type(peer_id)
  File "/workspace/venv/lib/python3.13/site-packages/pyrogram/utils.py", line 246, in get_peer_type
    raise ValueError(f"Peer id invalid: {peer_id}")
ValueError: Peer id invalid: -1002725376687
[16-Aug-25 03:45:14 - ERROR] - asyncio - Task exception was never retrieved
future: <Task finished name='Task-455' coro=<Client.handle_updates() done, defined at /workspace/venv/lib/python3.13/site-packages/pyrogram/client.py:535> exception=ValueError('Peer id invalid: -1002430970946')>
Traceback (most recent call last):
  File "/workspace/venv/lib/python3.13/site-packages/pyrogram/methods/advanced/resolve_peer.py", line 62, in resolve_peer
    return await self.storage.get_peer_by_id(peer_id)
           ^^^^^^^^^^^^^^^^^^^^^^^^^^^^^^^^^^^^^^^^^^
  File "/workspace/venv/lib/python3.13/site-packages/pyrogram/storage/sqlite_storage.py", line 142, in get_peer_by_id
    raise KeyError(f"ID not found: {peer_id}")
KeyError: 'ID not found: -1002430970946'

During handling of the above exception, another exception occurred:

Traceback (most recent call last):
  File "/workspace/venv/lib/python3.13/site-packages/pyrogram/client.py", line 569, in handle_updates
    channel=await self.resolve_peer(utils.get_channel_id(channel_id)),
            ^^^^^^^^^^^^^^^^^^^^^^^^^^^^^^^^^^^^^^^^^^^^^^^^^^^^^^^^^
  File "/workspace/venv/lib/python3.13/site-packages/pyrogram/methods/advanced/resolve_peer.py", line 89, in resolve_peer
    peer_type = utils.get_peer_type(peer_id)
  File "/workspace/venv/lib/python3.13/site-packages/pyrogram/utils.py", line 246, in get_peer_type
    raise ValueError(f"Peer id invalid: {peer_id}")
ValueError: Peer id invalid: -1002430970946
[16-Aug-25 03:45:18 - ERROR] - asyncio - Task exception was never retrieved
future: <Task finished name='Task-462' coro=<Client.handle_updates() done, defined at /workspace/venv/lib/python3.13/site-packages/pyrogram/client.py:535> exception=ValueError('Peer id invalid: -1002725376687')>
Traceback (most recent call last):
  File "/workspace/venv/lib/python3.13/site-packages/pyrogram/methods/advanced/resolve_peer.py", line 62, in resolve_peer
    return await self.storage.get_peer_by_id(peer_id)
           ^^^^^^^^^^^^^^^^^^^^^^^^^^^^^^^^^^^^^^^^^^
  File "/workspace/venv/lib/python3.13/site-packages/pyrogram/storage/sqlite_storage.py", line 142, in get_peer_by_id
    raise KeyError(f"ID not found: {peer_id}")
KeyError: 'ID not found: -1002725376687'

During handling of the above exception, another exception occurred:

Traceback (most recent call last):
  File "/workspace/venv/lib/python3.13/site-packages/pyrogram/client.py", line 569, in handle_updates
    channel=await self.resolve_peer(utils.get_channel_id(channel_id)),
            ^^^^^^^^^^^^^^^^^^^^^^^^^^^^^^^^^^^^^^^^^^^^^^^^^^^^^^^^^
  File "/workspace/venv/lib/python3.13/site-packages/pyrogram/methods/advanced/resolve_peer.py", line 89, in resolve_peer
    peer_type = utils.get_peer_type(peer_id)
  File "/workspace/venv/lib/python3.13/site-packages/pyrogram/utils.py", line 246, in get_peer_type
    raise ValueError(f"Peer id invalid: {peer_id}")
ValueError: Peer id invalid: -1002725376687
[16-Aug-25 03:45:19 - ERROR] - asyncio - Task exception was never retrieved
future: <Task finished name='Task-464' coro=<Client.handle_updates() done, defined at /workspace/venv/lib/python3.13/site-packages/pyrogram/client.py:535> exception=ValueError('Peer id invalid: -1002725376687')>
Traceback (most recent call last):
  File "/workspace/venv/lib/python3.13/site-packages/pyrogram/methods/advanced/resolve_peer.py", line 62, in resolve_peer
    return await self.storage.get_peer_by_id(peer_id)
           ^^^^^^^^^^^^^^^^^^^^^^^^^^^^^^^^^^^^^^^^^^
  File "/workspace/venv/lib/python3.13/site-packages/pyrogram/storage/sqlite_storage.py", line 142, in get_peer_by_id
    raise KeyError(f"ID not found: {peer_id}")
KeyError: 'ID not found: -1002725376687'

During handling of the above exception, another exception occurred:

Traceback (most recent call last):
  File "/workspace/venv/lib/python3.13/site-packages/pyrogram/client.py", line 569, in handle_updates
    channel=await self.resolve_peer(utils.get_channel_id(channel_id)),
            ^^^^^^^^^^^^^^^^^^^^^^^^^^^^^^^^^^^^^^^^^^^^^^^^^^^^^^^^^
  File "/workspace/venv/lib/python3.13/site-packages/pyrogram/methods/advanced/resolve_peer.py", line 89, in resolve_peer
    peer_type = utils.get_peer_type(peer_id)
  File "/workspace/venv/lib/python3.13/site-packages/pyrogram/utils.py", line 246, in get_peer_type
    raise ValueError(f"Peer id invalid: {peer_id}")
ValueError: Peer id invalid: -1002725376687
[16-Aug-25 03:45:30 - ERROR] - asyncio - Task exception was never retrieved
future: <Task finished name='Task-476' coro=<Client.handle_updates() done, defined at /workspace/venv/lib/python3.13/site-packages/pyrogram/client.py:535> exception=ValueError('Peer id invalid: -1002524216878')>
Traceback (most recent call last):
  File "/workspace/venv/lib/python3.13/site-packages/pyrogram/methods/advanced/resolve_peer.py", line 62, in resolve_peer
    return await self.storage.get_peer_by_id(peer_id)
           ^^^^^^^^^^^^^^^^^^^^^^^^^^^^^^^^^^^^^^^^^^
  File "/workspace/venv/lib/python3.13/site-packages/pyrogram/storage/sqlite_storage.py", line 142, in get_peer_by_id
    raise KeyError(f"ID not found: {peer_id}")
KeyError: 'ID not found: -1002524216878'

During handling of the above exception, another exception occurred:

Traceback (most recent call last):
  File "/workspace/venv/lib/python3.13/site-packages/pyrogram/client.py", line 569, in handle_updates
    channel=await self.resolve_peer(utils.get_channel_id(channel_id)),
            ^^^^^^^^^^^^^^^^^^^^^^^^^^^^^^^^^^^^^^^^^^^^^^^^^^^^^^^^^
  File "/workspace/venv/lib/python3.13/site-packages/pyrogram/methods/advanced/resolve_peer.py", line 89, in resolve_peer
    peer_type = utils.get_peer_type(peer_id)
  File "/workspace/venv/lib/python3.13/site-packages/pyrogram/utils.py", line 246, in get_peer_type
    raise ValueError(f"Peer id invalid: {peer_id}")
ValueError: Peer id invalid: -1002524216878
[16-Aug-25 03:45:31 - ERROR] - asyncio - Task exception was never retrieved
future: <Task finished name='Task-481' coro=<Client.handle_updates() done, defined at /workspace/venv/lib/python3.13/site-packages/pyrogram/client.py:535> exception=ValueError('Peer id invalid: -1002725376687')>
Traceback (most recent call last):
  File "/workspace/venv/lib/python3.13/site-packages/pyrogram/methods/advanced/resolve_peer.py", line 62, in resolve_peer
    return await self.storage.get_peer_by_id(peer_id)
           ^^^^^^^^^^^^^^^^^^^^^^^^^^^^^^^^^^^^^^^^^^
  File "/workspace/venv/lib/python3.13/site-packages/pyrogram/storage/sqlite_storage.py", line 142, in get_peer_by_id
    raise KeyError(f"ID not found: {peer_id}")
KeyError: 'ID not found: -1002725376687'

During handling of the above exception, another exception occurred:

Traceback (most recent call last):
  File "/workspace/venv/lib/python3.13/site-packages/pyrogram/client.py", line 569, in handle_updates
    channel=await self.resolve_peer(utils.get_channel_id(channel_id)),
            ^^^^^^^^^^^^^^^^^^^^^^^^^^^^^^^^^^^^^^^^^^^^^^^^^^^^^^^^^
  File "/workspace/venv/lib/python3.13/site-packages/pyrogram/methods/advanced/resolve_peer.py", line 89, in resolve_peer
    peer_type = utils.get_peer_type(peer_id)
  File "/workspace/venv/lib/python3.13/site-packages/pyrogram/utils.py", line 246, in get_peer_type
    raise ValueError(f"Peer id invalid: {peer_id}")
ValueError: Peer id invalid: -1002725376687
[16-Aug-25 03:45:32 - ERROR] - asyncio - Task exception was never retrieved
future: <Task finished name='Task-484' coro=<Client.handle_updates() done, defined at /workspace/venv/lib/python3.13/site-packages/pyrogram/client.py:535> exception=ValueError('Peer id invalid: -1002725376687')>
Traceback (most recent call last):
  File "/workspace/venv/lib/python3.13/site-packages/pyrogram/methods/advanced/resolve_peer.py", line 62, in resolve_peer
    return await self.storage.get_peer_by_id(peer_id)
           ^^^^^^^^^^^^^^^^^^^^^^^^^^^^^^^^^^^^^^^^^^
  File "/workspace/venv/lib/python3.13/site-packages/pyrogram/storage/sqlite_storage.py", line 142, in get_peer_by_id
    raise KeyError(f"ID not found: {peer_id}")
KeyError: 'ID not found: -1002725376687'

During handling of the above exception, another exception occurred:

Traceback (most recent call last):
  File "/workspace/venv/lib/python3.13/site-packages/pyrogram/client.py", line 569, in handle_updates
    channel=await self.resolve_peer(utils.get_channel_id(channel_id)),
            ^^^^^^^^^^^^^^^^^^^^^^^^^^^^^^^^^^^^^^^^^^^^^^^^^^^^^^^^^
  File "/workspace/venv/lib/python3.13/site-packages/pyrogram/methods/advanced/resolve_peer.py", line 89, in resolve_peer
    peer_type = utils.get_peer_type(peer_id)
  File "/workspace/venv/lib/python3.13/site-packages/pyrogram/utils.py", line 246, in get_peer_type
    raise ValueError(f"Peer id invalid: {peer_id}")
ValueError: Peer id invalid: -1002725376687
[16-Aug-25 03:45:33 - ERROR] - asyncio - Task exception was never retrieved
future: <Task finished name='Task-487' coro=<Client.handle_updates() done, defined at /workspace/venv/lib/python3.13/site-packages/pyrogram/client.py:535> exception=ValueError('Peer id invalid: -1002725376687')>
Traceback (most recent call last):
  File "/workspace/venv/lib/python3.13/site-packages/pyrogram/methods/advanced/resolve_peer.py", line 62, in resolve_peer
    return await self.storage.get_peer_by_id(peer_id)
           ^^^^^^^^^^^^^^^^^^^^^^^^^^^^^^^^^^^^^^^^^^
  File "/workspace/venv/lib/python3.13/site-packages/pyrogram/storage/sqlite_storage.py", line 142, in get_peer_by_id
    raise KeyError(f"ID not found: {peer_id}")
KeyError: 'ID not found: -1002725376687'

During handling of the above exception, another exception occurred:

Traceback (most recent call last):
  File "/workspace/venv/lib/python3.13/site-packages/pyrogram/client.py", line 569, in handle_updates
    channel=await self.resolve_peer(utils.get_channel_id(channel_id)),
            ^^^^^^^^^^^^^^^^^^^^^^^^^^^^^^^^^^^^^^^^^^^^^^^^^^^^^^^^^
  File "/workspace/venv/lib/python3.13/site-packages/pyrogram/methods/advanced/resolve_peer.py", line 89, in resolve_peer
    peer_type = utils.get_peer_type(peer_id)
  File "/workspace/venv/lib/python3.13/site-packages/pyrogram/utils.py", line 246, in get_peer_type
    raise ValueError(f"Peer id invalid: {peer_id}")
ValueError: Peer id invalid: -1002725376687
[16-Aug-25 03:45:33 - ERROR] - asyncio - Task exception was never retrieved
future: <Task finished name='Task-489' coro=<Client.handle_updates() done, defined at /workspace/venv/lib/python3.13/site-packages/pyrogram/client.py:535> exception=ValueError('Peer id invalid: -1002725376687')>
Traceback (most recent call last):
  File "/workspace/venv/lib/python3.13/site-packages/pyrogram/methods/advanced/resolve_peer.py", line 62, in resolve_peer
    return await self.storage.get_peer_by_id(peer_id)
           ^^^^^^^^^^^^^^^^^^^^^^^^^^^^^^^^^^^^^^^^^^
  File "/workspace/venv/lib/python3.13/site-packages/pyrogram/storage/sqlite_storage.py", line 142, in get_peer_by_id
    raise KeyError(f"ID not found: {peer_id}")
KeyError: 'ID not found: -1002725376687'

During handling of the above exception, another exception occurred:

Traceback (most recent call last):
  File "/workspace/venv/lib/python3.13/site-packages/pyrogram/client.py", line 569, in handle_updates
    channel=await self.resolve_peer(utils.get_channel_id(channel_id)),
            ^^^^^^^^^^^^^^^^^^^^^^^^^^^^^^^^^^^^^^^^^^^^^^^^^^^^^^^^^
  File "/workspace/venv/lib/python3.13/site-packages/pyrogram/methods/advanced/resolve_peer.py", line 89, in resolve_peer
    peer_type = utils.get_peer_type(peer_id)
  File "/workspace/venv/lib/python3.13/site-packages/pyrogram/utils.py", line 246, in get_peer_type
    raise ValueError(f"Peer id invalid: {peer_id}")
ValueError: Peer id invalid: -1002725376687
[16-Aug-25 03:45:44 - ERROR] - asyncio - Task exception was never retrieved
future: <Task finished name='Task-505' coro=<Client.handle_updates() done, defined at /workspace/venv/lib/python3.13/site-packages/pyrogram/client.py:535> exception=ValueError('Peer id invalid: -1002725376687')>
Traceback (most recent call last):
  File "/workspace/venv/lib/python3.13/site-packages/pyrogram/methods/advanced/resolve_peer.py", line 62, in resolve_peer
    return await self.storage.get_peer_by_id(peer_id)
           ^^^^^^^^^^^^^^^^^^^^^^^^^^^^^^^^^^^^^^^^^^
  File "/workspace/venv/lib/python3.13/site-packages/pyrogram/storage/sqlite_storage.py", line 142, in get_peer_by_id
    raise KeyError(f"ID not found: {peer_id}")
KeyError: 'ID not found: -1002725376687'

During handling of the above exception, another exception occurred:

Traceback (most recent call last):
  File "/workspace/venv/lib/python3.13/site-packages/pyrogram/client.py", line 569, in handle_updates
    channel=await self.resolve_peer(utils.get_channel_id(channel_id)),
            ^^^^^^^^^^^^^^^^^^^^^^^^^^^^^^^^^^^^^^^^^^^^^^^^^^^^^^^^^
  File "/workspace/venv/lib/python3.13/site-packages/pyrogram/methods/advanced/resolve_peer.py", line 89, in resolve_peer
    peer_type = utils.get_peer_type(peer_id)
  File "/workspace/venv/lib/python3.13/site-packages/pyrogram/utils.py", line 246, in get_peer_type
    raise ValueError(f"Peer id invalid: {peer_id}")
ValueError: Peer id invalid: -1002725376687
[16-Aug-25 03:45:44 - ERROR] - asyncio - Task exception was never retrieved
future: <Task finished name='Task-507' coro=<Client.handle_updates() done, defined at /workspace/venv/lib/python3.13/site-packages/pyrogram/client.py:535> exception=ValueError('Peer id invalid: -1002704003307')>
Traceback (most recent call last):
  File "/workspace/venv/lib/python3.13/site-packages/pyrogram/methods/advanced/resolve_peer.py", line 62, in resolve_peer
    return await self.storage.get_peer_by_id(peer_id)
           ^^^^^^^^^^^^^^^^^^^^^^^^^^^^^^^^^^^^^^^^^^
  File "/workspace/venv/lib/python3.13/site-packages/pyrogram/storage/sqlite_storage.py", line 142, in get_peer_by_id
    raise KeyError(f"ID not found: {peer_id}")
KeyError: 'ID not found: -1002704003307'

During handling of the above exception, another exception occurred:

Traceback (most recent call last):
  File "/workspace/venv/lib/python3.13/site-packages/pyrogram/client.py", line 569, in handle_updates
    channel=await self.resolve_peer(utils.get_channel_id(channel_id)),
            ^^^^^^^^^^^^^^^^^^^^^^^^^^^^^^^^^^^^^^^^^^^^^^^^^^^^^^^^^
  File "/workspace/venv/lib/python3.13/site-packages/pyrogram/methods/advanced/resolve_peer.py", line 89, in resolve_peer
    peer_type = utils.get_peer_type(peer_id)
  File "/workspace/venv/lib/python3.13/site-packages/pyrogram/utils.py", line 246, in get_peer_type
    raise ValueError(f"Peer id invalid: {peer_id}")
ValueError: Peer id invalid: -1002704003307
[16-Aug-25 03:45:44 - ERROR] - asyncio - Task exception was never retrieved
future: <Task finished name='Task-509' coro=<Client.handle_updates() done, defined at /workspace/venv/lib/python3.13/site-packages/pyrogram/client.py:535> exception=ValueError('Peer id invalid: -1002704003307')>
Traceback (most recent call last):
  File "/workspace/venv/lib/python3.13/site-packages/pyrogram/methods/advanced/resolve_peer.py", line 62, in resolve_peer
    return await self.storage.get_peer_by_id(peer_id)
           ^^^^^^^^^^^^^^^^^^^^^^^^^^^^^^^^^^^^^^^^^^
  File "/workspace/venv/lib/python3.13/site-packages/pyrogram/storage/sqlite_storage.py", line 142, in get_peer_by_id
    raise KeyError(f"ID not found: {peer_id}")
KeyError: 'ID not found: -1002704003307'

During handling of the above exception, another exception occurred:

Traceback (most recent call last):
  File "/workspace/ven[download] 100% of    4.66MiB                             WARNING: [youtube] Unable to download webpage: HTTP Error 429: Too Many Requests (caused by <HTTPError 429: Too Many Requests>)
[download] 100% of    4.66MiB                             WARNING: [youtube] Unable to download webpage: HTTP Error 429: Too Many Requests (caused by <HTTPError 429: Too Many Requests>)
[download] 100% of    4.66MiB                             WARNING: [youtube] Unable to download webpage: HTTP Error 429: Too Many Requests (caused by <HTTPError 429: Too Many Requests>)
[download] 100% of    4.66MiB                             WARNING: [youtube] Unable to download webpage: HTTP Error 429: Too Many Requests (caused by <HTTPError 429: Too Many Requests>)
[download] 100% of    4.66MiB                             WARNING: [youtube] Unable to download webpage: HTTP Error 429: Too Many Requests (caused by <HTTPError 429: Too Many Requests>)
[download] 100% of    4.66MiB                             WARNING: [youtube] Unable to download webpage: HTTP Error 429: Too Many Requests (caused by <HTTPError 429: Too Many Requests>)
[download] 100% of    4.66MiB                             WARNING: [youtube] Unable to download webpage: HTTP Error 429: Too Many Requests (caused by <HTTPError 429: Too Many Requests>)
[download] 100% of    4.66MiB                             WARNING: [youtube] Unable to download webpage: HTTP Error 429: Too Many Requests (caused by <HTTPError 429: Too Many Requests>)
[download] 100% of    4.66MiB                             WARNING: [youtube] Unable to download webpage: HTTP Error 429: Too Many Requests (caused by <HTTPError 429: Too Many Requests>)
[download] 100% of    4.66MiB                             WARNING: [youtube] Unable to download webpage: HTTP Error 429: Too Many Requests (caused by <HTTPError 429: Too Many Requests>)
[download] 100% of    4.66MiB                             WARNING: [youtube] Unable to download webpage: HTTP Error 429: Too Many Requests (caused by <HTTPError 429: Too Many Requests>)
[download] 100% of    4.66MiB                             WARNING: [youtube] Unable to download webpage: HTTP Error 429: Too Many Requests (caused by <HTTPError 429: Too Many Requests>)
[download]   0.0% of    5.17MiB at  Unknown B/s ETA Unknown[download]   0.1% of    5.17MiB at  Unknown B/s ETA Unknown[download]   0.1% of    5.17MiB at    6.54MiB/s ETA 00:00  [download]   0.3% of    5.17MiB at   11.71MiB/s ETA 00:00[download]   0.6% of    5.17MiB at    3.65MiB/s ETA 00:01[download]   1.2% of    5.17MiB at    3.77MiB/s ETA 00:01[download]   2.4% of    5.17MiB at    5.09MiB/s ETA 00:00[download]   4.8% of    5.17MiB at    7.67MiB/s ETA 00:00[download]   9.7% of    5.17MiB at   12.38MiB/s ETA 00:00[download]  19.3% of    5.17MiB at   20.10MiB/s ETA 00:00[download]  38.7% of    5.17MiB at   33.85MiB/s ETA 00:00[download]  77.3% of    5.17MiB at   51.73MiB/s ETA 00:00[download] 100.0% of    5.17MiB at   56.64MiB/s ETA 00:00[download] 100% of    5.17MiB in 00:00:00 at 20.22MiB/s                                                         WARNING: [youtube] Unable to download webpage: HTTP Error 429: Too Many Requests (caused by <HTTPError 429: Too Many Requests>)
[download] 100% of    5.17MiB                             WARNING: [youtube] Unable to download webpage: HTTP Error 429: Too Many Requests (caused by <HTTPError 429: Too Many Requests>)
[download] 100% of    5.17MiB                             WARNING: [youtube] Unable to download webpage: HTTP Error 429: Too Many Requests (caused by <HTTPError 429: Too Many Requests>)
[download] 100% of    5.17MiB                             WARNING: [youtube] Unable to download webpage: HTTP Error 429: Too Many Requests (caused by <HTTPError 429: Too Many Requests>)
[download] 100% of    5.17MiB                             WARNING: [youtube] Unable to download webpage: HTTP Error 429: Too Many Requests (caused by <HTTPError 429: Too Many Requests>)
[download] 100% of    5.17MiB                             WARNING: [youtube] Unable to download webpage: HTTP Error 429: Too Many Requests (caused by <HTTPError 429: Too Many Requests>)
[download] 100% of    5.17MiB                             WARNING: [youtube] Unable to download webpage: HTTP Error 429: Too Many Requests (caused by <HTTPError 429: Too Many Requests>)
[download] 100% of    5.17MiB                             WARNING: [youtube] Unable to download webpage: HTTP Error 429: Too Many Requests (caused by <HTTPError 429: Too Many Requests>)
[download] 100% of    5.17MiB                             WARNING: [youtube] Unable to download webpage: HTTP Error 429: Too Many Requests (caused by <HTTPError 429: Too Many Requests>)
[download] 100% of    5.17MiB                             WARNING: [youtube] Unable to download webpage: HTTP Error 429: Too Many Requests (caused by <HTTPError 429: Too Many Requests>)
[download] 100% of    5.17MiB                             WARNING: [youtube] Unable to download webpage: HTTP Error 429: Too Many Requests (caused by <HTTPError 429: Too Many Requests>)
[download] 100% of    5.17MiB                             WARNING: [youtube] Unable to download webpage: HTTP Error 429: Too Many Requests (caused by <HTTPError 429: Too Many Requests>)
[download] 100% of    5.17MiB                             WARNING: [youtube] Unable to download webpage: HTTP Error 429: Too Many Requests (caused by <HTTPError 429: Too Many Requests>)
[download] 100% of    5.17MiB                             WARNING: [youtube] Unable to download webpage: HTTP Error 429: Too Many Requests (caused by <HTTPError 429: Too Many Requests>)
[download] 100% of    5.17MiB                             WARNING: [youtube] Unable to download webpage: HTTP Error 429: Too Many Requests (caused by <HTTPError 429: Too Many Requests>)
[download] 100% of    5.17MiB                             WARNING: [youtube] Unable to download webpage: HTTP Error 429: Too Many Requests (caused by <HTTPError 429: Too Many Requests>)
[download] 100% of    5.17MiB                             WARNING: [youtube] Unable to download webpage: HTTP Error 429: Too Many Requests (caused by <HTTPError 429: Too Many Requests>)
[download] 100% of    5.17MiB                             WARNING: [youtube] Unable to download webpage: HTTP Error 429: Too Many Requests (caused by <HTTPError 429: Too Many Requests>)
[download] 100% of    5.17MiB                             WARNING: [youtube] Unable to download webpage: HTTP Error 429: Too Many Requests (caused by <HTTPError 429: Too Many Requests>)
[download] 100% of    5.17MiB                             WARNING: [youtube] Unable to download webpage: HTTP Error 429: Too Many Requests (caused by <HTTPError 429: Too Many Requests>)
[download] 100% of    5.17MiB                             WARNING: [youtube] Unable to download webpage: HTTP Error 429: Too Many Requests (caused by <HTTPError 429: Too Many Requests>)
[download] 100% of    5.17MiB                             WARNING: [youtube] Unable to download webpage: HTTP Error 429: Too Many Requests (caused by <HTTPError 429: Too Many Requests>)
[download] 100% of    5.17MiB                             WARNING: [youtube] Unable to download webpage: HTTP Error 429: Too Many Requests (caused by <HTTPError 429: Too Many Requests>)
[download] 100% of    5.17MiB                             WARNING: [youtube] Unable to download webpage: HTTP Error 429: Too Many Requests (caused by <HTTPError 429: Too Many Requests>)
[download] 100% of    5.17MiB                             WARNING: [youtube] Unable to download webpage: HTTP Error 429: Too Many Requests (caused by <HTTPError 429: Too Many Requests>)
[download] 100% of    5.17MiB                             WARNING: [youtube] Unable to download webpage: HTTP Error 429: Too Many Requests (caused by <HTTPError 429: Too Many Requests>)
[download] 100% of    5.17MiB                             WARNING: [youtube] Unable to download webpage: HTTP Error 429: Too Many Requests (caused by <HTTPError 429: Too Many Requests>)
[download] 100% of    5.17MiB                             WARNING: [youtube] Unable to download webpage: HTTP Error 429: Too Many Requests (caused by <HTTPError 429: Too Many Requests>)
[download] 100% of    5.17MiB                             WARNING: [youtube] Unable to download webpage: HTTP Error 429: Too Many Requests (caused by <HTTPError 429: Too Many Requests>)
[download] 100% of    5.17MiB                             WARNING: [youtube] Unable to download webpage: HTTP Error 429: Too Many Requests (caused by <HTTPError 429: Too Many Requests>)
[download] 100% of    5.17MiB                             WARNING: [youtube] Unable to download webpage: HTTP Error 429: Too Many Requests (caused by <HTTPError 429: Too Many Requests>)
[download] 100% of    5.17MiB                             WARNING: [youtube] Unable to download webpage: HTTP Error 429: Too Many Requests (caused by <HTTPError 429: Too Many Requests>)
[download] 100% of    5.17MiB                             WARNING: [youtube] Unable to download webpage: HTTP Error 429: Too Many Requests (caused by <HTTPError 429: Too Many Requests>)
[download] 100% of    5.17MiB                             WARNING: [youtube] Unable to download webpage: HTTP Error 429: Too Many Requests (caused by <HTTPError 429: Too Many Requests>)
[download] 100% of    5.17MiB                             WARNING: [youtube] Unable to download webpage: HTTP Error 429: Too Many Requests (caused by <HTTPError 429: Too Many Requests>)
[download] 100% of    5.17MiB                             WARNING: [youtube] Unable to download webpage: HTTP Error 429: Too Many Requests (caused by <HTTPError 429: Too Many Requests>)
[download] 100% of    5.17MiB                             WARNING: [youtube] Unable to download webpage: HTTP Error 429: Too Many Requests (caused by <HTTPError 429: Too Many Requests>)
[download] 100% of    5.17MiB                             WARNING: [youtube] Unable to download webpage: HTTP Error 429: Too Many Requests (caused by <HTTPError 429: Too Many Requests>)
[download] 100% of    5.17MiB                             WARNING: [youtube] Unable to download webpage: HTTP Error 429: Too Many Requests (caused by <HTTPError 429: Too Many Requests>)
[download] 100% of    5.17MiB                             WARNING: [youtube] Unable to download webpage: HTTP Error 429: Too Many Requests (caused by <HTTPError 429: Too Many Requests>)
[download] 100% of    5.17MiB                             WARNING: [youtube] Unable to download webpage: HTTP Error 429: Too Many Requests (caused by <HTTPError 429: Too Many Requests>)
[download] 100% of    5.17MiB                             WARNING: [youtube] Unable to download webpage: HTTP Error 429: Too Many Requests (caused by <HTTPError 429: Too Many Requests>)
[download] 100% of    5.17MiB                             WARNING: [youtube] Unable to download webpage: HTTP Error 429: Too Many Requests (caused by <HTTPError 429: Too Many Requests>)
[download] 100% of    5.17MiB                             WARNING: [youtube] Unable to download webpage: HTTP Error 429: Too Many Requests (caused by <HTTPError 429: Too Many Requests>)
[download] 100% of    5.17MiB                             WARNING: [youtube] Unable to download webpage: HTTP Error 429: Too Many Requests (caused by <HTTPError 429: Too Many Requests>)
[download] 100% of    5.17MiB                             WARNING: [youtube] Unable to download webpage: HTTP Error 429: Too Many Requests (caused by <HTTPError 429: Too Many Requests>)
[download] 100% of    5.17MiB                             WARNING: [youtube] Unable to download webpage: HTTP Error 429: Too Many Requests (caused by <HTTPError 429: Too Many Requests>)
[download] 100% of    5.17MiB                             WARNING: [youtube] Unable to download webpage: HTTP Error 429: Too Many Requests (caused by <HTTPError 429: Too Many Requests>)
[download] 100% of    5.17MiB                             WARNING: [youtube] Unable to download webpage: HTTP Error 429: Too Many Requests (caused by <HTTPError 429: Too Many Requests>)
[download] 100% of    5.17MiB                             WARNING: [youtube] Unable to download webpage: HTTP Error 429: Too Many Requests (caused by <HTTPError 429: Too Many Requests>)
[download] 100% of    5.17MiB                             WARNING: [youtube] Unable to download webpage: HTTP Error 429: Too Many Requests (caused by <HTTPError 429: Too Many Requests>)
[download] 100% of    5.17MiB                             WARNING: [youtube] Unable to download webpage: HTTP Error 429: Too Many Requests (caused by <HTTPError 429: Too Many Requests>)
[download] 100% of    5.17MiB                             WARNING: [youtube] Unable to download webpage: HTTP Error 429: Too Many Requests (caused by <HTTPError 429: Too Many Requests>)
[download] 100% of    5.17MiB                             n occurred:

Traceback (most recent call last):
  File "/workspace/venv/lib/python3.13/site-packages/pyrogram/client.py", line 569, in handle_updates
    channel=await self.resolve_peer(utils.get_channel_id(channel_id)),
            ^^^^^^^^^^^^^^^^^^^^^^^^^^^^^^^^^^^^^^^^^^^^^^^^^^^^^^^^^
  File "/workspace/venv/lib/python3.13/site-packages/pyrogram/methods/advanced/resolve_peer.py", line 89, in resolve_peer
    peer_type = utils.get_peer_type(peer_id)
  File "/workspace/venv/lib/python3.13/site-packages/pyrogram/utils.py", line 246, in get_peer_type
    raise ValueError(f"Peer id invalid: {peer_id}")
ValueError: Peer id invalid: -1002524216878
ERROR: [youtube] 6Q8e8tmKWMI: Sign in to confirm you’re not a bot. Use --cookies-from-browser or --cookies for the authentication. See  https://github.com/yt-dlp/yt-dlp/wiki/FAQ#how-do-i-pass-cookies-to-yt-dlp  for how to manually pass cookies. Also see  https://github.com/yt-dlp/yt-dlp/wiki/Extractors#exporting-youtube-cookies  for tips on effectively exporting YouTube cookies
[download] 100% of    4.66MiB[PATCH] ntgcalls compatibility aliases created successfully
🔍 التحقق من وجود قاعدة البيانات...
✅ قاعدة البيانات موجودة بالفعل - لا حاجة لإنشاء حساب جديد
PyTgCalls v1.0.9 powered by NTgCalls v1.2.3, Copyright (C) 2021-2025 Laky-64 <https://github.com/Laky-64>
Licensed under the terms of the GNU Lesser General Public License v3 or later (LGPLv3+)

[93mUpdate Available!
New PyTgCalls v2.2.5 is now available!
[0m
                             [16-Aug-25 03:46:08 - ERROR] - asyncio - Task exception was never retrieved
future: <Task finished name='Task-591' coro=<Client.handle_updates() done, defined at /workspace/venv/lib/python3.13/site-packages/pyrogram/client.py:535> exception=ValueError('Peer id invalid: -1002524216878')>
Traceback (most recent call last):
  File "/workspace/venv/lib/python3.13/site-packages/pyrogram/methods/advanced/resolve_peer.py", line 62, in resolve_peer
    return await self.storage.get_peer_by_id(peer_id)
           ^^^^^^^^^^^^^^^^^^^^^^^^^^^^^^^^^^^^^^^^^^
  File "/workspace/venv/lib/python3.13/site-packages/pyrogram/storage/sqlite_storage.py", line 142, in get_peer_by_id
    raise KeyError(f"ID not found: {peer_id}")
KeyError: 'ID not found: -1002524216878'

During handling of the above exception, another exception occurred:

Traceback (most recent call last):
  File "/workspace/venv/lib/python3.13/site-packages/pyrogram/client.py", line 569, in handle_updates
    channel=await self.resolve_peer(utils.get_channel_id(channel_id)),
            ^^^^^^^^^^^^^^^^^^^^^^^^^^^^^^^^^^^^^^^^^^^^^^^^^^^^^^^^^
  File "/workspace/venv/lib/python3.13/site-packages/pyrogram/methods/advanced/resolve_peer.py", line 89, in resolve_peer
    peer_type = utils.get_peer_type(peer_id)
  File "/workspace/venv/lib/python3.13/site-packages/pyrogram/utils.py", line 246, in get_peer_type
    raise ValueError(f"Peer id invalid: {peer_id}")
ValueError: Peer id invalid: -1002524216878
[16-Aug-25 03:46:08 - ERROR] - asyncio - Task exception was never retrieved
future: <Task finished name='Task-592' coro=<Client.handle_updates() done, defined at /workspace/venv/lib/python3.13/site-packages/pyrogram/client.py:535> exception=ValueError('Peer id invalid: -1002524216878')>
Traceback (most recent call last):
  File "/workspace/venv/lib/python3.13/site-packages/pyrogram/methods/advanced/resolve_peer.py", line 62, in resolve_peer
    return await self.storage.get_peer_by_id(peer_id)
           ^^^^^^^^^^^^^^^^^^^^^^^^^^^^^^^^^^^^^^^^^^
  File "/workspace/venv/lib/python3.13/site-packages/pyrogram/storage/sqlite_storage.py", line 142, in get_peer_by_id
    raise KeyError(f"ID not found: {peer_id}")
KeyError: 'ID not found: -1002524216878'

During handling of the above exception, another exception occurred:

Traceback (most recent call last):
  File "/workspace/venv/lib/python3.13/site-packages/pyrogram/client.py", line 569, in handle_updates
    channel=await self.resolve_peer(utils.get_channel_id(channel_id)),
            ^^^^^^^^^^^^^^^^^^^^^^^^^^^^^^^^^^^^^^^^^^^^^^^^^^^^^^^^^
  File "/workspace/venv/lib/python3.13/site-packages/pyrogram/methods/advanced/resolve_peer.py", line 89, in resolve_peer
    peer_type = utils.get_peer_type(peer_id)
  File "/workspace/venv/lib/python3.13/site-packages/pyrogram/utils.py", line 246, in get_peer_type
    raise ValueError(f"Peer id invalid: {peer_id}")
ValueError: Peer id invalid: -1002524216878
[16-Aug-25 03:46:08 - ERROR] - asyncio - Task exception was never retrieved
future: <Task finished name='Task-593' coro=<Client.handle_updates() done, defined at /workspace/venv/lib/python3.13/site-packages/pyrogram/client.py:535> exception=ValueError('Peer id invalid: -1002725376687')>
Traceback (most recent call last):
  File "/workspace/venv/lib/python3.13/site-packages/pyrogram/methods/advanced/resolve_peer.py", line 62, in resolve_peer
    return await self.storage.get_peer_by_id(peer_id)
           ^^^^^^^^^^^^^^^^^^^^^^^^^^^^^^^^^^^^^^^^^^
  File "/workspace/venv/lib/python3.13/site-packages/pyrogram/storage/sqlite_storage.py", line 142, in get_peer_by_id
    raise KeyError(f"ID not found: {peer_id}")
KeyError: 'ID not found: -1002725376687'

During handling of the above exception, another exception occurred:

Traceback (most recent call last):
  File "/workspace/venv/lib/python3.13/site-packages/pyrogram/client.py", line 569, in handle_updates
    channel=await self.resolve_peer(utils.get_channel_id(channel_id)),
            ^^^^^^^^^^^^^^^^^^^^^^^^^^^^^^^^^^^^^^^^^^^^^^^^^^^^^^^^^
  File "/workspace/venv/lib/python3.13/site-packages/pyrogram/methods/advanced/resolve_peer.py", line 89, in resolve_peer
    peer_type = utils.get_peer_type(peer_id)
  File "/workspace/venv/lib/python3.13/site-packages/pyrogram/utils.py", line 246, in get_peer_type
    raise ValueError(f"Peer id invalid: {peer_id}")
ValueError: Peer id invalid: -1002725376687
[16-Aug-25 03:46:08 - ERROR] - asyncio - Task exception was never retrieved
future: <Task finished name='Task-594' coro=<Client.handle_updates() done, defined at /workspace/venv/lib/python3.13/site-packages/pyrogram/client.py:535> exception=ValueError('Peer id invalid: -1002725376687')>
Traceback (most recent call last):
  File "/workspace/venv/lib/python3.13/site-packages/pyrogram/methods/advanced/resolve_peer.py", line 62, in resolve_peer
    return await self.storage.get_peer_by_id(peer_id)
           ^^^^^^^^^^^^^^^^^^^^^^^^^^^^^^^^^^^^^^^^^^
  File "/workspace/venv/lib/python3.13/site-packages/pyrogram/storage/sqlite_storage.py", line 142, in get_peer_by_id
    raise KeyError(f"ID not found: {peer_id}")
KeyError: 'ID not found: -1002725376687'

During handling of the above exception, another exception occurred:

Traceback (most recent call last):
  File "/workspace/venv/lib/python3.13/site-packages/pyrogram/client.py", line 569, in handle_updates
    channel=await self.resolve_peer(utils.get_channel_id(channel_id)),
            ^^^^^^^^^^^^^^^^^^^^^^^^^^^^^^^^^^^^^^^^^^^^^^^^^^^^^^^^^
  File "/workspace/venv/lib/python3.13/site-packages/pyrogram/methods/advanced/resolve_peer.py", line 89, in resolve_peer
    peer_type = utils.get_peer_type(peer_id)
  File "/workspace/venv/lib/python3.13/site-packages/pyrogram/utils.py", line 246, in get_peer_type
    raise ValueError(f"Peer id invalid: {peer_id}")
ValueError: Peer id invalid: -1002725376687
[16-Aug-25 03:46:08 - ERROR] - asyncio - Task exception was never retrieved
future: <Task finished name='Task-597' coro=<Client.handle_updates() done, defined at /workspace/venv/lib/python3.13/site-packages/pyrogram/client.py:535> exception=ValueError('Peer id invalid: -1002524216878')>
Traceback (most recent call last):
  File "/workspace/venv/lib/python3.13/site-packages/pyrogram/methods/advanced/resolve_peer.py", line 62, in resolve_peer
    return await self.storage.get_peer_by_id(peer_id)
           ^^^^^^^^^^^^^^^^^^^^^^^^^^^^^^^^^^^^^^^^^^
  File "/workspace/venv/lib/python3.13/site-packages/pyrogram/storage/sqlite_storage.py", line 142, in get_peer_by_id
    raise KeyError(f"ID not found: {peer_id}")
KeyError: 'ID not found: -1002524216878'

During handling of the above exception, another exception occurred:

Traceback (most recent call last):
  File "/workspace/venv/lib/python3.13/site-packages/pyrogram/client.py", line 569, in handle_updates
    channel=await self.resolve_peer(utils.get_channel_id(channel_id)),
            ^^^^^^^^^^^^^^^^^^^^^^^^^^^^^^^^^^^^^^^^^^^^^^^^^^^^^^^^^
  File "/workspace/venv/lib/python3.13/site-packages/pyrogram/methods/advanced/resolve_peer.py", line 89, in resolve_peer
    peer_type = utils.get_peer_type(peer_id)
  File "/workspace/venv/lib/python3.13/site-packages/pyrogram/utils.py", line 246, in get_peer_type
    raise ValueError(f"Peer id invalid: {peer_id}")
ValueError: Peer id invalid: -1002524216878
[16-Aug-25 03:46:09 - ERROR] - asyncio - Task exception was never retrieved
future: <Task finished name='Task-609' coro=<Client.handle_updates() done, defined at /workspace/venv/lib/python3.13/site-packages/pyrogram/client.py:535> exception=ValueError('Peer id invalid: -1002725376687')>
Traceback (most recent call last):
  File "/workspace/venv/lib/python3.13/site-packages/pyrogram/methods/advanced/resolve_peer.py", line 62, in resolve_peer
    return await self.storage.get_peer_by_id(peer_id)
           ^^^^^^^^^^^^^^^^^^^^^^^^^^^^^^^^^^^^^^^^^^
  File "/workspace/venv/lib/python3.13/site-packages/pyrogram/storage/sqlite_storage.py", line 142, in get_peer_by_id
    raise KeyError(f"ID not found: {peer_id}")
KeyError: 'ID not found: -1002725376687'

During handling of the above exception, another exception occurred:

Traceback (most recent call last):
  File "/workspace/venv/lib/python3.13/site-packages/pyrogram/client.py", line 569, in handle_updates
    channel=await self.resolve_peer(utils.get_channel_id(channel_id)),
            ^^^^^^^^^^^^^^^^^^^^^^^^^^^^^^^^^^^^^^^^^^^^^^^^^^^^^^^^^
  File "/workspace/venv/lib/python3.13/site-packages/pyrogram/methods/advanced/resolve_peer.py", line 89, in resolve_peer
    peer_type = utils.get_peer_type(peer_id)
  File "/workspace/venv/lib/python3.13/site-packages/pyrogram/utils.py", line 246, in get_peer_type
    raise ValueError(f"Peer id invalid: {peer_id}")
ValueError: Peer id invalid: -1002725376687
[16-Aug-25 03:46:09 - ERROR] - asyncio - Task exception was never retrieved
future: <Task finished name='Task-612' coro=<Client.handle_updates() done, defined at /workspace/venv/lib/python3.13/site-packages/pyrogram/client.py:535> exception=ValueError('Peer id invalid: -1002725376687')>
Traceback (most recent call last):
  File "/workspace/venv/lib/python3.13/site-packages/pyrogram/methods/advanced/resolve_peer.py", line 62, in resolve_peer
    return await self.storage.get_peer_by_id(peer_id)
           ^^^^^^^^^^^^^^^^^^^^^^^^^^^^^^^^^^^^^^^^^^
  File "/workspace/venv/lib/python3.13/site-packages/pyrogram/storage/sqlite_storage.py", line 142, in get_peer_by_id
    raise KeyError(f"ID not found: {peer_id}")
KeyError: 'ID not found: -1002725376687'

During handling of the above exception, another exception occurred:

Traceback (most recent call last):
  File "/workspace/venv/lib/python3.13/site-packages/pyrogram/client.py", line 569, in handle_updates
    channel=await self.resolve_peer(utils.get_channel_id(channel_id)),
            ^^^^^^^^^^^^^^^^^^^^^^^^^^^^^^^^^^^^^^^^^^^^^^^^^^^^^^^^^
  File "/workspace/venv/lib/python3.13/site-packages/pyrogram/methods/advanced/resolve_peer.py", line 89, in resolve_peer
    peer_type = utils.get_peer_type(peer_id)
  File "/workspace/venv/lib/python3.13/site-packages/pyrogram/utils.py", line 246, in get_peer_type
    raise ValueError(f"Peer id invalid: {peer_id}")
ValueError: Peer id invalid: -1002725376687
[16-Aug-25 03:46:10 - ERROR] - asyncio - Task exception was never retrieved
future: <Task finished name='Task-618' coro=<Client.handle_updates() done, defined at /workspace/venv/lib/python3.13/site-packages/pyrogram/client.py:535> exception=ValueError('Peer id invalid: -1002725376687')>
Traceback (most recent call last):
  File "/workspace/venv/lib/python3.13/site-packages/pyrogram/methods/advanced/resolve_peer.py", line 62, in resolve_peer
    return await self.storage.get_peer_by_id(peer_id)
           ^^^^^^^^^^^^^^^^^^^^^^^^^^^^^^^^^^^^^^^^^^
  File "/workspace/venv/lib/python3.13/site-packages/pyrogram/storage/sqlite_storage.py", line 142, in get_peer_by_id
    raise KeyError(f"ID not found: {peer_id}")
KeyError: 'ID not found: -1002725376687'

During handling of the above exception, another exception occurred:

Traceback (most recent call last):
  File "/workspace/venv/lib/python3.13/site-packages/pyrogram/client.py", line 569, in handle_updates
    channel=await self.resolve_peer(utils.get_channel_id(channel_id)),
            ^^^^^^^^^^^^^^^^^^^^^^^^^^^^^^^^^^^^^^^^^^^^^^^^^^^^^^^^^
  File "/workspace/venv/lib/python3.13/site-packages/pyrogram/methods/advanced/resolve_peer.py", line 89, in resolve_peer
    peer_type = utils.get_peer_type(peer_id)
  File "/workspace/venv/lib/python3.13/site-packages/pyrogram/utils.py", line 246, in get_peer_type
    raise ValueError(f"Peer id invalid: {peer_id}")
ValueError: Peer id invalid: -1002725376687
[16-Aug-25 03:46:11 - ERROR] - asyncio - Task exception was never retrieved
future: <Task finished name='Task-630' coro=<Client.handle_updates() done, defined at /workspace/venv/lib/python3.13/site-packages/pyrogram/client.py:535> exception=ValueError('Peer id invalid: -1002725376687')>
Traceback (most recent call last):
  File "/workspace/venv/lib/python3.13/site-packages/pyrogram/methods/advanced/resolve_peer.py", line 62, in resolve_peer
    return await self.storage.get_peer_by_id(peer_id)
           ^^^^^^^^^^^^^^^^^^^^^^^^^^^^^^^^^^^^^^^^^^
  File "/workspace/venv/lib/python3.13/site-packages/pyrogram/storage/sqlite_storage.py", line 142, in get_peer_by_id
    raise KeyError(f"ID not found: {peer_id}")
KeyError: 'ID not found: -1002725376687'

During handling of the above exception, another exception occurred:

Traceback (most recent call last):
  File "/workspace/venv/lib/python3.13/site-packages/pyrogram/client.py", line 569, in handle_updates
    channel=await self.resolve_peer(utils.get_channel_id(channel_id)),
            ^^^^^^^^^^^^^^^^^^^^^^^^^^^^^^^^^^^^^^^^^^^^^^^^^^^^^^^^^
  File "/workspace/venv/lib/python3.13/site-packages/pyrogram/methods/advanced/resolve_peer.py", line 89, in resolve_peer
    peer_type = utils.get_peer_type(peer_id)
  File "/workspace/venv/lib/python3.13/site-packages/pyrogram/utils.py", line 246, in get_peer_type
    raise ValueError(f"Peer id invalid: {peer_id}")
ValueError: Peer id invalid: -1002725376687
[16-Aug-25 03:46:19 - ERROR] - asyncio - Task exception was never retrieved
future: <Task finished name='Task-652' coro=<Client.handle_updates() done, defined at /workspace/venv/lib/python3.13/site-packages/pyrogram/client.py:535> exception=ValueError('Peer id invalid: -1002725376687')>
Traceback (most recent call last):
  File "/workspace/venv/lib/python3.13/site-packages/pyrogram/methods/advanced/resolve_peer.py", line 62, in resolve_peer
    return await self.storage.get_peer_by_id(peer_id)
           ^^^^^^^^^^^^^^^^^^^^^^^^^^^^^^^^^^^^^^^^^^
  File "/workspace/venv/lib/python3.13/site-packages/pyrogram/storage/sqlite_storage.py", line 142, in get_peer_by_id
    raise KeyError(f"ID not found: {peer_id}")
KeyError: 'ID not found: -1002725376687'

During handling of the above exception, another exception occurred:

Traceback (most recent call last):
  File "/workspace/venv/lib/python3.13/site-packages/pyrogram/client.py", line 569, in handle_updates
    channel=await self.resolve_peer(utils.get_channel_id(channel_id)),
            ^^^^^^^^^^^^^^^^^^^^^^^^^^^^^^^^^^^^^^^^^^^^^^^^^^^^^^^^^
  File "/workspace/venv/lib/python3.13/site-packages/pyrogram/methods/advanced/resolve_peer.py", line 89, in resolve_peer
    peer_type = utils.get_peer_type(peer_id)
  File "/workspace/venv/lib/python3.13/site-packages/pyrogram/utils.py", line 246, in get_peer_type
    raise ValueError(f"Peer id invalid: {peer_id}")
ValueError: Peer id invalid: -1002725376687
[16-Aug-25 03:46:19 - ERROR] - asyncio - Task exception was never retrieved
future: <Task finished name='Task-654' coro=<Client.handle_updates() done, defined at /workspace/venv/lib/python3.13/site-packages/pyrogram/client.py:535> exception=ValueError('Peer id invalid: -1002725376687')>
Traceback (most recent call last):
  File "/workspace/venv/lib/python3.13/site-packages/pyrogram/methods/advanced/resolve_peer.py", line 62, in resolve_peer
    return await self.storage.get_peer_by_id(peer_id)
           ^^^^^^^^^^^^^^^^^^^^^^^^^^^^^^^^^^^^^^^^^^
  File "/workspace/venv/lib/python3.13/site-packages/pyrogram/storage/sqlite_storage.py", line 142, in get_peer_by_id
    raise KeyError(f"ID not found: {peer_id}")
KeyError: 'ID not found: -1002725376687'

During handling of the above exception, another exception occurred:

Traceback (most recent call last):
  File "/workspace/venv/lib/python3.13/site-packages/pyrogram/client.py", line 569, in handle_updates
    channel=await self.resolve_peer(utils.get_channel_id(channel_id)),
            ^^^^^^^^^^^^^^^^^^^^^^^^^^^^^^^^^^^^^^^^^^^^^^^^^^^^^^^^^
  File "/workspace/venv/lib/python3.13/site-packages/pyrogram/methods/advanced/resolve_peer.py", line 89, in resolve_peer
    peer_type = utils.get_peer_type(peer_id)
  File "/workspace/venv/lib/python3.13/site-packages/pyrogram/utils.py", line 246, in get_peer_type
    raise ValueError(f"Peer id invalid: {peer_id}")
ValueError: Peer id invalid: -1002725376687
[16-Aug-25 03:46:27 - ERROR] - asyncio - Task exception was never retrieved
future: <Task finished name='Task-664' coro=<Client.handle_updates() done, defined at /workspace/venv/lib/python3.13/site-packages/pyrogram/client.py:535> exception=ValueError('Peer id invalid: -1002725376687')>
Traceback (most recent call last):
  File "/workspace/venv/lib/python3.13/site-packages/pyrogram/methods/advanced/resolve_peer.py", line 62, in resolve_peer
    return await self.storage.get_peer_by_id(peer_id)
           ^^^^^^^^^^^^^^^^^^^^^^^^^^^^^^^^^^^^^^^^^^
  File "/workspace/venv/lib/python3.13/site-packages/pyrogram/storage/sqlite_storage.py", line 142, in get_peer_by_id
    raise KeyError(f"ID not found: {peer_id}")
KeyError: 'ID not found: -1002725376687'

During handling of the above exception, another exception occurred:

Traceback (most recent call last):
  File "/workspace/venv/lib/python3.13/site-packages/pyrogram/client.py", line 569, in handle_updates
    channel=await self.resolve_peer(utils.get_channel_id(channel_id)),
            ^^^^^^^^^^^^^^^^^^^^^^^^^^^^^^^^^^^^^^^^^^^^^^^^^^^^^^^^^
  File "/workspace/venv/lib/python3.13/site-packages/pyrogram/methods/advanced/resolve_peer.py", line 89, in resolve_peer
    peer_type = utils.get_peer_type(peer_id)
  File "/workspace/venv/lib/python3.13/site-packages/pyrogram/utils.py", line 246, in get_peer_type
    raise ValueError(f"Peer id invalid: {peer_id}")
ValueError: Peer id invalid: -1002725376687
[16-Aug-25 03:46:34 - ERROR] - asyncio - Task exception was never retrieved
future: <Task finished name='Task-675' coro=<Client.handle_updates() done, defined at /workspace/venv/lib/python3.13/site-packages/pyrogram/client.py:535> exception=ValueError('Peer id invalid: -1002725376687')>
Traceback (most recent call last):
  File "/workspace/venv/lib/python3.13/site-packages/pyrogram/methods/advanced/resolve_peer.py", line 62, in resolve_peer
    return await self.storage.get_peer_by_id(peer_id)
           ^^^^^^^^^^^^^^^^^^^^^^^^^^^^^^^^^^^^^^^^^^
  File "/workspace/venv/lib/python3.13/site-packages/pyrogram/storage/sqlite_storage.py", line 142, in get_peer_by_id
    raise KeyError(f"ID not found: {peer_id}")
KeyError: 'ID not found: -1002725376687'

During handling of the above exception, another exception occurred:

Traceback (most recent call last):
  File "/workspace/venv/lib/python3.13/site-packages/pyrogram/client.py", line 569, in handle_updates
    channel=await self.resolve_peer(utils.get_channel_id(channel_id)),
            ^^^^^^^^^^^^^^^^^^^^^^^^^^^^^^^^^^^^^^^^^^^^^^^^^^^^^^^^^
  File "/workspace/venv/lib/python3.13/site-packages/pyrogram/methods/advanced/resolve_peer.py", line 89, in resolve_peer
    peer_type = utils.get_peer_type(peer_id)
  File "/workspace/venv/lib/python3.13/site-packages/pyrogram/utils.py", line 246, in get_peer_type
    raise ValueError(f"Peer id invalid: {peer_id}")
ValueError: Peer id invalid: -1002725376687
[16-Aug-25 03:46:36 - ERROR] - asyncio - Task exception was never retrieved
future: <Task finished name='Task-680' coro=<Client.handle_updates() done, defined at /workspace/venv/lib/python3.13/site-packages/pyrogram/client.py:535> exception=ValueError('Peer id invalid: -1002704003307')>
Traceback (most recent call last):
  File "/workspace/venv/lib/python3.13/site-packages/pyrogram/methods/advanced/resolve_peer.py", line 62, in resolve_peer
    return await self.storage.get_peer_by_id(peer_id)
           ^^^^^^^^^^^^^^^^^^^^^^^^^^^^^^^^^^^^^^^^^^
  File "/workspace/venv/lib/python3.13/site-packages/pyrogram/storage/sqlite_storage.py", line 142, in get_peer_by_id
    raise KeyError(f"ID not found: {peer_id}")
KeyError: 'ID not found: -1002704003307'

During handling of the above exception, another exception occurred:

Traceback (most recent call last):
  File "/workspace/venv/lib/python3.13/site-packages/pyrogram/client.py", line 569, in handle_updates
    channel=await self.resolve_peer(utils.get_channel_id(channel_id)),
            ^^^^^^^^^^^^^^^^^^^^^^^^^^^^^^^^^^^^^^^^^^^^^^^^^^^^^^^^^
  File "/workspace/venv/lib/python3.13/site-packages/pyrogram/methods/advanced/resolve_peer.py", line 89, in resolve_peer
    peer_type = utils.get_peer_type(peer_id)
  File "/workspace/venv/lib/python3.13/site-packages/pyrogram/utils.py", line 246, in get_peer_type
    raise ValueError(f"Peer id invalid: {peer_id}")
ValueError: Peer id invalid: -1002704003307
[16-Aug-25 03:46:37 - ERROR] - asyncio - Task exception was never retrieved
future: <Task finished name='Task-684' coro=<Client.handle_updates() done, defined at /workspace/venv/lib/python3.13/site-packages/pyrogram/client.py:535> exception=ValueError('Peer id invalid: -1002430970946')>
Traceback (most recent call last):
  File "/workspace/venv/lib/python3.13/site-packages/pyrogram/methods/advanced/resolve_peer.py", line 62, in resolve_peer
    return await self.storage.get_peer_by_id(peer_id)
           ^^^^^^^^^^^^^^^^^^^^^^^^^^^^^^^^^^^^^^^^^^
  File "/workspace/venv/lib/python3.13/site-packages/pyrogram/storage/sqlite_storage.py", line 142, in get_peer_by_id
    raise KeyError(f"ID not found: {peer_id}")
KeyError: 'ID not found: -1002430970946'

During handling of the above exception, another exception occurred:

Traceback (most recent call last):
  File "/workspace/venv/lib/python3.13/site-packages/pyrogram/client.py", line 569, in handle_updates
    channel=await self.resolve_peer(utils.get_channel_id(channel_id)),
            ^^^^^^^^^^^^^^^^^^^^^^^^^^^^^^^^^^^^^^^^^^^^^^^^^^^^^^^^^
  File "/workspace/venv/lib/python3.13/site-packages/pyrogram/methods/advanced/resolve_peer.py", line 89, in resolve_peer
    peer_type = utils.get_peer_type(peer_id)
  File "/workspace/venv/lib/python3.13/site-packages/pyrogram/utils.py", line 246, in get_peer_type
    raise ValueError(f"Peer id invalid: {peer_id}")
ValueError: Peer id invalid: -1002430970946
[16-Aug-25 03:46:37 - ERROR] - asyncio - Task exception was never retrieved
future: <Task finished name='Task-686' coro=<Client.handle_updates() done, defined at /workspace/venv/lib/python3.13/site-packages/pyrogram/client.py:535> exception=ValueError('Peer id invalid: -1002430970946')>
Traceback (most recent call last):
  File "/workspace/venv/lib/python3.13/site-packages/pyrogram/methods/advanced/resolve_peer.py", line 62, in resolve_peer
    return await self.storage.get_peer_by_id(peer_id)
           ^^^^^^^^^^^^^^^^^^^^^^^^^^^^^^^^^^^^^^^^^^
  File "/workspace/venv/lib/python3.13/site-packages/pyrogram/storage/sqlite_storage.py", line 142, in get_peer_by_id
    raise KeyError(f"ID not found: {peer_id}")
KeyError: 'ID not found: -1002430970946'

During handling of the above exception, another exception occurred:

Traceback (most recent call last):
  File "/workspace/venv/lib/python3.13/site-packages/pyrogram/client.py", line 569, in handle_updates
    channel=await self.resolve_peer(utils.get_channel_id(channel_id)),
            ^^^^^^^^^^^^^^^^^^^^^^^^^^^^^^^^^^^^^^^^^^^^^^^^^^^^^^^^^
  File "/workspace/venv/lib/python3.13/site-packages/pyrogram/methods/advanced/resolve_peer.py", line 89, in resolve_peer
    peer_type = utils.get_peer_type(peer_id)
  File "/workspace/venv/lib/python3.13/site-packages/pyrogram/utils.py", line 246, in get_peer_type
    raise ValueError(f"Peer id invalid: {peer_id}")
ValueError: Peer id invalid: -1002430970946
[16-Aug-25 03:46:38 - ERROR] - asyncio - Task exception was never retrieved
future: <Task finished name='Task-688' coro=<Client.handle_updates() done, defined at /workspace/venv/lib/python3.13/site-packages/pyrogram/client.py:535> exception=ValueError('Peer id invalid: -1002430970946')>
Traceback (most recent call last):
  File "/workspace/venv/lib/python3.13/site-packages/pyrogram/methods/advanced/resolve_peer.py", line 62, in resolve_peer
    return await self.storage.get_peer_by_id(peer_id)
           ^^^^^^^^^^^^^^^^^^^^^^^^^^^^^^^^^^^^^^^^^^
  File "/workspace/venv/lib/python3.13/site-packages/pyrogram/storage/sqlite_storage.py", line 142, in get_peer_by_id
    raise KeyError(f"ID not found: {peer_id}")
KeyError: 'ID not found: -1002430970946'

During handling of the above exception, another exception occurred:

Traceback (most recent call last):
  File "/workspace/venv/lib/python3.13/site-packages/pyrogram/client.py", line 569, in handle_updates
    channel=await self.resolve_peer(utils.get_channel_id(channel_id)),
            ^^^^^^^^^^^^^^^^^^^^^^^^^^^^^^^^^^^^^^^^^^^^^^^^^^^^^^^^^
  File "/workspace/venv/lib/python3.13/site-packages/pyrogram/methods/advanced/resolve_peer.py", line 89, in resolve_peer
    peer_type = utils.get_peer_type(peer_id)
  File "/workspace/venv/lib/python3.13/site-packages/pyrogram/utils.py", line 246, in get_peer_type
    raise ValueError(f"Peer id invalid: {peer_id}")
ValueError: Peer id invalid: -1002430970946
[16-Aug-25 03:46:39 - ERROR] - asyncio - Task exception was never retrieved
future: <Task finished name='Task-692' coro=<Client.handle_updates() done, defined at /workspace/venv/lib/python3.13/site-packages/pyrogram/client.py:535> exception=ValueError('Peer id invalid: -1002430970946')>
Traceback (most recent call last):
  File "/workspace/venv/lib/python3.13/site-packages/pyrogram/methods/advanced/resolve_peer.py", line 62, in resolve_peer
    return await self.storage.get_peer_by_id(peer_id)
           ^^^^^^^^^^^^^^^^^^^^^^^^^^^^^^^^^^^^^^^^^^
  File "/workspace/venv/lib/python3.13/site-packages/pyrogram/storage/sqlite_storage.py", line 142, in get_peer_by_id
    raise KeyError(f"ID not found: {peer_id}")
KeyError: 'ID not found: -1002430970946'

During handling of the above exception, another exception occurred:

Traceback (most recent call last):
  File "/workspace/venv/lib/python3.13/site-packages/pyrogram/client.py", line 569, in handle_updates
    channel=await self.resolve_peer(utils.get_channel_id(channel_id)),
            ^^^^^^^^^^^^^^^^^^^^^^^^^^^^^^^^^^^^^^^^^^^^^^^^^^^^^^^^^
  File "/workspace/venv/lib/python3.13/site-packages/pyrogram/methods/advanced/resolve_peer.py", line 89, in resolve_peer
    peer_type = utils.get_peer_type(peer_id)
  File "/workspace/venv/lib/python3.13/site-packages/pyrogram/utils.py", line 246, in get_peer_type
    raise ValueError(f"Peer id invalid: {peer_id}")
ValueError: Peer id invalid: -1002430970946
[16-Aug-25 03:46:39 - ERROR] - asyncio - Task exception was never retrieved
future: <Task finished name='Task-694' coro=<Client.handle_updates() done, defined at /workspace/venv/lib/python3.13/site-packages/pyrogram/client.py:535> exception=ValueError('Peer id invalid: -1002430970946')>
Traceback (most recent call last):
  File "/workspace/venv/lib/python3.13/site-packages/pyrogram/methods/advanced/resolve_peer.py", line 62, in resolve_peer
    return await self.storage.get_peer_by_id(peer_id)
           ^^^^^^^^^^^^^^^^^^^^^^^^^^^^^^^^^^^^^^^^^^
  File "/workspace/venv/lib/python3.13/site-packages/pyrogram/storage/sqlite_storage.py", line 142, in get_peer_by_id
    raise KeyError(f"ID not found: {peer_id}")
KeyError: 'ID not found: -1002430970946'

During handling of the above exception, another exception occurred:

Traceback (most recent call last):
  File "/workspace/venv/lib/python3.13/site-packages/pyrogram/client.py", line 569, in handle_updates
    channel=await self.resolve_peer(utils.get_channel_id(channel_id)),
            ^^^^^^^^^^^^^^^^^^^^^^^^^^^^^^^^^^^^^^^^^^^^^^^^^^^^^^^^^
  File "/workspace/venv/lib/python3.13/site-packages/pyrogram/methods/advanced/resolve_peer.py", line 89, in resolve_peer
    peer_type = utils.get_peer_type(peer_id)
  File "/workspace/venv/lib/python3.13/site-packages/pyrogram/utils.py", line 246, in get_peer_type
    raise ValueError(f"Peer id invalid: {peer_id}")
ValueError: Peer id invalid: -1002430970946
[16-Aug-25 03:46:40 - ERROR] - asyncio - Task exception was never retrieved
future: <Task finished name='Task-697' coro=<Client.handle_updates() done, defined at /workspace/venv/lib/python3.13/site-packages/pyrogram/client.py:535> exception=ValueError('Peer id invalid: -1002725376687')>
Traceback (most recent call last):
  File "/workspace/venv/lib/python3.13/site-packages/pyrogram/methods/advanced/resolve_peer.py", line 62, in resolve_peer
    return await self.storage.get_peer_by_id(peer_id)
           ^^^^^^^^^^^^^^^^^^^^^^^^^^^^^^^^^^^^^^^^^^
  File "/workspace/venv/lib/python3.13/site-packages/pyrogram/storage/sqlite_storage.py", line 142, in get_peer_by_id
    raise KeyError(f"ID not found: {peer_id}")
KeyError: 'ID not found: -1002725376687'

During handling of the above exception, another exception occurred:

Traceback (most recent call last):
  File "/workspace/venv/lib/python3.13/site-packages/pyrogram/client.py", line 569, in handle_updates
    channel=await self.resolve_peer(utils.get_channel_id(channel_id)),
            ^^^^^^^^^^^^^^^^^^^^^^^^^^^^^^^^^^^^^^^^^^^^^^^^^^^^^^^^^
  File "/workspace/venv/lib/python3.13/site-packages/pyrogram/methods/advanced/resolve_peer.py", line 89, in resolve_peer
    peer_type = utils.get_peer_type(peer_id)
  File "/workspace/venv/lib/python3.13/site-packages/pyrogram/utils.py", line 246, in get_peer_type
    raise ValueError(f"Peer id invalid: {peer_id}")
ValueError: Peer id invalid: -1002725376687
[16-Aug-25 03:46:42 - ERROR] - asyncio - Task exception was never retrieved
future: <Task finished name='Task-701' coro=<Client.handle_updates() done, defined at /workspace/venv/lib/python3.13/site-packages/pyrogram/client.py:535> exception=ValueError('Peer id invalid: -1002430970946')>
Traceback (most recent call last):
  File "/workspace/venv/lib/python3.13/site-packages/pyrogram/methods/advanced/resolve_peer.py", line 62, in resolve_peer
    return await self.storage.get_peer_by_id(peer_id)
           ^^^^^^^^^^^^^^^^^^^^^^^^^^^^^^^^^^^^^^^^^^
  File "/workspace/venv/lib/python3.13/site-packages/pyrogram/storage/sqlite_storage.py", line 142, in get_peer_by_id
    raise KeyError(f"ID not found: {peer_id}")
KeyError: 'ID not found: -1002430970946'

During handling of the above exception, another exception occurred:

Traceback (most recent call last):
  File "/workspace/venv/lib/python3.13/site-packages/pyrogram/client.py", line 569, in handle_updates
    channel=await self.resolve_peer(utils.get_channel_id(channel_id)),
            ^^^^^^^^^^^^^^^^^^^^^^^^^^^^^^^^^^^^^^^^^^^^^^^^^^^^^^^^^
  File "/workspace/venv/lib/python3.13/site-packages/pyrogram/methods/advanced/resolve_peer.py", line 89, in resolve_peer
    peer_type = utils.get_peer_type(peer_id)
  File "/workspace/venv/lib/python3.13/site-packages/pyrogram/utils.py", line 246, in get_peer_type
    raise ValueError(f"Peer id invalid: {peer_id}")
ValueError: Peer id invalid: -1002430970946
[16-Aug-25 03:46:42 - ERROR] - asyncio - Task exception was never retrieved
future: <Task finished name='Task-703' coro=<Client.handle_updates() done, defined at /workspace/venv/lib/python3.13/site-packages/pyrogram/client.py:535> exception=ValueError('Peer id invalid: -1002430970946')>
Traceback (most recent call last):
  File "/workspace/venv/lib/python3.13/site-packages/pyrogram/methods/advanced/resolve_peer.py", line 62, in resolve_peer
    return await self.storage.get_peer_by_id(peer_id)
           ^^^^^^^^^^^^^^^^^^^^^^^^^^^^^^^^^^^^^^^^^^
  File "/workspace/venv/lib/python3.13/site-packages/pyrogram/storage/sqlite_storage.py", line 142, in get_peer_by_id
    raise KeyError(f"ID not found: {peer_id}")
KeyError: 'ID not found: -1002430970946'

During handling of the above exception, another exception occurred:

Traceback (most recent call last):
  File "/workspace/venv/lib/python3.13/site-packages/pyrogram/client.py", line 569, in handle_updates
    channel=await self.resolve_peer(utils.get_channel_id(channel_id)),
            ^^^^^^^^^^^^^^^^^^^^^^^^^^^^^^^^^^^^^^^^^^^^^^^^^^^^^^^^^
  File "/workspace/venv/lib/python3.13/site-packages/pyrogram/methods/advanced/resolve_peer.py", line 89, in resolve_peer
    peer_type = utils.get_peer_type(peer_id)
  File "/workspace/venv/lib/python3.13/site-packages/pyrogram/utils.py", line 246, in get_peer_type
    raise ValueError(f"Peer id invalid: {peer_id}")
ValueError: Peer id invalid: -1002430970946
[16-Aug-25 03:46:51 - ERROR] - asyncio - Task exception was never retrieved
future: <Task finished name='Task-715' coro=<Client.handle_updates() done, defined at /workspace/venv/lib/python3.13/site-packages/pyrogram/client.py:535> exception=ValueError('Peer id invalid: -1002725376687')>
Traceback (most recent call last):
  File "/workspace/venv/lib/python3.13/site-packages/pyrogram/methods/advanced/resolve_peer.py", line 62, in resolve_peer
    return await self.storage.get_peer_by_id(peer_id)
           ^^^^^^^^^^^^^^^^^^^^^^^^^^^^^^^^^^^^^^^^^^
  File "/workspace/venv/lib/python3.13/site-packages/pyrogram/storage/sqlite_storage.py", line 142, in get_peer_by_id
    raise KeyError(f"ID not found: {peer_id}")
KeyError: 'ID not found: -1002725376687'

During handling of the above exception, another exception occurred:

Traceback (most recent call last):
  File "/workspace/venv/lib/python3.13/site-packages/pyrogram/client.py", line 569, in handle_updates
    channel=await self.resolve_peer(utils.get_channel_id(channel_id)),
            ^^^^^^^^^^^^^^^^^^^^^^^^^^^^^^^^^^^^^^^^^^^^^^^^^^^^^^^^^
  File "/workspace/venv/lib/python3.13/site-packages/pyrogram/methods/advanced/resolve_peer.py", line 89, in resolve_peer
    peer_type = utils.get_peer_type(peer_id)
  File "/workspace/venv/lib/python3.13/site-packages/pyrogram/utils.py", line 246, in get_peer_type
    raise ValueError(f"Peer id invalid: {peer_id}")
ValueError: Peer id invalid: -1002725376687
[16-Aug-25 03:46:51 - ERROR] - asyncio - Task exception was never retrieved
future: <Task finished name='Task-717' coro=<Client.handle_updates() done, defined at /workspace/venv/lib/python3.13/site-packages/pyrogram/client.py:535> exception=ValueError('Peer id invalid: -1002430970946')>
Traceback (most recent call last):
  File "/workspace/venv/lib/python3.13/site-packages/pyrogram/methods/advanced/resolve_peer.py", line 62, in resolve_peer
    return await self.storage.get_peer_by_id(peer_id)
           ^^^^^^^^^^^^^^^^^^^^^^^^^^^^^^^^^^^^^^^^^^
  File "/workspace/venv/lib/python3.13/site-packages/pyrogram/storage/sqlite_storage.py", line 142, in get_peer_by_id
    raise KeyError(f"ID not found: {peer_id}")
KeyError: 'ID not found: -1002430970946'

During handling of the above exception, another exception occurred:

Traceback (most recent call last):
  File "/workspace/venv/lib/python3.13/site-packages/pyrogram/client.py", line 569, in handle_updates
    channel=await self.resolve_peer(utils.get_channel_id(channel_id)),
            ^^^^^^^^^^^^^^^^^^^^^^^^^^^^^^^^^^^^^^^^^^^^^^^^^^^^^^^^^
  File "/workspace/venv/lib/python3.13/site-packages/pyrogram/methods/advanced/resolve_peer.py", line 89, in resolve_peer
    peer_type = utils.get_peer_type(peer_id)
  File "/workspace/venv/lib/python3.13/site-packages/pyrogram/utils.py", line 246, in get_peer_type
    raise ValueError(f"Peer id invalid: {peer_id}")
ValueError: Peer id invalid: -1002430970946
[16-Aug-25 03:46:54 - ERROR] - asyncio - Task exception was never retrieved
future: <Task finished name='Task-723' coro=<Client.handle_updates() done, defined at /workspace/venv/lib/python3.13/site-packages/pyrogram/client.py:535> exception=ValueError('Peer id invalid: -1002430970946')>
Traceback (most recent call last):
  File "/workspace/venv/lib/python3.13/site-packages/pyrogram/methods/advanced/resolve_peer.py", line 62, in resolve_peer
    return await self.storage.get_peer_by_id(peer_id)
           ^^^^^^^^^^^^^^^^^^^^^^^^^^^^^^^^^^^^^^^^^^
  File "/workspace/venv/lib/python3.13/site-packages/pyrogram/storage/sqlite_storage.py", line 142, in get_peer_by_id
    raise KeyError(f"ID not found: {peer_id}")
KeyError: 'ID not found: -1002430970946'

During handling of the above exception, another exception occurred:

Traceback (most recent call last):
  File "/workspace/venv/lib/python3.13/site-packages/pyrogram/client.py", line 569, in handle_updates
    channel=await self.resolve_peer(utils.get_channel_id(channel_id)),
            ^^^^^^^^^^^^^^^^^^^^^^^^^^^^^^^^^^^^^^^^^^^^^^^^^^^^^^^^^
  File "/workspace/venv/lib/python3.13/site-packages/pyrogram/methods/advanced/resolve_peer.py", line 89, in resolve_peer
    peer_type = utils.get_peer_type(peer_id)
  File "/workspace/venv/lib/python3.13/site-packages/pyrogram/utils.py", line 246, in get_peer_type
    raise ValueError(f"Peer id invalid: {peer_id}")
ValueError: Peer id invalid: -1002430970946
[16-Aug-25 03:46:54 - ERROR] - asyncio - Task exception was never retrieved
future: <Task finished name='Task-725' coro=<Client.handle_updates() done, defined at /workspace/venv/lib/python3.13/site-packages/pyrogram/client.py:535> exception=ValueError('Peer id invalid: -1002704003307')>
Traceback (most recent call last):
  File "/workspace/venv/lib/python3.13/site-packages/pyrogram/methods/advanced/resolve_peer.py", line 62, in resolve_peer
    return await self.storage.get_peer_by_id(peer_id)
           ^^^^^^^^^^^^^^^^^^^^^^^^^^^^^^^^^^^^^^^^^^
  File "/workspace/venv/lib/python3.13/site-packages/pyrogram/storage/sqlite_storage.py", line 142, in get_peer_by_id
    raise KeyError(f"ID not found: {peer_id}")
KeyError: 'ID not found: -1002704003307'

During handling of the above exception, another exception occurred:

Traceback (most recent call last):
  File "/workspace/venv/lib/python3.13/site-packages/pyrogram/client.py", line 569, in handle_updates
    channel=await self.resolve_peer(utils.get_channel_id(channel_id)),
            ^^^^^^^^^^^^^^^^^^^^^^^^^^^^^^^^^^^^^^^^^^^^^^^^^^^^^^^^^
  File "/workspace/venv/lib/python3.13/site-packages/pyrogram/methods/advanced/resolve_peer.py", line 89, in resolve_peer
    peer_type = utils.get_peer_type(peer_id)
  File "/workspace/venv/lib/python3.13/site-packages/pyrogram/utils.py", line 246, in get_peer_type
    raise ValueError(f"Peer id invalid: {peer_id}")
ValueError: Peer id invalid: -1002704003307
[16-Aug-25 03:46:54 - ERROR] - asyncio - Task exception was never retrieved
future: <Task finished name='Task-727' coro=<Client.handle_updates() done, defined at /workspace/venv/lib/python3.13/site-packages/pyrogram/client.py:535> exception=ValueError('Peer id invalid: -1002704003307')>
Traceback (most recent call last):
  File "/workspace/venv/lib/python3.13/site-packages/pyrogram/methods/advanced/resolve_peer.py", line 62, in resolve_peer
    return await self.storage.get_peer_by_id(peer_id)
           ^^^^^^^^^^^^^^^^^^^^^^^^^^^^^^^^^^^^^^^^^^
  File "/workspace/venv/lib/python3.13/site-packages/pyrogram/storage/sqlite_storage.py", line 142, in get_peer_by_id
    raise KeyError(f"ID not found: {peer_id}")
KeyError: 'ID not found: -1002704003307'

During handling of the above exception, another exception occurred:

Traceback (most recent call last):
  File "/workspace/venv/lib/python3.13/site-packages/pyrogram/client.py", line 569, in handle_updates
    channel=await self.resolve_peer(utils.get_channel_id(channel_id)),
            ^^^^^^^^^^^^^^^^^^^^^^^^^^^^^^^^^^^^^^^^^^^^^^^^^^^^^^^^^
  File "/workspace/venv/lib/python3.13/site-packages/pyrogram/methods/advanced/resolve_peer.py", line 89, in resolve_peer
    peer_type = utils.get_peer_type(peer_id)
  File "/workspace/venv/lib/python3.13/site-packages/pyrogram/utils.py", line 246, in get_peer_type
    raise ValueError(f"Peer id invalid: {peer_id}")
ValueError: Peer id invalid: -1002704003307
[16-Aug-25 03:46:54 - ERROR] - asyncio - Task exception was never retrieved
future: <Task finished name='Task-729' coro=<Client.handle_updates() done, defined at /workspace/venv/lib/python3.13/site-packages/pyrogram/client.py:535> exception=ValueError('Peer id invalid: -1002704003307')>
Traceback (most recent call last):
  File "/workspace/venv/lib/python3.13/site-packages/pyrogram/methods/advanced/resolve_peer.py", line 62, in resolve_peer
    return await self.storage.get_peer_by_id(peer_id)
           ^^^^^^^^^^^^^^^^^^^^^^^^^^^^^^^^^^^^^^^^^^
  File "/workspace/venv/lib/python3.13/site-packages/pyrogram/storage/sqlite_storage.py", line 142, in get_peer_by_id
    raise KeyError(f"ID not found: {peer_id}")
KeyError: 'ID not found: -1002704003307'

During handling of the above exception, another exception occurred:

Traceback (most recent call last):
  File "/workspace/venv/lib/python3.13/site-packages/pyrogram/client.py", line 569, in handle_updates
    channel=await self.resolve_peer(utils.get_channel_id(channel_id)),
            ^^^^^^^^^^^^^^^^^^^^^^^^^^^^^^^^^^^^^^^^^^^^^^^^^^^^^^^^^
  File "/workspace/venv/lib/python3.13/site-packages/pyrogram/methods/advanced/resolve_peer.py", line 89, in resolve_peer
    peer_type = utils.get_peer_type(peer_id)
  File "/workspace/venv/lib/python3.13/site-packages/pyrogram/utils.py", line 246, in get_peer_type
    raise ValueError(f"Peer id invalid: {peer_id}")
ValueError: Peer id invalid: -1002704003307
[16-Aug-25 03:46:54 - ERROR] - asyncio - Task exception was never retrieved
future: <Task finished name='Task-731' coro=<Client.handle_updates() done, defined at /workspace/venv/lib/python3.13/site-packages/pyrogram/client.py:535> exception=ValueError('Peer id invalid: -1002704003307')>
Traceback (most recent call last):
  File "/workspace/venv/lib/python3.13/site-packages/pyrogram/methods/advanced/resolve_peer.py", line 62, in resolve_peer
    return await self.storage.get_peer_by_id(peer_id)
           ^^^^^^^^^^^^^^^^^^^^^^^^^^^^^^^^^^^^^^^^^^
  File "/workspace/venv/lib/python3.13/site-packages/pyrogram/storage/sqlite_storage.py", line 142, in get_peer_by_id
    raise KeyError(f"ID not found: {peer_id}")
KeyError: 'ID not found: -1002704003307'

During handling of the above exception, another exception occurred:

Traceback (most recent call last):
  File "/workspace/venv/lib/python3.13/site-packages/pyrogram/client.py", line 569, in handle_updates
    channel=await self.resolve_peer(utils.get_channel_id(channel_id)),
            ^^^^^^^^^^^^^^^^^^^^^^^^^^^^^^^^^^^^^^^^^^^^^^^^^^^^^^^^^
  File "/workspace/venv/lib/python3.13/site-packages/pyrogram/methods/advanced/resolve_peer.py", line 89, in resolve_peer
    peer_type = utils.get_peer_type(peer_id)
  File "/workspace/venv/lib/python3.13/site-packages/pyrogram/utils.py", line 246, in get_peer_type
    raise ValueError(f"Peer id invalid: {peer_id}")
ValueError: Peer id invalid: -1002704003307
[16-Aug-25 03:46:55 - ERROR] - asyncio - Task exception was never retrieved
future: <Task finished name='Task-733' coro=<Client.handle_updates() done, defined at /workspace/venv/lib/python3.13/site-packages/pyrogram/client.py:535> exception=ValueError('Peer id invalid: -1002704003307')>
Traceback (most recent call last):
  File "/workspace/venv/lib/python3.13/site-packages/pyrogram/methods/advanced/resolve_peer.py", line 62, in resolve_peer
    return await self.storage.get_peer_by_id(peer_id)
           ^^^^^^^^^^^^^^^^^^^^^^^^^^^^^^^^^^^^^^^^^^
  File "/workspace/venv/lib/python3.13/site-packages/pyrogram/storage/sqlite_storage.py", line 142, in get_peer_by_id
    raise KeyError(f"ID not found: {peer_id}")
KeyError: 'ID not found: -1002704003307'

During handling of the above exception, another exception occurred:

Traceback (most recent call last):
  File "/workspace/venv/lib/python3.13/site-packages/pyrogram/client.py", line 569, in handle_updates
    channel=await self.resolve_peer(utils.get_channel_id(channel_id)),
            ^^^^^^^^^^^^^^^^^^^^^^^^^^^^^^^^^^^^^^^^^^^^^^^^^^^^^^^^^
  File "/workspace/venv/lib/python3.13/site-packages/pyrogram/methods/advanced/resolve_peer.py", line 89, in resolve_peer
    peer_type = utils.get_peer_type(peer_id)
  File "/workspace/venv/lib/python3.13/site-packages/pyrogram/utils.py", line 246, in get_peer_type
    raise ValueError(f"Peer id invalid: {peer_id}")
ValueError: Peer id invalid: -1002704003307
[16-Aug-25 03:46:55 - ERROR] - asyncio - Task exception was never retrieved
future: <Task finished name='Task-736' coro=<Client.handle_updates() done, defined at /workspace/venv/lib/python3.13/site-packages/pyrogram/client.py:535> exception=ValueError('Peer id invalid: -1002704003307')>
Traceback (most recent call last):
  File "/workspace/venv/lib/python3.13/site-packages/pyrogram/methods/advanced/resolve_peer.py", line 62, in resolve_peer
    return await self.storage.get_peer_by_id(peer_id)
           ^^^^^^^^^^^^^^^^^^^^^^^^^^^^^^^^^^^^^^^^^^
  File "/workspace/venv/lib/python3.13/site-packages/pyrogram/storage/sqlite_storage.py", line 142, in get_peer_by_id
    raise KeyError(f"ID not found: {peer_id}")
KeyError: 'ID not found: -1002704003307'

During handling of the above exception, another exception occurred:

Traceback (most recent call last):
  File "/workspace/venv/lib/python3.13/site-packages/pyrogram/client.py", line 569, in handle_updates
    channel=await self.resolve_peer(utils.get_channel_id(channel_id)),
            ^^^^^^^^^^^^^^^^^^^^^^^^^^^^^^^^^^^^^^^^^^^^^^^^^^^^^^^^^
  File "/workspace/venv/lib/python3.13/site-packages/pyrogram/methods/advanced/resolve_peer.py", line 89, in resolve_peer
    peer_type = utils.get_peer_type(peer_id)
  File "/workspace/venv/lib/python3.13/site-packages/pyrogram/utils.py", line 246, in get_peer_type
    raise ValueError(f"Peer id invalid: {peer_id}")
ValueError: Peer id invalid: -1002704003307
[16-Aug-25 03:47:03 - ERROR] - asyncio - Task exception was never retrieved
future: <Task finished name='Task-747' coro=<Client.handle_updates() done, defined at /workspace/venv/lib/python3.13/site-packages/pyrogram/client.py:535> exception=ValueError('Peer id invalid: -1002430970946')>
Traceback (most recent call last):
  File "/workspace/venv/lib/python3.13/site-packages/pyrogram/methods/advanced/resolve_peer.py", line 62, in resolve_peer
    return await self.storage.get_peer_by_id(peer_id)
           ^^^^^^^^^^^^^^^^^^^^^^^^^^^^^^^^^^^^^^^^^^
  File "/workspace/venv/lib/python3.13/site-packages/pyrogram/storage/sqlite_storage.py", line 142, in get_peer_by_id
    raise KeyError(f"ID not found: {peer_id}")
KeyError: 'ID not found: -1002430970946'

During handling of the above exception, another exception occurred:

Traceback (most recent call last):
  File "/workspace/venv/lib/python3.13/site-packages/pyrogram/client.py", line 569, in handle_updates
    channel=await self.resolve_peer(utils.get_channel_id(channel_id)),
            ^^^^^^^^^^^^^^^^^^^^^^^^^^^^^^^^^^^^^^^^^^^^^^^^^^^^^^^^^
  File "/workspace/venv/lib/python3.13/site-packages/pyrogram/methods/advanced/resolve_peer.py", line 89, in resolve_peer
    peer_type = utils.get_peer_type(peer_id)
  File "/workspace/venv/lib/python3.13/site-packages/pyrogram/utils.py", line 246, in get_peer_type
    raise ValueError(f"Peer id invalid: {peer_id}")
ValueError: Peer id invalid: -1002430970946
[16-Aug-25 03:47:06 - ERROR] - asyncio - Task exception was never retrieved
future: <Task finished name='Task-752' coro=<Client.handle_updates() done, defined at /workspace/venv/lib/python3.13/site-packages/pyrogram/client.py:535> exception=ValueError('Peer id invalid: -1002590071792')>
Traceback (most recent call last):
  File "/workspace/venv/lib/python3.13/site-packages/pyrogram/methods/advanced/resolve_peer.py", line 62, in resolve_peer
    return await self.storage.get_peer_by_id(peer_id)
           ^^^^^^^^^^^^^^^^^^^^^^^^^^^^^^^^^^^^^^^^^^
  File "/workspace/venv/lib/python3.13/site-packages/pyrogram/storage/sqlite_storage.py", line 142, in get_peer_by_id
    raise KeyError(f"ID not found: {peer_id}")
KeyError: 'ID not found: -1002590071792'

During handling of the above exception, another exception occurred:

Traceback (most recent call last):
  File "/workspace/venv/lib/python3.13/site-packages/pyrogram/client.py", line 569, in handle_updates
    channel=await self.resolve_peer(utils.get_channel_id(channel_id)),
            ^^^^^^^^^^^^^^^^^^^^^^^^^^^^^^^^^^^^^^^^^^^^^^^^^^^^^^^^^
  File "/workspace/venv/lib/python3.13/site-packages/pyrogram/methods/advanced/resolve_peer.py", line 89, in resolve_peer
    peer_type = utils.get_peer_type(peer_id)
  File "/workspace/venv/lib/python3.13/site-packages/pyrogram/utils.py", line 246, in get_peer_type
    raise ValueError(f"Peer id invalid: {peer_id}")
ValueError: Peer id invalid: -1002590071792
[16-Aug-25 03:47:07 - ERROR] - asyncio - Task exception was never retrieved
future: <Task finished name='Task-754' coro=<Client.handle_updates() done, defined at /workspace/venv/lib/python3.13/site-packages/pyrogram/client.py:535> exception=ValueError('Peer id invalid: -1002430970946')>
Traceback (most recent call last):
  File "/workspace/venv/lib/python3.13/site-packages/pyrogram/methods/advanced/resolve_peer.py", line 62, in resolve_peer
    return await self.storage.get_peer_by_id(peer_id)
           ^^^^^^^^^^^^^^^^^^^^^^^^^^^^^^^^^^^^^^^^^^
  File "/workspace/venv/lib/python3.13/site-packages/pyrogram/storage/sqlite_storage.py", line 142, in get_peer_by_id
    raise KeyError(f"ID not found: {peer_id}")
KeyError: 'ID not found: -1002430970946'

During handling of the above exception, another exception occurred:

Traceback (most recent call last):
  File "/workspace/venv/lib/python3.13/site-packages/pyrogram/client.py", line 569, in handle_updates
    channel=await self.resolve_peer(utils.get_channel_id(channel_id)),
            ^^^^^^^^^^^^^^^^^^^^^^^^^^^^^^^^^^^^^^^^^^^^^^^^^^^^^^^^^
  File "/workspace/venv/lib/python3.13/site-packages/pyrogram/methods/advanced/resolve_peer.py", line 89, in resolve_peer
    peer_type = utils.get_peer_type(peer_id)
  File "/workspace/venv/lib/python3.13/site-packages/pyrogram/utils.py", line 246, in get_peer_type
    raise ValueError(f"Peer id invalid: {peer_id}")
ValueError: Peer id invalid: -1002430970946
[16-Aug-25 03:47:10 - ERROR] - asyncio - Task exception was never retrieved
future: <Task finished name='Task-759' coro=<Client.handle_updates() done, defined at /workspace/venv/lib/python3.13/site-packages/pyrogram/client.py:535> exception=ValueError('Peer id invalid: -1002430970946')>
Traceback (most recent call last):
  File "/workspace/venv/lib/python3.13/site-packages/pyrogram/methods/advanced/resolve_peer.py", line 62, in resolve_peer
    return await self.storage.get_peer_by_id(peer_id)
           ^^^^^^^^^^^^^^^^^^^^^^^^^^^^^^^^^^^^^^^^^^
  File "/workspace/venv/lib/python3.13/site-packages/pyrogram/storage/sqlite_storage.py", line 142, in get_peer_by_id
    raise KeyError(f"ID not found: {peer_id}")
KeyError: 'ID not found: -1002430970946'

During handling of the above exception, another exception occurred:

Traceback (most recent call last):
  File "/workspace/venv/lib/python3.13/site-packages/pyrogram/client.py", line 569, in handle_updates
    channel=await self.resolve_peer(utils.get_channel_id(channel_id)),
            ^^^^^^^^^^^^^^^^^^^^^^^^^^^^^^^^^^^^^^^^^^^^^^^^^^^^^^^^^
  File "/workspace/venv/lib/python3.13/site-packages/pyrogram/methods/advanced/resolve_peer.py", line 89, in resolve_peer
    peer_type = utils.get_peer_type(peer_id)
  File "/workspace/venv/lib/python3.13/site-packages/pyrogram/utils.py", line 246, in get_peer_type
    raise ValueError(f"Peer id invalid: {peer_id}")
ValueError: Peer id invalid: -1002430970946
[16-Aug-25 03:47:12 - ERROR] - asyncio - Task exception was never retrieved
future: <Task finished name='Task-763' coro=<Client.handle_updates() done, defined at /workspace/venv/lib/python3.13/site-packages/pyrogram/client.py:535> exception=ValueError('Peer id invalid: -1002524216878')>
Traceback (most recent call last):
  File "/workspace/venv/lib/python3.13/site-packages/pyrogram/methods/advanced/resolve_peer.py", line 62, in resolve_peer
    return await self.storage.get_peer_by_id(peer_id)
           ^^^^^^^^^^^^^^^^^^^^^^^^^^^^^^^^^^^^^^^^^^
  File "/workspace/venv/lib/python3.13/site-packages/pyrogram/storage/sqlite_storage.py", line 142, in get_peer_by_id
    raise KeyError(f"ID not found: {peer_id}")
KeyError: 'ID not found: -1002524216878'

During handling of the above exception, another exception occurred:

Traceback (most recent call last):
  File "/workspace/venv/lib/python3.13/site-packages/pyrogram/client.py", line 569, in handle_updates
    channel=await self.resolve_peer(utils.get_channel_id(channel_id)),
            ^^^^^^^^^^^^^^^^^^^^^^^^^^^^^^^^^^^^^^^^^^^^^^^^^^^^^^^^^
  File "/workspace/venv/lib/python3.13/site-packages/pyrogram/methods/advanced/resolve_peer.py", line 89, in resolve_peer
    peer_type = utils.get_peer_type(peer_id)
  File "/workspace/venv/lib/python3.13/site-packages/pyrogram/utils.py", line 246, in get_peer_type
    raise ValueError(f"Peer id invalid: {peer_id}")
ValueError: Peer id invalid: -1002524216878
[16-Aug-25 03:47:16 - ERROR] - asyncio - Task exception was never retrieved
future: <Task finished name='Task-770' coro=<Client.handle_updates() done, defined at /workspace/venv/lib/python3.13/site-packages/pyrogram/client.py:535> exception=ValueError('Peer id invalid: -1002430970946')>
Traceback (most recent call last):
  File "/workspace/venv/lib/python3.13/site-packages/pyrogram/methods/advanced/resolve_peer.py", line 62, in resolve_peer
    return await self.storage.get_peer_by_id(peer_id)
           ^^^^^^^^^^^^^^^^^^^^^^^^^^^^^^^^^^^^^^^^^^
  File "/workspace/venv/lib/python3.13/site-packages/pyrogram/storage/sqlite_storage.py", line 142, in get_peer_by_id
    raise KeyError(f"ID not found: {peer_id}")
KeyError: 'ID not found: -1002430970946'

During handling of the above exception, another exception occurred:

Traceback (most recent call last):
  File "/workspace/venv/lib/python3.13/site-packages/pyrogram/client.py", line 569, in handle_updates
    channel=await self.resolve_peer(utils.get_channel_id(channel_id)),
            ^^^^^^^^^^^^^^^^^^^^^^^^^^^^^^^^^^^^^^^^^^^^^^^^^^^^^^^^^
  File "/workspace/venv/lib/python3.13/site-packages/pyrogram/methods/advanced/resolve_peer.py", line 89, in resolve_peer
    peer_type = utils.get_peer_type(peer_id)
  File "/workspace/venv/lib/python3.13/site-packages/pyrogram/utils.py", line 246, in get_peer_type
    raise ValueError(f"Peer id invalid: {peer_id}")
ValueError: Peer id invalid: -1002430970946
[16-Aug-25 03:47:20 - ERROR] - asyncio - Task exception was never retrieved
future: <Task finished name='Task-777' coro=<Client.handle_updates() done, defined at /workspace/venv/lib/python3.13/site-packages/pyrogram/client.py:535> exception=ValueError('Peer id invalid: -1002430970946')>
Traceback (most recent call last):
  File "/workspace/venv/lib/python3.13/site-packages/pyrogram/methods/advanced/resolve_peer.py", line 62, in resolve_peer
    return await self.storage.get_peer_by_id(peer_id)
           ^^^^^^^^^^^^^^^^^^^^^^^^^^^^^^^^^^^^^^^^^^
  File "/workspace/venv/lib/python3.13/site-packages/pyrogram/storage/sqlite_storage.py", line 142, in get_peer_by_id
    raise KeyError(f"ID not found: {peer_id}")
KeyError: 'ID not found: -1002430970946'

During handling of the above exception, another exception occurred:

Traceback (most recent call last):
  File "/workspace/venv/lib/python3.13/site-packages/pyrogram/client.py", line 569, in handle_updates
    channel=await self.resolve_peer(utils.get_channel_id(channel_id)),
            ^^^^^^^^^^^^^^^^^^^^^^^^^^^^^^^^^^^^^^^^^^^^^^^^^^^^^^^^^
  File "/workspace/venv/lib/python3.13/site-packages/pyrogram/methods/advanced/resolve_peer.py", line 89, in resolve_peer
    peer_type = utils.get_peer_type(peer_id)
  File "/workspace/venv/lib/python3.13/site-packages/pyrogram/utils.py", line 246, in get_peer_type
    raise ValueError(f"Peer id invalid: {peer_id}")
ValueError: Peer id invalid: -1002430970946
[16-Aug-25 03:47:24 - ERROR] - asyncio - Task exception was never retrieved
future: <Task finished name='Task-783' coro=<Client.handle_updates() done, defined at /workspace/venv/lib/python3.13/site-packages/pyrogram/client.py:535> exception=ValueError('Peer id invalid: -1002430970946')>
Traceback (most recent call last):
  File "/workspace/venv/lib/python3.13/site-packages/pyrogram/methods/advanced/resolve_peer.py", line 62, in resolve_peer
    return await self.storage.get_peer_by_id(peer_id)
           ^^^^^^^^^^^^^^^^^^^^^^^^^^^^^^^^^^^^^^^^^^
  File "/workspace/venv/lib/python3.13/site-packages/pyrogram/storage/sqlite_storage.py", line 142, in get_peer_by_id
    raise KeyError(f"ID not found: {peer_id}")
KeyError: 'ID not found: -1002430970946'

During handling of the above exception, another exception occurred:

Traceback (most recent call last):
  File "/workspace/venv/lib/python3.13/site-packages/pyrogram/client.py", line 569, in handle_updates
    channel=await self.resolve_peer(utils.get_channel_id(channel_id)),
            ^^^^^^^^^^^^^^^^^^^^^^^^^^^^^^^^^^^^^^^^^^^^^^^^^^^^^^^^^
  File "/workspace/venv/lib/python3.13/site-packages/pyrogram/methods/advanced/resolve_peer.py", line 89, in resolve_peer
    peer_type = utils.get_peer_type(peer_id)
  File "/workspace/venv/lib/python3.13/site-packages/pyrogram/utils.py", line 246, in get_peer_type
    raise ValueError(f"Peer id invalid: {peer_id}")
ValueError: Peer id invalid: -1002430970946
[16-Aug-25 03:47:27 - ERROR] - pyrogram.dispatcher - Peer id invalid: -1002430970946
Traceback (most recent call last):
  File "/workspace/venv/lib/python3.13/site-packages/pyrogram/methods/advanced/resolve_peer.py", line 62, in resolve_peer
    return await self.storage.get_peer_by_id(peer_id)
           ^^^^^^^^^^^^^^^^^^^^^^^^^^^^^^^^^^^^^^^^^^
  File "/workspace/venv/lib/python3.13/site-packages/pyrogram/storage/sqlite_storage.py", line 142, in get_peer_by_id
    raise KeyError(f"ID not found: {peer_id}")
KeyError: 'ID not found: -1002430970946'

During handling of the above exception, another exception occurred:

Traceback (most recent call last):
  File "/workspace/venv/lib/python3.13/site-packages/pyrogram/dispatcher.py", line 214, in handler_worker
    await parser(update, users, chats)
  File "/workspace/venv/lib/python3.13/site-packages/pyrogram/dispatcher.py", line 75, in edited_message_parser
    parsed, _ = await message_parser(update, users, chats)
                ^^^^^^^^^^^^^^^^^^^^^^^^^^^^^^^^^^^^^^^^^^
  File "/workspace/venv/lib/python3.13/site-packages/pyrogram/dispatcher.py", line 68, in message_parser
    await pyrogram.types.Message._parse(self.client, update.message, users, chats,
    ^^^^^^^^^^^^^^^^^^^^^^^^^^^^^^^^^^^^^^^^^^^^^^^^^^^^^^^^^^^^^^^^^^^^^^^^^^^^^^
                                        isinstance(update, UpdateNewScheduledMessage)),
                                        ^^^^^^^^^^^^^^^^^^^^^^^^^^^^^^^^^^^^^^^^^^^^^^
  File "/workspace/venv/lib/python3.13/site-packages/pyrogram/types/messages_and_media/message.py", line 836, in _parse
    reply_to_message = await client.get_messages(
                       ^^^^^^^^^^^^^^^^^^^^^^^^^^
    ...<3 lines>...
    )
    ^
  File "/workspace/venv/lib/python3.13/site-packages/pyrogram/methods/messages/get_messages.py", line 101, in get_messages
    peer = await self.resolve_peer(chat_id)
           ^^^^^^^^^^^^^^^^^^^^^^^^^^^^^^^^
  File "/workspace/venv/lib/python3.13/site-packages/pyrogram/methods/advanced/resolve_peer.py", line 89, in resolve_peer
    peer_type = utils.get_peer_type(peer_id)
  File "/workspace/venv/lib/python3.13/site-packages/pyrogram/utils.py", line 246, in get_peer_type
    raise ValueError(f"Peer id invalid: {peer_id}")
ValueError: Peer id invalid: -1002430970946
[16-Aug-25 03:47:29 - ERROR] - asyncio - Task exception was never retrieved
future: <Task finished name='Task-792' coro=<Client.handle_updates() done, defined at /workspace/venv/lib/python3.13/site-packages/pyrogram/client.py:535> exception=ValueError('Peer id invalid: -1002430970946')>
Traceback (most recent call last):
  File "/workspace/venv/lib/python3.13/site-packages/pyrogram/methods/advanced/resolve_peer.py", line 62, in resolve_peer
    return await self.storage.get_peer_by_id(peer_id)
           ^^^^^^^^^^^^^^^^^^^^^^^^^^^^^^^^^^^^^^^^^^
  File "/workspace/venv/lib/python3.13/site-packages/pyrogram/storage/sqlite_storage.py", line 142, in get_peer_by_id
    raise KeyError(f"ID not found: {peer_id}")
KeyError: 'ID not found: -1002430970946'

During handling of the above exception, another exception occurred:

Traceback (most recent call last):
  File "/workspace/venv/lib/python3.13/site-packages/pyrogram/client.py", line 569, in handle_updates
    channel=await self.resolve_peer(utils.get_channel_id(channel_id)),
            ^^^^^^^^^^^^^^^^^^^^^^^^^^^^^^^^^^^^^^^^^^^^^^^^^^^^^^^^^
  File "/workspace/venv/lib/python3.13/site-packages/pyrogram/methods/advanced/resolve_peer.py", line 89, in resolve_peer
    peer_type = utils.get_peer_type(peer_id)
  File "/workspace/venv/lib/python3.13/site-packages/pyrogram/utils.py", line 246, in get_peer_type
    raise ValueError(f"Peer id invalid: {peer_id}")
ValueError: Peer id invalid: -1002430970946
[16-Aug-25 03:47:33 - ERROR] - asyncio - Task exception was never retrieved
future: <Task finished name='Task-799' coro=<Client.handle_updates() done, defined at /workspace/venv/lib/python3.13/site-packages/pyrogram/client.py:535> exception=ValueError('Peer id invalid: -1002704003307')>
Traceback (most recent call last):
  File "/workspace/venv/lib/python3.13/site-packages/pyrogram/methods/advanced/resolve_peer.py", line 62, in resolve_peer
    return await self.storage.get_peer_by_id(peer_id)
           ^^^^^^^^^^^^^^^^^^^^^^^^^^^^^^^^^^^^^^^^^^
  File "/workspace/venv/lib/python3.13/site-packages/pyrogram/storage/sqlite_storage.py", line 142, in get_peer_by_id
    raise KeyError(f"ID not found: {peer_id}")
KeyError: 'ID not found: -1002704003307'

During handling of the above exception, another exception occurred:

Traceback (most recent call last):
  File "/workspace/venv/lib/python3.13/site-packages/pyrogram/client.py", line 569, in handle_updates
    channel=await self.resolve_peer(utils.get_channel_id(channel_id)),
            ^^^^^^^^^^^^^^^^^^^^^^^^^^^^^^^^^^^^^^^^^^^^^^^^^^^^^^^^^
  File "/workspace/venv/lib/python3.13/site-packages/pyrogram/methods/advanced/resolve_peer.py", line 89, in resolve_peer
    peer_type = utils.get_peer_type(peer_id)
  File "/workspace/venv/lib/python3.13/site-packages/pyrogram/utils.py", line 246, in get_peer_type
    raise ValueError(f"Peer id invalid: {peer_id}")
ValueError: Peer id invalid: -1002704003307
[16-Aug-25 03:47:33 - ERROR] - asyncio - Task exception was never retrieved
future: <Task finished name='Task-801' coro=<Client.handle_updates() done, defined at /workspace/venv/lib/python3.13/site-packages/pyrogram/client.py:535> exception=ValueError('Peer id invalid: -1002704003307')>
Traceback (most recent call last):
  File "/workspace/venv/lib/python3.13/site-packages/pyrogram/methods/advanced/resolve_peer.py", line 62, in resolve_peer
    return await self.storage.get_peer_by_id(peer_id)
           ^^^^^^^^^^^^^^^^^^^^^^^^^^^^^^^^^^^^^^^^^^
  File "/workspace/venv/lib/python3.13/site-packages/pyrogram/storage/sqlite_storage.py", line 142, in get_peer_by_id
    raise KeyError(f"ID not found: {peer_id}")
KeyError: 'ID not found: -1002704003307'

During handling of the above exception, another exception occurred:

Traceback (most recent call last):
  File "/workspace/venv/lib/python3.13/site-packages/pyrogram/client.py", line 569, in handle_updates
    channel=await self.resolve_peer(utils.get_channel_id(channel_id)),
            ^^^^^^^^^^^^^^^^^^^^^^^^^^^^^^^^^^^^^^^^^^^^^^^^^^^^^^^^^
  File "/workspace/venv/lib/python3.13/site-packages/pyrogram/methods/advanced/resolve_peer.py", line 89, in resolve_peer
    peer_type = utils.get_peer_type(peer_id)
  File "/workspace/venv/lib/python3.13/site-packages/pyrogram/utils.py", line 246, in get_peer_type
    raise ValueError(f"Peer id invalid: {peer_id}")
ValueError: Peer id invalid: -1002704003307
[16-Aug-25 03:47:35 - ERROR] - asyncio - Task exception was never retrieved
future: <Task finished name='Task-806' coro=<Client.handle_updates() done, defined at /workspace/venv/lib/python3.13/site-packages/pyrogram/client.py:535> exception=ValueError('Peer id invalid: -1002704003307')>
Traceback (most recent call last):
  File "/workspace/venv/lib/python3.13/site-packages/pyrogram/methods/advanced/resolve_peer.py", line 62, in resolve_peer
    return await self.storage.get_peer_by_id(peer_id)
           ^^^^^^^^^^^^^^^^^^^^^^^^^^^^^^^^^^^^^^^^^^
  File "/workspace/venv/lib/python3.13/site-packages/pyrogram/storage/sqlite_storage.py", line 142, in get_peer_by_id
    raise KeyError(f"ID not found: {peer_id}")
KeyError: 'ID not found: -1002704003307'

During handling of the above exception, another exception occurred:

Traceback (most recent call last):
  File "/workspace/venv/lib/python3.13/site-packages/pyrogram/client.py", line 569, in handle_updates
    channel=await self.resolve_peer(utils.get_channel_id(channel_id)),
            ^^^^^^^^^^^^^^^^^^^^^^^^^^^^^^^^^^^^^^^^^^^^^^^^^^^^^^^^^
  File "/workspace/venv/lib/python3.13/site-packages/pyrogram/methods/advanced/resolve_peer.py", line 89, in resolve_peer
    peer_type = utils.get_peer_type(peer_id)
  File "/workspace/venv/lib/python3.13/site-packages/pyrogram/utils.py", line 246, in get_peer_type
    raise ValueError(f"Peer id invalid: {peer_id}")
ValueError: Peer id invalid: -1002704003307
[16-Aug-25 03:47:35 - ERROR] - asyncio - Task exception was never retrieved
future: <Task finished name='Task-808' coro=<Client.handle_updates() done, defined at /workspace/venv/lib/python3.13/site-packages/pyrogram/client.py:535> exception=ValueError('Peer id invalid: -1002704003307')>
Traceback (most recent call last):
  File "/workspace/venv/lib/python3.13/site-packages/pyrogram/methods/advanced/resolve_peer.py", line 62, in resolve_peer
    return await self.storage.get_peer_by_id(peer_id)
           ^^^^^^^^^^^^^^^^^^^^^^^^^^^^^^^^^^^^^^^^^^
  File "/workspace/venv/lib/python3.13/site-packages/pyrogram/storage/sqlite_storage.py", line 142, in get_peer_by_id
    raise KeyError(f"ID not found: {peer_id}")
KeyError: 'ID not found: -1002704003307'

During handling of the above exception, another exception occurred:

Traceback (most recent call last):
  File "/workspace/venv/lib/python3.13/site-packages/pyrogram/client.py", line 569, in handle_updates
    channel=await self.resolve_peer(utils.get_channel_id(channel_id)),
            ^^^^^^^^^^^^^^^^^^^^^^^^^^^^^^^^^^^^^^^^^^^^^^^^^^^^^^^^^
  File "/workspace/venv/lib/python3.13/site-packages/pyrogram/methods/advanced/resolve_peer.py", line 89, in resolve_peer
    peer_type = utils.get_peer_type(peer_id)
  File "/workspace/venv/lib/python3.13/site-packages/pyrogram/utils.py", line 246, in get_peer_type
    raise ValueError(f"Peer id invalid: {peer_id}")
ValueError: Peer id invalid: -1002704003307
[16-Aug-25 03:47:35 - ERROR] - asyncio - Task exception was never retrieved
future: <Task finished name='Task-812' coro=<Client.handle_updates() done, defined at /workspace/venv/lib/python3.13/site-packages/pyrogram/client.py:535> exception=ValueError('Peer id invalid: -1002704003307')>
Traceback (most recent call last):
  File "/workspace/venv/lib/python3.13/site-packages/pyrogram/methods/advanced/resolve_peer.py", line 62, in resolve_peer
    return await self.storage.get_peer_by_id(peer_id)
           ^^^^^^^^^^^^^^^^^^^^^^^^^^^^^^^^^^^^^^^^^^
  File "/workspace/venv/lib/python3.13/site-packages/pyrogram/storage/sqlite_storage.py", line 142, in get_peer_by_id
    raise KeyError(f"ID not found: {peer_id}")
KeyError: 'ID not found: -1002704003307'

During handling of the above exception, another exception occurred:

Traceback (most recent call last):
  File "/workspace/venv/lib/python3.13/site-packages/pyrogram/client.py", line 569, in handle_updates
    channel=await self.resolve_peer(utils.get_channel_id(channel_id)),
            ^^^^^^^^^^^^^^^^^^^^^^^^^^^^^^^^^^^^^^^^^^^^^^^^^^^^^^^^^
  File "/workspace/venv/lib/python3.13/site-packages/pyrogram/methods/advanced/resolve_peer.py", line 89, in resolve_peer
    peer_type = utils.get_peer_type(peer_id)
  File "/workspace/venv/lib/python3.13/site-packages/pyrogram/utils.py", line 246, in get_peer_type
    raise ValueError(f"Peer id invalid: {peer_id}")
ValueError: Peer id invalid: -1002704003307
[16-Aug-25 03:47:47 - ERROR] - asyncio - Task exception was never retrieved
future: <Task finished name='Task-824' coro=<Client.handle_updates() done, defined at /workspace/venv/lib/python3.13/site-packages/pyrogram/client.py:535> exception=ValueError('Peer id invalid: -1002430970946')>
Traceback (most recent call last):
  File "/workspace/venv/lib/python3.13/site-packages/pyrogram/methods/advanced/resolve_peer.py", line 62, in resolve_peer
    return await self.storage.get_peer_by_id(peer_id)
           ^^^^^^^^^^^^^^^^^^^^^^^^^^^^^^^^^^^^^^^^^^
  File "/workspace/venv/lib/python3.13/site-packages/pyrogram/storage/sqlite_storage.py", line 142, in get_peer_by_id
    raise KeyError(f"ID not found: {peer_id}")
KeyError: 'ID not found: -1002430970946'

During handling of the above exception, another exception occurred:

Traceback (most recent call last):
  File "/workspace/venv/lib/python3.13/site-packages/pyrogram/client.py", line 569, in handle_updates
    channel=await self.resolve_peer(utils.get_channel_id(channel_id)),
            ^^^^^^^^^^^^^^^^^^^^^^^^^^^^^^^^^^^^^^^^^^^^^^^^^^^^^^^^^
  File "/workspace/venv/lib/python3.13/site-packages/pyrogram/methods/advanced/resolve_peer.py", line 89, in resolve_peer
    peer_type = utils.get_peer_type(peer_id)
  File "/workspace/venv/lib/python3.13/site-packages/pyrogram/utils.py", line 246, in get_peer_type
    raise ValueError(f"Peer id invalid: {peer_id}")
ValueError: Peer id invalid: -1002430970946
[16-Aug-25 03:47:51 - ERROR] - pyrogram.dispatcher - Peer id invalid: -1002430970946
Traceback (most recent call last):
  File "/workspace/venv/lib/python3.13/site-packages/pyrogram/methods/advanced/resolve_peer.py", line 62, in resolve_peer
    return await self.storage.get_peer_by_id(peer_id)
           ^^^^^^^^^^^^^^^^^^^^^^^^^^^^^^^^^^^^^^^^^^
  File "/workspace/venv/lib/python3.13/site-packages/pyrogram/storage/sqlite_storage.py", line 142, in get_peer_by_id
    raise KeyError(f"ID not found: {peer_id}")
KeyError: 'ID not found: -1002430970946'

During handling of the above exception, another exception occurred:

Traceback (most recent call last):
  File "/workspace/venv/lib/python3.13/site-packages/pyrogram/dispatcher.py", line 214, in handler_worker
    await parser(update, users, chats)
  File "/workspace/venv/lib/python3.13/site-packages/pyrogram/dispatcher.py", line 75, in edited_message_parser
    parsed, _ = await message_parser(update, users, chats)
                ^^^^^^^^^^^^^^^^^^^^^^^^^^^^^^^^^^^^^^^^^^
  File "/workspace/venv/lib/python3.13/site-packages/pyrogram/dispatcher.py", line 68, in message_parser
    await pyrogram.types.Message._parse(self.client, update.message, users, chats,
    ^^^^^^^^^^^^^^^^^^^^^^^^^^^^^^^^^^^^^^^^^^^^^^^^^^^^^^^^^^^^^^^^^^^^^^^^^^^^^^
                                        isinstance(update, UpdateNewScheduledMessage)),
                                        ^^^^^^^^^^^^^^^^^^^^^^^^^^^^^^^^^^^^^^^^^^^^^^
  File "/workspace/venv/lib/python3.13/site-packages/pyrogram/types/messages_and_media/message.py", line 836, in _parse
    reply_to_message = await client.get_messages(
                       ^^^^^^^^^^^^^^^^^^^^^^^^^^
    ...<3 lines>...
    )
    ^
  File "/workspace/venv/lib/python3.13/site-packages/pyrogram/methods/messages/get_messages.py", line 101, in get_messages
    peer = await self.resolve_peer(chat_id)
           ^^^^^^^^^^^^^^^^^^^^^^^^^^^^^^^^
  File "/workspace/venv/lib/python3.13/site-packages/pyrogram/methods/advanced/resolve_peer.py", line 89, in resolve_peer
    peer_type = utils.get_peer_type(peer_id)
  File "/workspace/venv/lib/python3.13/site-packages/pyrogram/utils.py", line 246, in get_peer_type
    raise ValueError(f"Peer id invalid: {peer_id}")
ValueError: Peer id invalid: -1002430970946
[16-Aug-25 03:47:51 - ERROR] - asyncio - Task exception was never retrieved
future: <Task finished name='Task-833' coro=<Client.handle_updates() done, defined at /workspace/venv/lib/python3.13/site-packages/pyrogram/client.py:535> exception=ValueError('Peer id invalid: -1002524216878')>
Traceback (most recent call last):
  File "/workspace/venv/lib/python3.13/site-packages/pyrogram/methods/advanced/resolve_peer.py", line 62, in resolve_peer
    return await self.storage.get_peer_by_id(peer_id)
           ^^^^^^^^^^^^^^^^^^^^^^^^^^^^^^^^^^^^^^^^^^
  File "/workspace/venv/lib/python3.13/site-packages/pyrogram/storage/sqlite_storage.py", line 142, in get_peer_by_id
    raise KeyError(f"ID not found: {peer_id}")
KeyError: 'ID not found: -1002524216878'

During handling of the above exception, another exception occurred:

Traceback (most recent call last):
  File "/workspace/venv/lib/python3.13/site-packages/pyrogram/client.py", line 569, in handle_updates
    channel=await self.resolve_peer(utils.get_channel_id(channel_id)),
            ^^^^^^^^^^^^^^^^^^^^^^^^^^^^^^^^^^^^^^^^^^^^^^^^^^^^^^^^^
  File "/workspace/venv/lib/python3.13/site-packages/pyrogram/methods/advanced/resolve_peer.py", line 89, in resolve_peer
    peer_type = utils.get_peer_type(peer_id)
  File "/workspace/venv/lib/python3.13/site-packages/pyrogram/utils.py", line 246, in get_peer_type
    raise ValueError(f"Peer id invalid: {peer_id}")
ValueError: Peer id invalid: -1002524216878
[16-Aug-25 03:47:53 - ERROR] - asyncio - Task exception was never retrieved
future: <Task finished name='Task-837' coro=<Client.handle_updates() done, defined at /workspace/venv/lib/python3.13/site-packages/pyrogram/client.py:535> exception=ValueError('Peer id invalid: -1002704003307')>
Traceback (most recent call last):
  File "/workspace/venv/lib/python3.13/site-packages/pyrogram/methods/advanced/resolve_peer.py", line 62, in resolve_peer
    return await self.storage.get_peer_by_id(peer_id)
           ^^^^^^^^^^^^^^^^^^^^^^^^^^^^^^^^^^^^^^^^^^
  File "/workspace/venv/lib/python3.13/site-packages/pyrogram/storage/sqlite_storage.py", line 142, in get_peer_by_id
    raise KeyError(f"ID not found: {peer_id}")
KeyError: 'ID not found: -1002704003307'

During handling of the above exception, another exception occurred:

Traceback (most recent call last):
  File "/workspace/venv/lib/python3.13/site-packages/pyrogram/client.py", line 569, in handle_updates
    channel=await self.resolve_peer(utils.get_channel_id(channel_id)),
            ^^^^^^^^^^^^^^^^^^^^^^^^^^^^^^^^^^^^^^^^^^^^^^^^^^^^^^^^^
  File "/workspace/venv/lib/python3.13/site-packages/pyrogram/methods/advanced/resolve_peer.py", line 89, in resolve_peer
    peer_type = utils.get_peer_type(peer_id)
  File "/workspace/venv/lib/python3.13/site-packages/pyrogram/utils.py", line 246, in get_peer_type
    raise ValueError(f"Peer id invalid: {peer_id}")
ValueError: Peer id invalid: -1002704003307
[16-Aug-25 03:47:53 - ERROR] - asyncio - Task exception was never retrieved
future: <Task finished name='Task-839' coro=<Client.handle_updates() done, defined at /workspace/venv/lib/python3.13/site-packages/pyrogram/client.py:535> exception=ValueError('Peer id invalid: -1002704003307')>
Traceback (most recent call last):
  File "/workspace/venv/lib/python3.13/site-packages/pyrogram/methods/advanced/resolve_peer.py", line 62, in resolve_peer
    return await self.storage.get_peer_by_id(peer_id)
           ^^^^^^^^^^^^^^^^^^^^^^^^^^^^^^^^^^^^^^^^^^
  File "/workspace/venv/lib/python3.13/site-packages/pyrogram/storage/sqlite_storage.py", line 142, in get_peer_by_id
    raise KeyError(f"ID not found: {peer_id}")
KeyError: 'ID not found: -1002704003307'

During handling of the above exception, another exception occurred:

Traceback (most recent call last):
  File "/workspace/venv/lib/python3.13/site-packages/pyrogram/client.py", line 569, in handle_updates
    channel=await self.resolve_peer(utils.get_channel_id(channel_id)),
            ^^^^^^^^^^^^^^^^^^^^^^^^^^^^^^^^^^^^^^^^^^^^^^^^^^^^^^^^^
  File "/workspace/venv/lib/python3.13/site-packages/pyrogram/methods/advanced/resolve_peer.py", line 89, in resolve_peer
    peer_type = utils.get_peer_type(peer_id)
  File "/workspace/venv/lib/python3.13/site-packages/pyrogram/utils.py", line 246, in get_peer_type
    raise ValueError(f"Peer id invalid: {peer_id}")
ValueError: Peer id invalid: -1002704003307
[16-Aug-25 03:48:00 - ERROR] - asyncio - Task exception was never retrieved
future: <Task finished name='Task-848' coro=<Client.handle_updates() done, defined at /workspace/venv/lib/python3.13/site-packages/pyrogram/client.py:535> exception=ValueError('Peer id invalid: -1002704003307')>
Traceback (most recent call last):
  File "/workspace/venv/lib/python3.13/site-packages/pyrogram/methods/advanced/resolve_peer.py", line 62, in resolve_peer
    return await self.storage.get_peer_by_id(peer_id)
           ^^^^^^^^^^^^^^^^^^^^^^^^^^^^^^^^^^^^^^^^^^
  File "/workspace/venv/lib/python3.13/site-packages/pyrogram/storage/sqlite_storage.py", line 142, in get_peer_by_id
    raise KeyError(f"ID not found: {peer_id}")
KeyError: 'ID not found: -1002704003307'

During handling of the above exception, another exception occurred:

Traceback (most recent call last):
  File "/workspace/venv/lib/python3.13/site-packages/pyrogram/client.py", line 569, in handle_updates
    channel=await self.resolve_peer(utils.get_channel_id(channel_id)),
            ^^^^^^^^^^^^^^^^^^^^^^^^^^^^^^^^^^^^^^^^^^^^^^^^^^^^^^^^^
  File "/workspace/venv/lib/python3.13/site-packages/pyrogram/methods/advanced/resolve_peer.py", line 89, in resolve_peer
    peer_type = utils.get_peer_type(peer_id)
  File "/workspace/venv/lib/python3.13/site-packages/pyrogram/utils.py", line 246, in get_peer_type
    raise ValueError(f"Peer id invalid: {peer_id}")
ValueError: Peer id invalid: -1002704003307
[16-Aug-25 03:48:04 - ERROR] - asyncio - Task exception was never retrieved
future: <Task finished name='Task-855' coro=<Client.handle_updates() done, defined at /workspace/venv/lib/python3.13/site-packages/pyrogram/client.py:535> exception=ValueError('Peer id invalid: -1002725376687')>
Traceback (most recent call last):
  File "/workspace/venv/lib/python3.13/site-packages/pyrogram/methods/advanced/resolve_peer.py", line 62, in resolve_peer
    return await self.storage.get_peer_by_id(peer_id)
           ^^^^^^^^^^^^^^^^^^^^^^^^^^^^^^^^^^^^^^^^^^
  File "/workspace/venv/lib/python3.13/site-packages/pyrogram/storage/sqlite_storage.py", line 142, in get_peer_by_id
    raise KeyError(f"ID not found: {peer_id}")
KeyError: 'ID not found: -1002725376687'

During handling of the above exception, another exception occurred:

Traceback (most recent call last):
  File "/workspace/venv/lib/python3.13/site-packages/pyrogram/client.py", line 569, in handle_updates
    channel=await self.resolve_peer(utils.get_channel_id(channel_id)),
            ^^^^^^^^^^^^^^^^^^^^^^^^^^^^^^^^^^^^^^^^^^^^^^^^^^^^^^^^^
  File "/workspace/venv/lib/python3.13/site-packages/pyrogram/methods/advanced/resolve_peer.py", line 89, in resolve_peer
    peer_type = utils.get_peer_type(peer_id)
  File "/workspace/venv/lib/python3.13/site-packages/pyrogram/utils.py", line 246, in get_peer_type
    raise ValueError(f"Peer id invalid: {peer_id}")
ValueError: Peer id invalid: -1002725376687
[16-Aug-25 03:48:06 - ERROR] - asyncio - Task exception was never retrieved
future: <Task finished name='Task-860' coro=<Client.handle_updates() done, defined at /workspace/venv/lib/python3.13/site-packages/pyrogram/client.py:535> exception=ValueError('Peer id invalid: -1002725376687')>
Traceback (most recent call last):
  File "/workspace/venv/lib/python3.13/site-packages/pyrogram/methods/advanced/resolve_peer.py", line 62, in resolve_peer
    return await self.storage.get_peer_by_id(peer_id)
           ^^^^^^^^^^^^^^^^^^^^^^^^^^^^^^^^^^^^^^^^^^
  File "/workspace/venv/lib/python3.13/site-packages/pyrogram/storage/sqlite_storage.py", line 142, in get_peer_by_id
    raise KeyError(f"ID not found: {peer_id}")
KeyError: 'ID not found: -1002725376687'

During handling of the above exception, another exception occurred:

Traceback (most recent call last):
  File "/workspace/venv/lib/python3.13/site-packages/pyrogram/client.py", line 569, in handle_updates
    channel=await self.resolve_peer(utils.get_channel_id(channel_id)),
            ^^^^^^^^^^^^^^^^^^^^^^^^^^^^^^^^^^^^^^^^^^^^^^^^^^^^^^^^^
  File "/workspace/venv/lib/python3.13/site-packages/pyrogram/methods/advanced/resolve_peer.py", line 89, in resolve_peer
    peer_type = utils.get_peer_type(peer_id)
  File "/workspace/venv/lib/python3.13/site-packages/pyrogram/utils.py", line 246, in get_peer_type
    raise ValueError(f"Peer id invalid: {peer_id}")
ValueError: Peer id invalid: -1002725376687
[16-Aug-25 03:48:09 - ERROR] - asyncio - Task exception was never retrieved
future: <Task finished name='Task-864' coro=<Client.handle_updates() done, defined at /workspace/venv/lib/python3.13/site-packages/pyrogram/client.py:535> exception=ValueError('Peer id invalid: -1002704003307')>
Traceback (most recent call last):
  File "/workspace/venv/lib/python3.13/site-packages/pyrogram/methods/advanced/resolve_peer.py", line 62, in resolve_peer
    return await self.storage.get_peer_by_id(peer_id)
           ^^^^^^^^^^^^^^^^^^^^^^^^^^^^^^^^^^^^^^^^^^
  File "/workspace/venv/lib/python3.13/site-packages/pyrogram/storage/sqlite_storage.py", line 142, in get_peer_by_id
    raise KeyError(f"ID not found: {peer_id}")
KeyError: 'ID not found: -1002704003307'

During handling of the above exception, another exception occurred:

Traceback (most recent call last):
  File "/workspace/venv/lib/python3.13/site-packages/pyrogram/client.py", line 569, in handle_updates
    channel=await self.resolve_peer(utils.get_channel_id(channel_id)),
            ^^^^^^^^^^^^^^^^^^^^^^^^^^^^^^^^^^^^^^^^^^^^^^^^^^^^^^^^^
  File "/workspace/venv/lib/python3.13/site-packages/pyrogram/methods/advanced/resolve_peer.py", line 89, in resolve_peer
    peer_type = utils.get_peer_type(peer_id)
  File "/workspace/venv/lib/python3.13/site-packages/pyrogram/utils.py", line 246, in get_peer_type
    raise ValueError(f"Peer id invalid: {peer_id}")
ValueError: Peer id invalid: -1002704003307
