nohup: ignoring input
[16-Aug-25 03:10:24 - INFO] - ZeMusic.core.mongo - يتم رفع البيانات...
[16-Aug-25 03:10:24 - INFO] - ZeMusic.core.mongo - تم رفع البيانات.
[16-Aug-25 03:10:24 - INFO] - ZeMusic.core.dir - تم اكتمال التحميل.
[16-Aug-25 03:10:24 - INFO] - ZeMusic.core.git - Git Client Found [VPS DEPLOYER]
[16-Aug-25 03:10:24 - INFO] - ZeMusic.misc - Local Database Initialized.
[16-Aug-25 03:10:24 - INFO] - ZeMusic.core.bot - يتم تشغيل البوت..
[16-Aug-25 03:10:25 - INFO] - __main__ - 🚀 بدء إعداد PostgreSQL تلقائياً...
[16-Aug-25 03:10:25 - INFO] - __main__ - 🔍 التحقق من تثبيت PostgreSQL...
[16-Aug-25 03:10:25 - INFO] - __main__ - ⚡ بدء تشغيل PostgreSQL...
[16-Aug-25 03:10:25 - INFO] - __main__ - ✅ تم بدء تشغيل PostgreSQL
[16-Aug-25 03:10:25 - INFO] - __main__ - 🔐 إعداد كلمة مرور للمستخدم postgres...
[16-Aug-25 03:10:25 - INFO] - __main__ - ℹ️ كلمة مرور PostgreSQL موجودة بالفعل
[16-Aug-25 03:10:25 - INFO] - __main__ - 🗄️ التحقق من وجود قاعدة البيانات...
[16-Aug-25 03:10:25 - INFO] - __main__ - ℹ️ قاعدة البيانات zemusic_bot موجودة بالفعل
[16-Aug-25 03:10:25 - INFO] - __main__ - ⚙️ إعداد قاعدة بيانات PostgreSQL...
[16-Aug-25 03:10:25 - INFO] - ZeMusic.database.setup - بدء إعداد قاعدة البيانات...
[16-Aug-25 03:10:25 - INFO] - ZeMusic.database.setup - قاعدة البيانات موجودة بالفعل
[16-Aug-25 03:10:25 - INFO] - ZeMusic.core.postgres - يتم الاتصال بقاعدة بيانات PostgreSQL...
[16-Aug-25 03:10:25 - INFO] - ZeMusic.core.postgres - تم الاتصال بنجاح - PostgreSQL: PostgreSQL 17.5 (Ubuntu 17.5-0ubuntu0.25.04.1) on x86_64-pc-linux-gnu, compiled by gcc (Ubuntu 14.2.0-19ubuntu2) 14.2.0, 64-bit
[16-Aug-25 03:10:25 - INFO] - ZeMusic.database.setup - CREATE TABLE
CREATE TABLE
CREATE TABLE
CREATE TABLE
CREATE TABLE
CREATE TABLE
CREATE TABLE
CREATE TABLE
CREATE TABLE
CREATE TABLE
CREATE TABLE
CREATE TABLE
CREATE TABLE
CREATE TABLE
CREATE INDEX
CREATE INDEX
CREATE INDEX
CREATE INDEX
CREATE INDEX
CREATE INDEX
CREATE INDEX
CREATE INDEX
CREATE INDEX
CREATE INDEX
CREATE INDEX
CREATE INDEX
CREATE INDEX
CREATE INDEX
CREATE INDEX
CREATE INDEX
CREATE INDEX
CREATE INDEX
CREATE INDEX
CREATE INDEX
CREATE INDEX
CREATE INDEX
CREATE INDEX
CREATE INDEX
CREATE INDEX
INSERT 0 0
INSERT 0 0
CREATE FUNCTION
CREATE FUNCTION
CREATE FUNCTION
[16-Aug-25 03:10:25 - INFO] - ZeMusic.database.setup - تم تنفيذ ملف SQL بنجاح: /workspace/database_schema.sql
[16-Aug-25 03:10:25 - INFO] - ZeMusic.database.setup - تم إنشاء جدول audio_cache بنجاح
[16-Aug-25 03:10:25 - INFO] - ZeMusic.database.setup - تم إنشاء جدول search_history بنجاح
[16-Aug-25 03:10:25 - INFO] - ZeMusic.database.setup - تم إنشاء جدول download_stats بنجاح
[16-Aug-25 03:10:25 - INFO] - ZeMusic.database.setup - تم إنشاء جدول cache_metrics بنجاح
[16-Aug-25 03:10:25 - INFO] - ZeMusic.database.setup - تم إنشاء جدول popular_content بنجاح
[16-Aug-25 03:10:25 - INFO] - ZeMusic.database.setup - تم إنشاء جميع جداول التحميل بنجاح
[16-Aug-25 03:10:25 - INFO] - ZeMusic.database.setup - تم إدراج البيانات الأولية بنجاح
[16-Aug-25 03:10:25 - INFO] - ZeMusic.database.setup - تم التحقق من سلامة قاعدة البيانات بنجاح
[16-Aug-25 03:10:25 - INFO] - ZeMusic.database.setup - تم إعداد قاعدة البيانات بنجاح! ✅
[16-Aug-25 03:10:25 - INFO] - ZeMusic.database.migrations - لا توجد تحديثات معلقة
[16-Aug-25 03:10:25 - INFO] - __main__ - ✅ تم إعداد PostgreSQL بنجاح
[16-Aug-25 03:10:25 - INFO] - ZeMusic.misc - تم رفع البيانات.
[16-Aug-25 03:10:28 - INFO] - ZeMusic.core.bot - تم تسغيل 𝐋𝐎𝐋  بنجاح..
[16-Aug-25 03:10:28 - INFO] - ZeMusic.plugins - تنزيل معلومات السورس...
[16-Aug-25 03:10:28 - INFO] - ZeMusic.core.userbot - جلب معلومات السورس...
[16-Aug-25 03:10:29 - INFO] - ZeMusic.core.userbot - تم تشغيل المساعد <a href=tg://user?id=5929114274>الحساب المساعد ♫</a> على سورس الملك
[16-Aug-25 03:10:29 - INFO] - ZeMusic.core.call - Starting PyTgCalls Client...

[16-Aug-25 03:10:33 - ERROR] - asyncio - Task exception was never retrieved
future: <Task finished name='Task-275' coro=<Client.handle_updates() done, defined at /workspace/venv/lib/python3.13/site-packages/pyrogram/client.py:535> exception=ValueError('Peer id invalid: -1002725376687')>
Traceback (most recent call last):
  File "/workspace/venv/lib/python3.13/site-packages/pyrogram/methods/advanced/resolve_peer.py", line 62, in resolve_peer
    return await self.storage.get_peer_by_id(peer_id)
           ^^^^^^^^^^^^^^^^^^^^^^^^^^^^^^^^^^^^^^^^^^
  File "/workspace/venv/lib/python3.13/site-packages/pyrogram/storage/sqlite_storage.py", line 142, in get_peer_by_id
    raise KeyError(f"ID not found: {peer_id}")
KeyError: 'ID not found: -1002725376687'

During handling of the above exception, another exception occurred:

Traceback (most recent call last):
  File "/workspace/venv/lib/python3.13/site-packages/pyrogram/client.py", line 569, in handle_updates
    channel=await self.resolve_peer(utils.get_channel_id(channel_id)),
            ^^^^^^^^^^^^^^^^^^^^^^^^^^^^^^^^^^^^^^^^^^^^^^^^^^^^^^^^^
  File "/workspace/venv/lib/python3.13/site-packages/pyrogram/methods/advanced/resolve_peer.py", line 89, in resolve_peer
    peer_type = utils.get_peer_type(peer_id)
  File "/workspace/venv/lib/python3.13/site-packages/pyrogram/utils.py", line 246, in get_peer_type
    raise ValueError(f"Peer id invalid: {peer_id}")
ValueError: Peer id invalid: -1002725376687
[16-Aug-25 03:10:34 - ERROR] - asyncio - Task exception was never retrieved
future: <Task finished name='Task-278' coro=<Client.handle_updates() done, defined at /workspace/venv/lib/python3.13/site-packages/pyrogram/client.py:535> exception=ValueError('Peer id invalid: -1002725376687')>
Traceback (most recent call last):
  File "/workspace/venv/lib/python3.13/site-packages/pyrogram/methods/advanced/resolve_peer.py", line 62, in resolve_peer
    return await self.storage.get_peer_by_id(peer_id)
           ^^^^^^^^^^^^^^^^^^^^^^^^^^^^^^^^^^^^^^^^^^
  File "/workspace/venv/lib/python3.13/site-packages/pyrogram/storage/sqlite_storage.py", line 142, in get_peer_by_id
    raise KeyError(f"ID not found: {peer_id}")
KeyError: 'ID not found: -1002725376687'

During handling of the above exception, another exception occurred:

Traceback (most recent call last):
  File "/workspace/venv/lib/python3.13/site-packages/pyrogram/client.py", line 569, in handle_updates
    channel=await self.resolve_peer(utils.get_channel_id(channel_id)),
            ^^^^^^^^^^^^^^^^^^^^^^^^^^^^^^^^^^^^^^^^^^^^^^^^^^^^^^^^^
  File "/workspace/venv/lib/python3.13/site-packages/pyrogram/methods/advanced/resolve_peer.py", line 89, in resolve_peer
    peer_type = utils.get_peer_type(peer_id)
  File "/workspace/venv/lib/python3.13/site-packages/pyrogram/utils.py", line 246, in get_peer_type
    raise ValueError(f"Peer id invalid: {peer_id}")
ValueError: Peer id invalid: -1002725376687
[16-Aug-25 03:10:39 - ERROR] - asyncio - Task exception was never retrieved
future: <Task finished name='Task-287' coro=<Client.handle_updates() done, defined at /workspace/venv/lib/python3.13/site-packages/pyrogram/client.py:535> exception=ValueError('Peer id invalid: -1002474305961')>
Traceback (most recent call last):
  File "/workspace/venv/lib/python3.13/site-packages/pyrogram/methods/advanced/resolve_peer.py", line 62, in resolve_peer
    return await self.storage.get_peer_by_id(peer_id)
           ^^^^^^^^^^^^^^^^^^^^^^^^^^^^^^^^^^^^^^^^^^
  File "/workspace/venv/lib/python3.13/site-packages/pyrogram/storage/sqlite_storage.py", line 142, in get_peer_by_id
    raise KeyError(f"ID not found: {peer_id}")
KeyError: 'ID not found: -1002474305961'

During handling of the above exception, another exception occurred:

Traceback (most recent call last):
  File "/workspace/venv/lib/python3.13/site-packages/pyrogram/client.py", line 569, in handle_updates
    channel=await self.resolve_peer(utils.get_channel_id(channel_id)),
            ^^^^^^^^^^^^^^^^^^^^^^^^^^^^^^^^^^^^^^^^^^^^^^^^^^^^^^^^^
  File "/workspace/venv/lib/python3.13/site-packages/pyrogram/methods/advanced/resolve_peer.py", line 89, in resolve_peer
    peer_type = utils.get_peer_type(peer_id)
  File "/workspace/venv/lib/python3.13/site-packages/pyrogram/utils.py", line 246, in get_peer_type
    raise ValueError(f"Peer id invalid: {peer_id}")
ValueError: Peer id invalid: -1002474305961
[16-Aug-25 03:10:42 - ERROR] - asyncio - Task exception was never retrieved
future: <Task finished name='Task-294' coro=<Client.handle_updates() done, defined at /workspace/venv/lib/python3.13/site-packages/pyrogram/client.py:535> exception=ValueError('Peer id invalid: -1002430970946')>
Traceback (most recent call last):
  File "/workspace/venv/lib/python3.13/site-packages/pyrogram/methods/advanced/resolve_peer.py", line 62, in resolve_peer
    return await self.storage.get_peer_by_id(peer_id)
           ^^^^^^^^^^^^^^^^^^^^^^^^^^^^^^^^^^^^^^^^^^
  File "/workspace/venv/lib/python3.13/site-packages/pyrogram/storage/sqlite_storage.py", line 142, in get_peer_by_id
    raise KeyError(f"ID not found: {peer_id}")
KeyError: 'ID not found: -1002430970946'

During handling of the above exception, another exception occurred:

Traceback (most recent call last):
  File "/workspace/venv/lib/python3.13/site-packages/pyrogram/client.py", line 569, in handle_updates
    channel=await self.resolve_peer(utils.get_channel_id(channel_id)),
            ^^^^^^^^^^^^^^^^^^^^^^^^^^^^^^^^^^^^^^^^^^^^^^^^^^^^^^^^^
  File "/workspace/venv/lib/python3.13/site-packages/pyrogram/methods/advanced/resolve_peer.py", line 89, in resolve_peer
    peer_type = utils.get_peer_type(peer_id)
  File "/workspace/venv/lib/python3.13/site-packages/pyrogram/utils.py", line 246, in get_peer_type
    raise ValueError(f"Peer id invalid: {peer_id}")
ValueError: Peer id invalid: -1002430970946
[16-Aug-25 03:10:45 - ERROR] - asyncio - Task exception was never retrieved
future: <Task finished name='Task-302' coro=<Client.handle_updates() done, defined at /workspace/venv/lib/python3.13/site-packages/pyrogram/client.py:535> exception=ValueError('Peer id invalid: -1002430970946')>
Traceback (most recent call last):
  File "/workspace/venv/lib/python3.13/site-packages/pyrogram/methods/advanced/resolve_peer.py", line 62, in resolve_peer
    return await self.storage.get_peer_by_id(peer_id)
           ^^^^^^^^^^^^^^^^^^^^^^^^^^^^^^^^^^^^^^^^^^
  File "/workspace/venv/lib/python3.13/site-packages/pyrogram/storage/sqlite_storage.py", line 142, in get_peer_by_id
    raise KeyError(f"ID not found: {peer_id}")
KeyError: 'ID not found: -1002430970946'

During handling of the above exception, another exception occurred:

Traceback (most recent call last):
  File "/workspace/venv/lib/python3.13/site-packages/pyrogram/client.py", line 569, in handle_updates
    channel=await self.resolve_peer(utils.get_channel_id(channel_id)),
            ^^^^^^^^^^^^^^^^^^^^^^^^^^^^^^^^^^^^^^^^^^^^^^^^^^^^^^^^^
  File "/workspace/venv/lib/python3.13/site-packages/pyrogram/methods/advanced/resolve_peer.py", line 89, in resolve_peer
    peer_type = utils.get_peer_type(peer_id)
  File "/workspace/venv/lib/python3.13/site-packages/pyrogram/utils.py", line 246, in get_peer_type
    raise ValueError(f"Peer id invalid: {peer_id}")
ValueError: Peer id invalid: -1002430970946
