nohup: ignoring input
[16-Aug-25 03:10:24 - INFO] - ZeMusic.core.mongo - يتم رفع البيانات...
[16-Aug-25 03:10:24 - INFO] - ZeMusic.core.mongo - تم رفع البيانات.
[16-Aug-25 03:10:24 - INFO] - ZeMusic.core.dir - تم اكتمال التحميل.
[16-Aug-25 03:10:24 - INFO] - ZeMusic.core.git - Git Client Found [VPS DEPLOYER]
[16-Aug-25 03:10:24 - INFO] - ZeMusic.misc - Local Database Initialized.
[16-Aug-25 03:10:24 - INFO] - ZeMusic.core.bot - يتم تشغيل البوت..
[16-Aug-25 03:10:25 - INFO] - __main__ - 🚀 بدء إعداد PostgreSQL تلقائياً...
[16-Aug-25 03:10:25 - INFO] - __main__ - 🔍 التحقق من تثبيت PostgreSQL...
[16-Aug-25 03:10:25 - INFO] - __main__ - ⚡ بدء تشغيل PostgreSQL...
[16-Aug-25 03:10:25 - INFO] - __main__ - ✅ تم بدء تشغيل PostgreSQL
[16-Aug-25 03:10:25 - INFO] - __main__ - 🔐 إعداد كلمة مرور للمستخدم postgres...
[16-Aug-25 03:10:25 - INFO] - __main__ - ℹ️ كلمة مرور PostgreSQL موجودة بالفعل
[16-Aug-25 03:10:25 - INFO] - __main__ - 🗄️ التحقق من وجود قاعدة البيانات...
[16-Aug-25 03:10:25 - INFO] - __main__ - ℹ️ قاعدة البيانات zemusic_bot موجودة بالفعل
[16-Aug-25 03:10:25 - INFO] - __main__ - ⚙️ إعداد قاعدة بيانات PostgreSQL...
[16-Aug-25 03:10:25 - INFO] - ZeMusic.database.setup - بدء إعداد قاعدة البيانات...
[16-Aug-25 03:10:25 - INFO] - ZeMusic.database.setup - قاعدة البيانات موجودة بالفعل
[16-Aug-25 03:10:25 - INFO] - ZeMusic.core.postgres - يتم الاتصال بقاعدة بيانات PostgreSQL...
[16-Aug-25 03:10:25 - INFO] - ZeMusic.core.postgres - تم الاتصال بنجاح - PostgreSQL: PostgreSQL 17.5 (Ubuntu 17.5-0ubuntu0.25.04.1) on x86_64-pc-linux-gnu, compiled by gcc (Ubuntu 14.2.0-19ubuntu2) 14.2.0, 64-bit
[16-Aug-25 03:10:25 - INFO] - ZeMusic.database.setup - CREATE TABLE
CREATE TABLE
CREATE TABLE
CREATE TABLE
CREATE TABLE
CREATE TABLE
CREATE TABLE
CREATE TABLE
CREATE TABLE
CREATE TABLE
CREATE TABLE
CREATE TABLE
CREATE TABLE
CREATE TABLE
CREATE INDEX
CREATE INDEX
CREATE INDEX
CREATE INDEX
CREATE INDEX
CREATE INDEX
CREATE INDEX
CREATE INDEX
CREATE INDEX
CREATE INDEX
CREATE INDEX
CREATE INDEX
CREATE INDEX
CREATE INDEX
CREATE INDEX
CREATE INDEX
CREATE INDEX
CREATE INDEX
CREATE INDEX
CREATE INDEX
CREATE INDEX
CREATE INDEX
CREATE INDEX
CREATE INDEX
CREATE INDEX
INSERT 0 0
INSERT 0 0
CREATE FUNCTION
CREATE FUNCTION
CREATE FUNCTION
[16-Aug-25 03:10:25 - INFO] - ZeMusic.database.setup - تم تنفيذ ملف SQL بنجاح: /workspace/database_schema.sql
[16-Aug-25 03:10:25 - INFO] - ZeMusic.database.setup - تم إنشاء جدول audio_cache بنجاح
[16-Aug-25 03:10:25 - INFO] - ZeMusic.database.setup - تم إنشاء جدول search_history بنجاح
[16-Aug-25 03:10:25 - INFO] - ZeMusic.database.setup - تم إنشاء جدول download_stats بنجاح
[16-Aug-25 03:10:25 - INFO] - ZeMusic.database.setup - تم إنشاء جدول cache_metrics بنجاح
[16-Aug-25 03:10:25 - INFO] - ZeMusic.database.setup - تم إنشاء جدول popular_content بنجاح
[16-Aug-25 03:10:25 - INFO] - ZeMusic.database.setup - تم إنشاء جميع جداول التحميل بنجاح
[16-Aug-25 03:10:25 - INFO] - ZeMusic.database.setup - تم إدراج البيانات الأولية بنجاح
[16-Aug-25 03:10:25 - INFO] - ZeMusic.database.setup - تم التحقق من سلامة قاعدة البيانات بنجاح
[16-Aug-25 03:10:25 - INFO] - ZeMusic.database.setup - تم إعداد قاعدة البيانات بنجاح! ✅
[16-Aug-25 03:10:25 - INFO] - ZeMusic.database.migrations - لا توجد تحديثات معلقة
[16-Aug-25 03:10:25 - INFO] - __main__ - ✅ تم إعداد PostgreSQL بنجاح
[16-Aug-25 03:10:25 - INFO] - ZeMusic.misc - تم رفع البيانات.
[16-Aug-25 03:10:28 - INFO] - ZeMusic.core.bot - تم تسغيل 𝐋𝐎𝐋  بنجاح..
[16-Aug-25 03:10:28 - INFO] - ZeMusic.plugins - تنزيل معلومات السورس...
[16-Aug-25 03:10:28 - INFO] - ZeMusic.core.userbot - جلب معلومات السورس...
[16-Aug-25 03:10:29 - INFO] - ZeMusic.core.userbot - تم تشغيل المساعد <a href=tg://user?id=5929114274>الحساب المساعد ♫</a> على سورس الملك
[16-Aug-25 03:10:29 - INFO] - ZeMusic.core.call - Starting PyTgCalls Client...

[16-Aug-25 03:10:33 - ERROR] - asyncio - Task exception was never retrieved
future: <Task finished name='Task-275' coro=<Client.handle_updates() done, defined at /workspace/venv/lib/python3.13/site-packages/pyrogram/client.py:535> exception=ValueError('Peer id invalid: -1002725376687')>
Traceback (most recent call last):
  File "/workspace/venv/lib/python3.13/site-packages/pyrogram/methods/advanced/resolve_peer.py", line 62, in resolve_peer
    return await self.storage.get_peer_by_id(peer_id)
           ^^^^^^^^^^^^^^^^^^^^^^^^^^^^^^^^^^^^^^^^^^
  File "/workspace/venv/lib/python3.13/site-packages/pyrogram/storage/sqlite_storage.py", line 142, in get_peer_by_id
    raise KeyError(f"ID not found: {peer_id}")
KeyError: 'ID not found: -1002725376687'

During handling of the above exception, another exception occurred:

Traceback (most recent call last):
  File "/workspace/venv/lib/python3.13/site-packages/pyrogram/client.py", line 569, in handle_updates
    channel=await self.resolve_peer(utils.get_channel_id(channel_id)),
            ^^^^^^^^^^^^^^^^^^^^^^^^^^^^^^^^^^^^^^^^^^^^^^^^^^^^^^^^^
  File "/workspace/venv/lib/python3.13/site-packages/pyrogram/methods/advanced/resolve_peer.py", line 89, in resolve_peer
    peer_type = utils.get_peer_type(peer_id)
  File "/workspace/venv/lib/python3.13/site-packages/pyrogram/utils.py", line 246, in get_peer_type
    raise ValueError(f"Peer id invalid: {peer_id}")
ValueError: Peer id invalid: -1002725376687
[16-Aug-25 03:10:34 - ERROR] - asyncio - Task exception was never retrieved
future: <Task finished name='Task-278' coro=<Client.handle_updates() done, defined at /workspace/venv/lib/python3.13/site-packages/pyrogram/client.py:535> exception=ValueError('Peer id invalid: -1002725376687')>
Traceback (most recent call last):
  File "/workspace/venv/lib/python3.13/site-packages/pyrogram/methods/advanced/resolve_peer.py", line 62, in resolve_peer
    return await self.storage.get_peer_by_id(peer_id)
           ^^^^^^^^^^^^^^^^^^^^^^^^^^^^^^^^^^^^^^^^^^
  File "/workspace/venv/lib/python3.13/site-packages/pyrogram/storage/sqlite_storage.py", line 142, in get_peer_by_id
    raise KeyError(f"ID not found: {peer_id}")
KeyError: 'ID not found: -1002725376687'

During handling of the above exception, another exception occurred:

Traceback (most recent call last):
  File "/workspace/venv/lib/python3.13/site-packages/pyrogram/client.py", line 569, in handle_updates
    channel=await self.resolve_peer(utils.get_channel_id(channel_id)),
            ^^^^^^^^^^^^^^^^^^^^^^^^^^^^^^^^^^^^^^^^^^^^^^^^^^^^^^^^^
  File "/workspace/venv/lib/python3.13/site-packages/pyrogram/methods/advanced/resolve_peer.py", line 89, in resolve_peer
    peer_type = utils.get_peer_type(peer_id)
  File "/workspace/venv/lib/python3.13/site-packages/pyrogram/utils.py", line 246, in get_peer_type
    raise ValueError(f"Peer id invalid: {peer_id}")
ValueError: Peer id invalid: -1002725376687
[16-Aug-25 03:10:39 - ERROR] - asyncio - Task exception was never retrieved
future: <Task finished name='Task-287' coro=<Client.handle_updates() done, defined at /workspace/venv/lib/python3.13/site-packages/pyrogram/client.py:535> exception=ValueError('Peer id invalid: -1002474305961')>
Traceback (most recent call last):
  File "/workspace/venv/lib/python3.13/site-packages/pyrogram/methods/advanced/resolve_peer.py", line 62, in resolve_peer
    return await self.storage.get_peer_by_id(peer_id)
           ^^^^^^^^^^^^^^^^^^^^^^^^^^^^^^^^^^^^^^^^^^
  File "/workspace/venv/lib/python3.13/site-packages/pyrogram/storage/sqlite_storage.py", line 142, in get_peer_by_id
    raise KeyError(f"ID not found: {peer_id}")
KeyError: 'ID not found: -1002474305961'

During handling of the above exception, another exception occurred:

Traceback (most recent call last):
  File "/workspace/venv/lib/python3.13/site-packages/pyrogram/client.py", line 569, in handle_updates
    channel=await self.resolve_peer(utils.get_channel_id(channel_id)),
            ^^^^^^^^^^^^^^^^^^^^^^^^^^^^^^^^^^^^^^^^^^^^^^^^^^^^^^^^^
  File "/workspace/venv/lib/python3.13/site-packages/pyrogram/methods/advanced/resolve_peer.py", line 89, in resolve_peer
    peer_type = utils.get_peer_type(peer_id)
  File "/workspace/venv/lib/python3.13/site-packages/pyrogram/utils.py", line 246, in get_peer_type
    raise ValueError(f"Peer id invalid: {peer_id}")
ValueError: Peer id invalid: -1002474305961
[16-Aug-25 03:10:42 - ERROR] - asyncio - Task exception was never retrieved
future: <Task finished name='Task-294' coro=<Client.handle_updates() done, defined at /workspace/venv/lib/python3.13/site-packages/pyrogram/client.py:535> exception=ValueError('Peer id invalid: -1002430970946')>
Traceback (most recent call last):
  File "/workspace/venv/lib/python3.13/site-packages/pyrogram/methods/advanced/resolve_peer.py", line 62, in resolve_peer
    return await self.storage.get_peer_by_id(peer_id)
           ^^^^^^^^^^^^^^^^^^^^^^^^^^^^^^^^^^^^^^^^^^
  File "/workspace/venv/lib/python3.13/site-packages/pyrogram/storage/sqlite_storage.py", line 142, in get_peer_by_id
    raise KeyError(f"ID not found: {peer_id}")
KeyError: 'ID not found: -1002430970946'

During handling of the above exception, another exception occurred:

Traceback (most recent call last):
  File "/workspace/venv/lib/python3.13/site-packages/pyrogram/client.py", line 569, in handle_updates
    channel=await self.resolve_peer(utils.get_channel_id(channel_id)),
            ^^^^^^^^^^^^^^^^^^^^^^^^^^^^^^^^^^^^^^^^^^^^^^^^^^^^^^^^^
  File "/workspace/venv/lib/python3.13/site-packages/pyrogram/methods/advanced/resolve_peer.py", line 89, in resolve_peer
    peer_type = utils.get_peer_type(peer_id)
  File "/workspace/venv/lib/python3.13/site-packages/pyrogram/utils.py", line 246, in get_peer_type
    raise ValueError(f"Peer id invalid: {peer_id}")
ValueError: Peer id invalid: -1002430970946
[16-Aug-25 03:10:45 - ERROR] - asyncio - Task exception was never retrieved
future: <Task finished name='Task-302' coro=<Client.handle_updates() done, defined at /workspace/venv/lib/python3.13/site-packages/pyrogram/client.py:535> exception=ValueError('Peer id invalid: -1002430970946')>
Traceback (most recent call last):
  File "/workspace/venv/lib/python3.13/site-packages/pyrogram/methods/advanced/resolve_peer.py", line 62, in resolve_peer
    return await self.storage.get_peer_by_id(peer_id)
           ^^^^^^^^^^^^^^^^^^^^^^^^^^^^^^^^^^^^^^^^^^
  File "/workspace/venv/lib/python3.13/site-packages/pyrogram/storage/sqlite_storage.py", line 142, in get_peer_by_id
    raise KeyError(f"ID not found: {peer_id}")
KeyError: 'ID not found: -1002430970946'

During handling of the above exception, another exception occurred:

Traceback (most recent call last):
  File "/workspace/venv/lib/python3.13/site-packages/pyrogram/client.py", line 569, in handle_updates
    channel=await self.resolve_peer(utils.get_channel_id(channel_id)),
            ^^^^^^^^^^^^^^^^^^^^^^^^^^^^^^^^^^^^^^^^^^^^^^^^^^^^^^^^^
  File "/workspace/venv/lib/python3.13/site-packages/pyrogram/methods/advanced/resolve_peer.py", line 89, in resolve_peer
    peer_type = utils.get_peer_type(peer_id)
  File "/workspace/venv/lib/python3.13/site-packages/pyrogram/utils.py", line 246, in get_peer_type
    raise ValueError(f"Peer id invalid: {peer_id}")
ValueError: Peer id invalid: -1002430970946
[16-Aug-25 03:10:49 - ERROR] - asyncio - Task exception was never retrieved
future: <Task finished name='Task-315' coro=<Client.handle_updates() done, defined at /workspace/venv/lib/python3.13/site-packages/pyrogram/client.py:535> exception=ValueError('Peer id invalid: -1002475315714')>
Traceback (most recent call last):
  File "/workspace/venv/lib/python3.13/site-packages/pyrogram/methods/advanced/resolve_peer.py", line 62, in resolve_peer
    return await self.storage.get_peer_by_id(peer_id)
           ^^^^^^^^^^^^^^^^^^^^^^^^^^^^^^^^^^^^^^^^^^
  File "/workspace/venv/lib/python3.13/site-packages/pyrogram/storage/sqlite_storage.py", line 142, in get_peer_by_id
    raise KeyError(f"ID not found: {peer_id}")
KeyError: 'ID not found: -1002475315714'

During handling of the above exception, another exception occurred:

Traceback (most recent call last):
  File "/workspace/venv/lib/python3.13/site-packages/pyrogram/client.py", line 569, in handle_updates
    channel=await self.resolve_peer(utils.get_channel_id(channel_id)),
            ^^^^^^^^^^^^^^^^^^^^^^^^^^^^^^^^^^^^^^^^^^^^^^^^^^^^^^^^^
  File "/workspace/venv/lib/python3.13/site-packages/pyrogram/methods/advanced/resolve_peer.py", line 89, in resolve_peer
    peer_type = utils.get_peer_type(peer_id)
  File "/workspace/venv/lib/python3.13/site-packages/pyrogram/utils.py", line 246, in get_peer_type
    raise ValueError(f"Peer id invalid: {peer_id}")
ValueError: Peer id invalid: -1002475315714
[16-Aug-25 03:10:49 - ERROR] - asyncio - Task exception was never retrieved
future: <Task finished name='Task-317' coro=<Client.handle_updates() done, defined at /workspace/venv/lib/python3.13/site-packages/pyrogram/client.py:535> exception=ValueError('Peer id invalid: -1002475315714')>
Traceback (most recent call last):
  File "/workspace/venv/lib/python3.13/site-packages/pyrogram/methods/advanced/resolve_peer.py", line 62, in resolve_peer
    return await self.storage.get_peer_by_id(peer_id)
           ^^^^^^^^^^^^^^^^^^^^^^^^^^^^^^^^^^^^^^^^^^
  File "/workspace/venv/lib/python3.13/site-packages/pyrogram/storage/sqlite_storage.py", line 142, in get_peer_by_id
    raise KeyError(f"ID not found: {peer_id}")
KeyError: 'ID not found: -1002475315714'

During handling of the above exception, another exception occurred:

Traceback (most recent call last):
  File "/workspace/venv/lib/python3.13/site-packages/pyrogram/client.py", line 569, in handle_updates
    channel=await self.resolve_peer(utils.get_channel_id(channel_id)),
            ^^^^^^^^^^^^^^^^^^^^^^^^^^^^^^^^^^^^^^^^^^^^^^^^^^^^^^^^^
  File "/workspace/venv/lib/python3.13/site-packages/pyrogram/methods/advanced/resolve_peer.py", line 89, in resolve_peer
    peer_type = utils.get_peer_type(peer_id)
  File "/workspace/venv/lib/python3.13/site-packages/pyrogram/utils.py", line 246, in get_peer_type
    raise ValueError(f"Peer id invalid: {peer_id}")
ValueError: Peer id invalid: -1002475315714
[16-Aug-25 03:11:00 - INFO] - ZeMusic.core.call - تم تهيئة PyTgCalls بدون decorators
[16-Aug-25 03:11:00 - INFO] - ZeMusic - جاري تشغيل البوت
تم التنصيب على سورس الملك بنجاح
قناة السورس https://t.me/EF_19
[16-Aug-25 03:11:02 - ERROR] - asyncio - Task exception was never retrieved
future: <Task finished name='Task-337' coro=<Client.handle_updates() done, defined at /workspace/venv/lib/python3.13/site-packages/pyrogram/client.py:535> exception=ValueError('Peer id invalid: -1002725376687')>
Traceback (most recent call last):
  File "/workspace/venv/lib/python3.13/site-packages/pyrogram/methods/advanced/resolve_peer.py", line 62, in resolve_peer
    return await self.storage.get_peer_by_id(peer_id)
           ^^^^^^^^^^^^^^^^^^^^^^^^^^^^^^^^^^^^^^^^^^
  File "/workspace/venv/lib/python3.13/site-packages/pyrogram/storage/sqlite_storage.py", line 142, in get_peer_by_id
    raise KeyError(f"ID not found: {peer_id}")
KeyError: 'ID not found: -1002725376687'

During handling of the above exception, another exception occurred:

Traceback (most recent call last):
  File "/workspace/venv/lib/python3.13/site-packages/pyrogram/client.py", line 569, in handle_updates
    channel=await self.resolve_peer(utils.get_channel_id(channel_id)),
            ^^^^^^^^^^^^^^^^^^^^^^^^^^^^^^^^^^^^^^^^^^^^^^^^^^^^^^^^^
  File "/workspace/venv/lib/python3.13/site-packages/pyrogram/methods/advanced/resolve_peer.py", line 89, in resolve_peer
    peer_type = utils.get_peer_type(peer_id)
  File "/workspace/venv/lib/python3.13/site-packages/pyrogram/utils.py", line 246, in get_peer_type
    raise ValueError(f"Peer id invalid: {peer_id}")
ValueError: Peer id invalid: -1002725376687
[16-Aug-25 03:11:15 - ERROR] - asyncio - Task exception was never retrieved
future: <Task finished name='Task-379' coro=<Client.handle_updates() done, defined at /workspace/venv/lib/python3.13/site-packages/pyrogram/client.py:535> exception=ValueError('Peer id invalid: -1002474305961')>
Traceback (most recent call last):
  File "/workspace/venv/lib/python3.13/site-packages/pyrogram/methods/advanced/resolve_peer.py", line 62, in resolve_peer
    return await self.storage.get_peer_by_id(peer_id)
           ^^^^^^^^^^^^^^^^^^^^^^^^^^^^^^^^^^^^^^^^^^
  File "/workspace/venv/lib/python3.13/site-packages/pyrogram/storage/sqlite_storage.py", line 142, in get_peer_by_id
    raise KeyError(f"ID not found: {peer_id}")
KeyError: 'ID not found: -1002474305961'

During handling of the above exception, another exception occurred:

Traceback (most recent call last):
  File "/workspace/venv/lib/python3.13/site-packages/pyrogram/client.py", line 569, in handle_updates
    channel=await self.resolve_peer(utils.get_channel_id(channel_id)),
            ^^^^^^^^^^^^^^^^^^^^^^^^^^^^^^^^^^^^^^^^^^^^^^^^^^^^^^^^^
  File "/workspace/venv/lib/python3.13/site-packages/pyrogram/methods/advanced/resolve_peer.py", line 89, in resolve_peer
    peer_type = utils.get_peer_type(peer_id)
  File "/workspace/venv/lib/python3.13/site-packages/pyrogram/utils.py", line 246, in get_peer_type
    raise ValueError(f"Peer id invalid: {peer_id}")
ValueError: Peer id invalid: -1002474305961
[16-Aug-25 03:11:15 - ERROR] - asyncio - Task exception was never retrieved
future: <Task finished name='Task-382' coro=<Client.handle_updates() done, defined at /workspace/venv/lib/python3.13/site-packages/pyrogram/client.py:535> exception=ValueError('Peer id invalid: -1002474305961')>
Traceback (most recent call last):
  File "/workspace/venv/lib/python3.13/site-packages/pyrogram/methods/advanced/resolve_peer.py", line 62, in resolve_peer
    return await self.storage.get_peer_by_id(peer_id)
           ^^^^^^^^^^^^^^^^^^^^^^^^^^^^^^^^^^^^^^^^^^
  File "/workspace/venv/lib/python3.13/site-packages/pyrogram/storage/sqlite_storage.py", line 142, in get_peer_by_id
    raise KeyError(f"ID not found: {peer_id}")
KeyError: 'ID not found: -1002474305961'

During handling of the above exception, another exception occurred:

Traceback (most recent call last):
  File "/workspace/venv/lib/python3.13/site-packages/pyrogram/client.py", line 569, in handle_updates
    channel=await self.resolve_peer(utils.get_channel_id(channel_id)),
            ^^^^^^^^^^^^^^^^^^^^^^^^^^^^^^^^^^^^^^^^^^^^^^^^^^^^^^^^^
  File "/workspace/venv/lib/python3.13/site-packages/pyrogram/methods/advanced/resolve_peer.py", line 89, in resolve_peer
    peer_type = utils.get_peer_type(peer_id)
  File "/workspace/venv/lib/python3.13/site-packages/pyrogram/utils.py", line 246, in get_peer_type
    raise ValueError(f"Peer id invalid: {peer_id}")
ValueError: Peer id invalid: -1002474305961
[16-Aug-25 03:11:28 - ERROR] - asyncio - Task exception was never retrieved
future: <Task finished name='Task-399' coro=<Client.handle_updates() done, defined at /workspace/venv/lib/python3.13/site-packages/pyrogram/client.py:535> exception=ValueError('Peer id invalid: -1002725376687')>
Traceback (most recent call last):
  File "/workspace/venv/lib/python3.13/site-packages/pyrogram/methods/advanced/resolve_peer.py", line 62, in resolve_peer
    return await self.storage.get_peer_by_id(peer_id)
           ^^^^^^^^^^^^^^^^^^^^^^^^^^^^^^^^^^^^^^^^^^
  File "/workspace/venv/lib/python3.13/site-packages/pyrogram/storage/sqlite_storage.py", line 142, in get_peer_by_id
    raise KeyError(f"ID not found: {peer_id}")
KeyError: 'ID not found: -1002725376687'

During handling of the above exception, another exception occurred:

Traceback (most recent call last):
  File "/workspace/venv/lib/python3.13/site-packages/pyrogram/client.py", line 569, in handle_updates
    channel=await self.resolve_peer(utils.get_channel_id(channel_id)),
            ^^^^^^^^^^^^^^^^^^^^^^^^^^^^^^^^^^^^^^^^^^^^^^^^^^^^^^^^^
  File "/workspace/venv/lib/python3.13/site-packages/pyrogram/methods/advanced/resolve_peer.py", line 89, in resolve_peer
    peer_type = utils.get_peer_type(peer_id)
  File "/workspace/venv/lib/python3.13/site-packages/pyrogram/utils.py", line 246, in get_peer_type
    raise ValueError(f"Peer id invalid: {peer_id}")
ValueError: Peer id invalid: -1002725376687
[16-Aug-25 03:11:29 - ERROR] - asyncio - Task exception was never retrieved
future: <Task finished name='Task-404' coro=<Client.handle_updates() done, defined at /workspace/venv/lib/python3.13/site-packages/pyrogram/client.py:535> exception=ValueError('Peer id invalid: -1002524216878')>
Traceback (most recent call last):
  File "/workspace/venv/lib/python3.13/site-packages/pyrogram/methods/advanced/resolve_peer.py", line 62, in resolve_peer
    return await self.storage.get_peer_by_id(peer_id)
           ^^^^^^^^^^^^^^^^^^^^^^^^^^^^^^^^^^^^^^^^^^
  File "/workspace/venv/lib/python3.13/site-packages/pyrogram/storage/sqlite_storage.py", line 142, in get_peer_by_id
    raise KeyError(f"ID not found: {peer_id}")
KeyError: 'ID not found: -1002524216878'

During handling of the above exception, another exception occurred:

Traceback (most recent call last):
  File "/workspace/venv/lib/python3.13/site-packages/pyrogram/client.py", line 569, in handle_updates
    channel=await self.resolve_peer(utils.get_channel_id(channel_id)),
            ^^^^^^^^^^^^^^^^^^^^^^^^^^^^^^^^^^^^^^^^^^^^^^^^^^^^^^^^^
  File "/workspace/venv/lib/python3.13/site-packages/pyrogram/methods/advanced/resolve_peer.py", line 89, in resolve_peer
    peer_type = utils.get_peer_type(peer_id)
  File "/workspace/venv/lib/python3.13/site-packages/pyrogram/utils.py", line 246, in get_peer_type
    raise ValueError(f"Peer id invalid: {peer_id}")
ValueError: Peer id invalid: -1002524216878
[16-Aug-25 03:11:29 - ERROR] - asyncio - Task exception was never retrieved
future: <Task finished name='Task-406' coro=<Client.handle_updates() done, defined at /workspace/venv/lib/python3.13/site-packages/pyrogram/client.py:535> exception=ValueError('Peer id invalid: -1002524216878')>
Traceback (most recent call last):
  File "/workspace/venv/lib/python3.13/site-packages/pyrogram/methods/advanced/resolve_peer.py", line 62, in resolve_peer
    return await self.storage.get_peer_by_id(peer_id)
           ^^^^^^^^^^^^^^^^^^^^^^^^^^^^^^^^^^^^^^^^^^
  File "/workspace/venv/lib/python3.13/site-packages/pyrogram/storage/sqlite_storage.py", line 142, in get_peer_by_id
    raise KeyError(f"ID not found: {peer_id}")
KeyError: 'ID not found: -1002524216878'

During handling of the above exception, another exception occurred:

Traceback (most recent call last):
  File "/workspace/venv/lib/python3.13/site-packages/pyrogram/client.py", line 569, in handle_updates
    channel=await self.resolve_peer(utils.get_channel_id(channel_id)),
            ^^^^^^^^^^^^^^^^^^^^^^^^^^^^^^^^^^^^^^^^^^^^^^^^^^^^^^^^^
  File "/workspace/venv/lib/python3.13/site-packages/pyrogram/methods/advanced/resolve_peer.py", line 89, in resolve_peer
    peer_type = utils.get_peer_type(peer_id)
  File "/workspace/venv/lib/python3.13/site-packages/pyrogram/utils.py", line 246, in get_peer_type
    raise ValueError(f"Peer id invalid: {peer_id}")
ValueError: Peer id invalid: -1002524216878
[16-Aug-25 03:11:29 - ERROR] - asyncio - Task exception was never retrieved
future: <Task finished name='Task-408' coro=<Client.handle_updates() done, defined at /workspace/venv/lib/python3.13/site-packages/pyrogram/client.py:535> exception=ValueError('Peer id invalid: -1002524216878')>
Traceback (most recent call last):
  File "/workspace/venv/lib/python3.13/site-packages/pyrogram/methods/advanced/resolve_peer.py", line 62, in resolve_peer
    return await self.storage.get_peer_by_id(peer_id)
           ^^^^^^^^^^^^^^^^^^^^^^^^^^^^^^^^^^^^^^^^^^
  File "/workspace/venv/lib/python3.13/site-packages/pyrogram/storage/sqlite_storage.py", line 142, in get_peer_by_id
    raise KeyError(f"ID not found: {peer_id}")
KeyError: 'ID not found: -1002524216878'

During handling of the above exception, another exception occurred:

Traceback (most recent call last):
  File "/workspace/venv/lib/python3.13/site-packages/pyrogram/client.py", line 569, in handle_updates
    channel=await self.resolve_peer(utils.get_channel_id(channel_id)),
            ^^^^^^^^^^^^^^^^^^^^^^^^^^^^^^^^^^^^^^^^^^^^^^^^^^^^^^^^^
  File "/workspace/venv/lib/python3.13/site-packages/pyrogram/methods/advanced/resolve_peer.py", line 89, in resolve_peer
    peer_type = utils.get_peer_type(peer_id)
  File "/workspace/venv/lib/python3.13/site-packages/pyrogram/utils.py", line 246, in get_peer_type
    raise ValueError(f"Peer id invalid: {peer_id}")
ValueError: Peer id invalid: -1002524216878
[16-Aug-25 03:11:29 - ERROR] - asyncio - Task exception was never retrieved
future: <Task finished name='Task-410' coro=<Client.handle_updates() done, defined at /workspace/venv/lib/python3.13/site-packages/pyrogram/client.py:535> exception=ValueError('Peer id invalid: -1002524216878')>
Traceback (most recent call last):
  File "/workspace/venv/lib/python3.13/site-packages/pyrogram/methods/advanced/resolve_peer.py", line 62, in resolve_peer
    return await self.storage.get_peer_by_id(peer_id)
           ^^^^^^^^^^^^^^^^^^^^^^^^^^^^^^^^^^^^^^^^^^
  File "/workspace/venv/lib/python3.13/site-packages/pyrogram/storage/sqlite_storage.py", line 142, in get_peer_by_id
    raise KeyError(f"ID not found: {peer_id}")
KeyError: 'ID not found: -1002524216878'

During handling of the above exception, another exception occurred:

Traceback (most recent call last):
  File "/workspace/venv/lib/python3.13/site-packages/pyrogram/client.py", line 569, in handle_updates
    channel=await self.resolve_peer(utils.get_channel_id(channel_id)),
            ^^^^^^^^^^^^^^^^^^^^^^^^^^^^^^^^^^^^^^^^^^^^^^^^^^^^^^^^^
  File "/workspace/venv/lib/python3.13/site-packages/pyrogram/methods/advanced/resolve_peer.py", line 89, in resolve_peer
    peer_type = utils.get_peer_type(peer_id)
  File "/workspace/venv/lib/python3.13/site-packages/pyrogram/utils.py", line 246, in get_peer_type
    raise ValueError(f"Peer id invalid: {peer_id}")
ValueError: Peer id invalid: -1002524216878
[16-Aug-25 03:11:29 - ERROR] - asyncio - Task exception was never retrieved
future: <Task finished name='Task-412' coro=<Client.handle_updates() done, defined at /workspace/venv/lib/python3.13/site-packages/pyrogram/client.py:535> exception=ValueError('Peer id invalid: -1002524216878')>
Traceback (most recent call last):
  File "/workspace/venv/lib/python3.13/site-packages/pyrogram/methods/advanced/resolve_peer.py", line 62, in resolve_peer
    return await self.storage.get_peer_by_id(peer_id)
           ^^^^^^^^^^^^^^^^^^^^^^^^^^^^^^^^^^^^^^^^^^
  File "/workspace/venv/lib/python3.13/site-packages/pyrogram/storage/sqlite_storage.py", line 142, in get_peer_by_id
    raise KeyError(f"ID not found: {peer_id}")
KeyError: 'ID not found: -1002524216878'

During handling of the above exception, another exception occurred:

Traceback (most recent call last):
  File "/workspace/venv/lib/python3.13/site-packages/pyrogram/client.py", line 569, in handle_updates
    channel=await self.resolve_peer(utils.get_channel_id(channel_id)),
            ^^^^^^^^^^^^^^^^^^^^^^^^^^^^^^^^^^^^^^^^^^^^^^^^^^^^^^^^^
  File "/workspace/venv/lib/python3.13/site-packages/pyrogram/methods/advanced/resolve_peer.py", line 89, in resolve_peer
    peer_type = utils.get_peer_type(peer_id)
  File "/workspace/venv/lib/python3.13/site-packages/pyrogram/utils.py", line 246, in get_peer_type
    raise ValueError(f"Peer id invalid: {peer_id}")
ValueError: Peer id invalid: -1002524216878
[16-Aug-25 03:11:29 - ERROR] - asyncio - Task exception was never retrieved
future: <Task finished name='Task-414' coro=<Client.handle_updates() done, defined at /workspace/venv/lib/python3.13/site-packages/pyrogram/client.py:535> exception=ValueError('Peer id invalid: -1002524216878')>
Traceback (most recent call last):
  File "/workspace/venv/lib/python3.13/site-packages/pyrogram/methods/advanced/resolve_peer.py", line 62, in resolve_peer
    return await self.storage.get_peer_by_id(peer_id)
           ^^^^^^^^^^^^^^^^^^^^^^^^^^^^^^^^^^^^^^^^^^
  File "/workspace/venv/lib/python3.13/site-packages/pyrogram/storage/sqlite_storage.py", line 142, in get_peer_by_id
    raise KeyError(f"ID not found: {peer_id}")
KeyError: 'ID not found: -1002524216878'

During handling of the above exception, another exception occurred:

Traceback (most recent call last):
  File "/workspace/venv/lib/python3.13/site-packages/pyrogram/client.py", line 569, in handle_updates
    channel=await self.resolve_peer(utils.get_channel_id(channel_id)),
            ^^^^^^^^^^^^^^^^^^^^^^^^^^^^^^^^^^^^^^^^^^^^^^^^^^^^^^^^^
  File "/workspace/venv/lib/python3.13/site-packages/pyrogram/methods/advanced/resolve_peer.py", line 89, in resolve_peer
    peer_type = utils.get_peer_type(peer_id)
  File "/workspace/venv/lib/python3.13/site-packages/pyrogram/utils.py", line 246, in get_peer_type
    raise ValueError(f"Peer id invalid: {peer_id}")
ValueError: Peer id invalid: -1002524216878
[16-Aug-25 03:11:29 - ERROR] - asyncio - Task exception was never retrieved
future: <Task finished name='Task-416' coro=<Client.handle_updates() done, defined at /workspace/venv/lib/python3.13/site-packages/pyrogram/client.py:535> exception=ValueError('Peer id invalid: -1002524216878')>
Traceback (most recent call last):
  File "/workspace/venv/lib/python3.13/site-packages/pyrogram/methods/advanced/resolve_peer.py", line 62, in resolve_peer
    return await self.storage.get_peer_by_id(peer_id)
           ^^^^^^^^^^^^^^^^^^^^^^^^^^^^^^^^^^^^^^^^^^
  File "/workspace/venv/lib/python3.13/site-packages/pyrogram/storage/sqlite_storage.py", line 142, in get_peer_by_id
    raise KeyError(f"ID not found: {peer_id}")
KeyError: 'ID not found: -1002524216878'

During handling of the above exception, another exception occurred:

Traceback (most recent call last):
  File "/workspace/venv/lib/python3.13/site-packages/pyrogram/client.py", line 569, in handle_updates
    channel=await self.resolve_peer(utils.get_channel_id(channel_id)),
            ^^^^^^^^^^^^^^^^^^^^^^^^^^^^^^^^^^^^^^^^^^^^^^^^^^^^^^^^^
  File "/workspace/venv/lib/python3.13/site-packages/pyrogram/methods/advanced/resolve_peer.py", line 89, in resolve_peer
    peer_type = utils.get_peer_type(peer_id)
  File "/workspace/venv/lib/python3.13/site-packages/pyrogram/utils.py", line 246, in get_peer_type
    raise ValueError(f"Peer id invalid: {peer_id}")
ValueError: Peer id invalid: -1002524216878
[16-Aug-25 03:11:31 - ERROR] - asyncio - Task exception was never retrieved
future: <Task finished name='Task-421' coro=<Client.handle_updates() done, defined at /workspace/venv/lib/python3.13/site-packages/pyrogram/client.py:535> exception=ValueError('Peer id invalid: -1002475315714')>
Traceback (most recent call last):
  File "/workspace/venv/lib/python3.13/site-packages/pyrogram/methods/advanced/resolve_peer.py", line 62, in resolve_peer
    return await self.storage.get_peer_by_id(peer_id)
           ^^^^^^^^^^^^^^^^^^^^^^^^^^^^^^^^^^^^^^^^^^
  File "/workspace/venv/lib/python3.13/site-packages/pyrogram/storage/sqlite_storage.py", line 142, in get_peer_by_id
    raise KeyError(f"ID not found: {peer_id}")
KeyError: 'ID not found: -1002475315714'

During handling of the above exception, another exception occurred:

Traceback (most recent call last):
  File "/workspace/venv/lib/python3.13/site-packages/pyrogram/client.py", line 569, in handle_updates
    channel=await self.resolve_peer(utils.get_channel_id(channel_id)),
            ^^^^^^^^^^^^^^^^^^^^^^^^^^^^^^^^^^^^^^^^^^^^^^^^^^^^^^^^^
  File "/workspace/venv/lib/python3.13/site-packages/pyrogram/methods/advanced/resolve_peer.py", line 89, in resolve_peer
    peer_type = utils.get_peer_type(peer_id)
  File "/workspace/venv/lib/python3.13/site-packages/pyrogram/utils.py", line 246, in get_peer_type
    raise ValueError(f"Peer id invalid: {peer_id}")
ValueError: Peer id invalid: -1002475315714
[16-Aug-25 03:11:32 - ERROR] - asyncio - Task exception was never retrieved
future: <Task finished name='Task-423' coro=<Client.handle_updates() done, defined at /workspace/venv/lib/python3.13/site-packages/pyrogram/client.py:535> exception=ValueError('Peer id invalid: -1002474305961')>
Traceback (most recent call last):
  File "/workspace/venv/lib/python3.13/site-packages/pyrogram/methods/advanced/resolve_peer.py", line 62, in resolve_peer
    return await self.storage.get_peer_by_id(peer_id)
           ^^^^^^^^^^^^^^^^^^^^^^^^^^^^^^^^^^^^^^^^^^
  File "/workspace/venv/lib/python3.13/site-packages/pyrogram/storage/sqlite_storage.py", line 142, in get_peer_by_id
    raise KeyError(f"ID not found: {peer_id}")
KeyError: 'ID not found: -1002474305961'

During handling of the above exception, another exception occurred:

Traceback (most recent call last):
  File "/workspace/venv/lib/python3.13/site-packages/pyrogram/client.py", line 569, in handle_updates
    channel=await self.resolve_peer(utils.get_channel_id(channel_id)),
            ^^^^^^^^^^^^^^^^^^^^^^^^^^^^^^^^^^^^^^^^^^^^^^^^^^^^^^^^^
  File "/workspace/venv/lib/python3.13/site-packages/pyrogram/methods/advanced/resolve_peer.py", line 89, in resolve_peer
    peer_type = utils.get_peer_type(peer_id)
  File "/workspace/venv/lib/python3.13/site-packages/pyrogram/utils.py", line 246, in get_peer_type
    raise ValueError(f"Peer id invalid: {peer_id}")
ValueError: Peer id invalid: -1002474305961
[16-Aug-25 03:11:34 - ERROR] - asyncio - Task exception was never retrieved
future: <Task finished name='Task-432' coro=<Client.handle_updates() done, defined at /workspace/venv/lib/python3.13/site-packages/pyrogram/client.py:535> exception=ValueError('Peer id invalid: -1002524216878')>
Traceback (most recent call last):
  File "/workspace/venv/lib/python3.13/site-packages/pyrogram/methods/advanced/resolve_peer.py", line 62, in resolve_peer
    return await self.storage.get_peer_by_id(peer_id)
           ^^^^^^^^^^^^^^^^^^^^^^^^^^^^^^^^^^^^^^^^^^
  File "/workspace/venv/lib/python3.13/site-packages/pyrogram/storage/sqlite_storage.py", line 142, in get_peer_by_id
    raise KeyError(f"ID not found: {peer_id}")
KeyError: 'ID not found: -1002524216878'

During handling of the above exception, another exception occurred:

Traceback (most recent call last):
  File "/workspace/venv/lib/python3.13/site-packages/pyrogram/client.py", line 569, in handle_updates
    channel=await self.resolve_peer(utils.get_channel_id(channel_id)),
            ^^^^^^^^^^^^^^^^^^^^^^^^^^^^^^^^^^^^^^^^^^^^^^^^^^^^^^^^^
  File "/workspace/venv/lib/python3.13/site-packages/pyrogram/methods/advanced/resolve_peer.py", line 89, in resolve_peer
    peer_type = utils.get_peer_type(peer_id)
  File "/workspace/venv/lib/python3.13/site-packages/pyrogram/utils.py", line 246, in get_peer_type
    raise ValueError(f"Peer id invalid: {peer_id}")
ValueError: Peer id invalid: -1002524216878
[16-Aug-25 03:11:34 - ERROR] - asyncio - Task exception was never retrieved
future: <Task finished name='Task-434' coro=<Client.handle_updates() done, defined at /workspace/venv/lib/python3.13/site-packages/pyrogram/client.py:535> exception=ValueError('Peer id invalid: -1002524216878')>
Traceback (most recent call last):
  File "/workspace/venv/lib/python3.13/site-packages/pyrogram/methods/advanced/resolve_peer.py", line 62, in resolve_peer
    return await self.storage.get_peer_by_id(peer_id)
           ^^^^^^^^^^^^^^^^^^^^^^^^^^^^^^^^^^^^^^^^^^
  File "/workspace/venv/lib/python3.13/site-packages/pyrogram/storage/sqlite_storage.py", line 142, in get_peer_by_id
    raise KeyError(f"ID not found: {peer_id}")
KeyError: 'ID not found: -1002524216878'

During handling of the above exception, another exception occurred:

Traceback (most recent call last):
  File "/workspace/venv/lib/python3.13/site-packages/pyrogram/client.py", line 569, in handle_updates
    channel=await self.resolve_peer(utils.get_channel_id(channel_id)),
            ^^^^^^^^^^^^^^^^^^^^^^^^^^^^^^^^^^^^^^^^^^^^^^^^^^^^^^^^^
  File "/workspace/venv/lib/python3.13/site-packages/pyrogram/methods/advanced/resolve_peer.py", line 89, in resolve_peer
    peer_type = utils.get_peer_type(peer_id)
  File "/workspace/venv/lib/python3.13/site-packages/pyrogram/utils.py", line 246, in get_peer_type
    raise ValueError(f"Peer id invalid: {peer_id}")
ValueError: Peer id invalid: -1002524216878
[16-Aug-25 03:11:34 - ERROR] - asyncio - Task exception was never retrieved
future: <Task finished name='Task-436' coro=<Client.handle_updates() done, defined at /workspace/venv/lib/python3.13/site-packages/pyrogram/client.py:535> exception=ValueError('Peer id invalid: -1002524216878')>
Traceback (most recent call last):
  File "/workspace/venv/lib/python3.13/site-packages/pyrogram/methods/advanced/resolve_peer.py", line 62, in resolve_peer
    return await self.storage.get_peer_by_id(peer_id)
           ^^^^^^^^^^^^^^^^^^^^^^^^^^^^^^^^^^^^^^^^^^
  File "/workspace/venv/lib/python3.13/site-packages/pyrogram/storage/sqlite_storage.py", line 142, in get_peer_by_id
    raise KeyError(f"ID not found: {peer_id}")
KeyError: 'ID not found: -1002524216878'

During handling of the above exception, another exception occurred:

Traceback (most recent call last):
  File "/workspace/venv/lib/python3.13/site-packages/pyrogram/client.py", line 569, in handle_updates
    channel=await self.resolve_peer(utils.get_channel_id(channel_id)),
            ^^^^^^^^^^^^^^^^^^^^^^^^^^^^^^^^^^^^^^^^^^^^^^^^^^^^^^^^^
  File "/workspace/venv/lib/python3.13/site-packages/pyrogram/methods/advanced/resolve_peer.py", line 89, in resolve_peer
    peer_type = utils.get_peer_type(peer_id)
  File "/workspace/venv/lib/python3.13/site-packages/pyrogram/utils.py", line 246, in get_peer_type
    raise ValueError(f"Peer id invalid: {peer_id}")
ValueError: Peer id invalid: -1002524216878
[16-Aug-25 03:11:34 - ERROR] - asyncio - Task exception was never retrieved
future: <Task finished name='Task-438' coro=<Client.handle_updates() done, defined at /workspace/venv/lib/python3.13/site-packages/pyrogram/client.py:535> exception=ValueError('Peer id invalid: -1002524216878')>
Traceback (most recent call last):
  File "/workspace/venv/lib/python3.13/site-packages/pyrogram/methods/advanced/resolve_peer.py", line 62, in resolve_peer
    return await self.storage.get_peer_by_id(peer_id)
           ^^^^^^^^^^^^^^^^^^^^^^^^^^^^^^^^^^^^^^^^^^
  File "/workspace/venv/lib/python3.13/site-packages/pyrogram/storage/sqlite_storage.py", line 142, in get_peer_by_id
    raise KeyError(f"ID not found: {peer_id}")
KeyError: 'ID not found: -1002524216878'

During handling of the above exception, another exception occurred:

Traceback (most recent call last):
  File "/workspace/venv/lib/python3.13/site-packages/pyrogram/client.py", line 569, in handle_updates
    channel=await self.resolve_peer(utils.get_channel_id(channel_id)),
            ^^^^^^^^^^^^^^^^^^^^^^^^^^^^^^^^^^^^^^^^^^^^^^^^^^^^^^^^^
  File "/workspace/venv/lib/python3.13/site-packages/pyrogram/methods/advanced/resolve_peer.py", line 89, in resolve_peer
    peer_type = utils.get_peer_type(peer_id)
  File "/workspace/venv/lib/python3.13/site-packages/pyrogram/utils.py", line 246, in get_peer_type
    raise ValueError(f"Peer id invalid: {peer_id}")
ValueError: Peer id invalid: -1002524216878
[16-Aug-25 03:11:34 - ERROR] - asyncio - Task exception was never retrieved
future: <Task finished name='Task-440' coro=<Client.handle_updates() done, defined at /workspace/venv/lib/python3.13/site-packages/pyrogram/client.py:535> exception=ValueError('Peer id invalid: -1002524216878')>
Traceback (most recent call last):
  File "/workspace/venv/lib/python3.13/site-packages/pyrogram/methods/advanced/resolve_peer.py", line 62, in resolve_peer
    return await self.storage.get_peer_by_id(peer_id)
           ^^^^^^^^^^^^^^^^^^^^^^^^^^^^^^^^^^^^^^^^^^
  File "/workspace/venv/lib/python3.13/site-packages/pyrogram/storage/sqlite_storage.py", line 142, in get_peer_by_id
    raise KeyError(f"ID not found: {peer_id}")
KeyError: 'ID not found: -1002524216878'

During handling of the above exception, another exception occurred:

Traceback (most recent call last):
  File "/workspace/venv/lib/python3.13/site-packages/pyrogram/client.py", line 569, in handle_updates
    channel=await self.resolve_peer(utils.get_channel_id(channel_id)),
            ^^^^^^^^^^^^^^^^^^^^^^^^^^^^^^^^^^^^^^^^^^^^^^^^^^^^^^^^^
  File "/workspace/venv/lib/python3.13/site-packages/pyrogram/methods/advanced/resolve_peer.py", line 89, in resolve_peer
    peer_type = utils.get_peer_type(peer_id)
  File "/workspace/venv/lib/python3.13/site-packages/pyrogram/utils.py", line 246, in get_peer_type
    raise ValueError(f"Peer id invalid: {peer_id}")
ValueError: Peer id invalid: -1002524216878
[16-Aug-25 03:11:39 - ERROR] - asyncio - Task exception was never retrieved
future: <Task finished name='Task-449' coro=<Client.handle_updates() done, defined at /workspace/venv/lib/python3.13/site-packages/pyrogram/client.py:535> exception=ValueError('Peer id invalid: -1002725376687')>
Traceback (most recent call last):
  File "/workspace/venv/lib/python3.13/site-packages/pyrogram/methods/advanced/resolve_peer.py", line 62, in resolve_peer
    return await self.storage.get_peer_by_id(peer_id)
           ^^^^^^^^^^^^^^^^^^^^^^^^^^^^^^^^^^^^^^^^^^
  File "/workspace/venv/lib/python3.13/site-packages/pyrogram/storage/sqlite_storage.py", line 142, in get_peer_by_id
    raise KeyError(f"ID not found: {peer_id}")
KeyError: 'ID not found: -1002725376687'

During handling of the above exception, another exception occurred:

Traceback (most recent call last):
  File "/workspace/venv/lib/python3.13/site-packages/pyrogram/client.py", line 569, in handle_updates
    channel=await self.resolve_peer(utils.get_channel_id(channel_id)),
            ^^^^^^^^^^^^^^^^^^^^^^^^^^^^^^^^^^^^^^^^^^^^^^^^^^^^^^^^^
  File "/workspace/venv/lib/python3.13/site-packages/pyrogram/methods/advanced/resolve_peer.py", line 89, in resolve_peer
    peer_type = utils.get_peer_type(peer_id)
  File "/workspace/venv/lib/python3.13/site-packages/pyrogram/utils.py", line 246, in get_peer_type
    raise ValueError(f"Peer id invalid: {peer_id}")
ValueError: Peer id invalid: -1002725376687
[16-Aug-25 03:11:39 - ERROR] - asyncio - Task exception was never retrieved
future: <Task finished name='Task-451' coro=<Client.handle_updates() done, defined at /workspace/venv/lib/python3.13/site-packages/pyrogram/client.py:535> exception=ValueError('Peer id invalid: -1002725376687')>
Traceback (most recent call last):
  File "/workspace/venv/lib/python3.13/site-packages/pyrogram/methods/advanced/resolve_peer.py", line 62, in resolve_peer
    return await self.storage.get_peer_by_id(peer_id)
           ^^^^^^^^^^^^^^^^^^^^^^^^^^^^^^^^^^^^^^^^^^
  File "/workspace/venv/lib/python3.13/site-packages/pyrogram/storage/sqlite_storage.py", line 142, in get_peer_by_id
    raise KeyError(f"ID not found: {peer_id}")
KeyError: 'ID not found: -1002725376687'

During handling of the above exception, another exception occurred:

Traceback (most recent call last):
  File "/workspace/venv/lib/python3.13/site-packages/pyrogram/client.py", line 569, in handle_updates
    channel=await self.resolve_peer(utils.get_channel_id(channel_id)),
            ^^^^^^^^^^^^^^^^^^^^^^^^^^^^^^^^^^^^^^^^^^^^^^^^^^^^^^^^^
  File "/workspace/venv/lib/python3.13/site-packages/pyrogram/methods/advanced/resolve_peer.py", line 89, in resolve_peer
    peer_type = utils.get_peer_type(peer_id)
  File "/workspace/venv/lib/python3.13/site-packages/pyrogram/utils.py", line 246, in get_peer_type
    raise ValueError(f"Peer id invalid: {peer_id}")
ValueError: Peer id invalid: -1002725376687
[16-Aug-25 03:11:39 - ERROR] - asyncio - Task exception was never retrieved
future: <Task finished name='Task-453' coro=<Client.handle_updates() done, defined at /workspace/venv/lib/python3.13/site-packages/pyrogram/client.py:535> exception=ValueError('Peer id invalid: -1002725376687')>
Traceback (most recent call last):
  File "/workspace/venv/lib/python3.13/site-packages/pyrogram/methods/advanced/resolve_peer.py", line 62, in resolve_peer
    return await self.storage.get_peer_by_id(peer_id)
           ^^^^^^^^^^^^^^^^^^^^^^^^^^^^^^^^^^^^^^^^^^
  File "/workspace/venv/lib/python3.13/site-packages/pyrogram/storage/sqlite_storage.py", line 142, in get_peer_by_id
    raise KeyError(f"ID not found: {peer_id}")
KeyError: 'ID not found: -1002725376687'

During handling of the above exception, another exception occurred:

Traceback (most recent call last):
  File "/workspace/venv/lib/python3.13/site-packages/pyrogram/client.py", line 569, in handle_updates
    channel=await self.resolve_peer(utils.get_channel_id(channel_id)),
            ^^^^^^^^^^^^^^^^^^^^^^^^^^^^^^^^^^^^^^^^^^^^^^^^^^^^^^^^^
  File "/workspace/venv/lib/python3.13/site-packages/pyrogram/methods/advanced/resolve_peer.py", line 89, in resolve_peer
    peer_type = utils.get_peer_type(peer_id)
  File "/workspace/venv/lib/python3.13/site-packages/pyrogram/utils.py", line 246, in get_peer_type
    raise ValueError(f"Peer id invalid: {peer_id}")
ValueError: Peer id invalid: -1002725376687
[16-Aug-25 03:11:44 - ERROR] - asyncio - Task exception was never retrieved
future: <Task finished name='Task-464' coro=<Client.handle_updates() done, defined at /workspace/venv/lib/python3.13/site-packages/pyrogram/client.py:535> exception=ValueError('Peer id invalid: -1002474305961')>
Traceback (most recent call last):
  File "/workspace/venv/lib/python3.13/site-packages/pyrogram/methods/advanced/resolve_peer.py", line 62, in resolve_peer
    return await self.storage.get_peer_by_id(peer_id)
           ^^^^^^^^^^^^^^^^^^^^^^^^^^^^^^^^^^^^^^^^^^
  File "/workspace/venv/lib/python3.13/site-packages/pyrogram/storage/sqlite_storage.py", line 142, in get_peer_by_id
    raise KeyError(f"ID not found: {peer_id}")
KeyError: 'ID not found: -1002474305961'

During handling of the above exception, another exception occurred:

Traceback (most recent call last):
  File "/workspace/venv/lib/python3.13/site-packages/pyrogram/client.py", line 569, in handle_updates
    channel=await self.resolve_peer(utils.get_channel_id(channel_id)),
            ^^^^^^^^^^^^^^^^^^^^^^^^^^^^^^^^^^^^^^^^^^^^^^^^^^^^^^^^^
  File "/workspace/venv/lib/python3.13/site-packages/pyrogram/methods/advanced/resolve_peer.py", line 89, in resolve_peer
    peer_type = utils.get_peer_type(peer_id)
  File "/workspace/venv/lib/python3.13/site-packages/pyrogram/utils.py", line 246, in get_peer_type
    raise ValueError(f"Peer id invalid: {peer_id}")
ValueError: Peer id invalid: -1002474305961
[16-Aug-25 03:11:48 - ERROR] - asyncio - Task exception was never retrieved
future: <Task finished name='Task-470' coro=<Client.handle_updates() done, defined at /workspace/venv/lib/python3.13/site-packages/pyrogram/client.py:535> exception=ValueError('Peer id invalid: -1002524216878')>
Traceback (most recent call last):
  File "/workspace/venv/lib/python3.13/site-packages/pyrogram/methods/advanced/resolve_peer.py", line 62, in resolve_peer
    return await self.storage.get_peer_by_id(peer_id)
           ^^^^^^^^^^^^^^^^^^^^^^^^^^^^^^^^^^^^^^^^^^
  File "/workspace/venv/lib/python3.13/site-packages/pyrogram/storage/sqlite_storage.py", line 142, in get_peer_by_id
    raise KeyError(f"ID not found: {peer_id}")
KeyError: 'ID not found: -1002524216878'

During handling of the above exception, another exception occurred:

Traceback (most recent call last):
  File "/workspace/venv/lib/python3.13/site-packages/pyrogram/client.py", line 569, in handle_updates
    channel=await self.resolve_peer(utils.get_channel_id(channel_id)),
            ^^^^^^^^^^^^^^^^^^^^^^^^^^^^^^^^^^^^^^^^^^^^^^^^^^^^^^^^^
  File "/workspace/venv/lib/python3.13/site-packages/pyrogram/methods/advanced/resolve_peer.py", line 89, in resolve_peer
    peer_type = utils.get_peer_type(peer_id)
  File "/workspace/venv/lib/python3.13/site-packages/pyrogram/utils.py", line 246, in get_peer_type
    raise ValueError(f"Peer id invalid: {peer_id}")
ValueError: Peer id invalid: -1002524216878
[16-Aug-25 03:11:51 - ERROR] - asyncio - Task exception was never retrieved
future: <Task finished name='Task-478' coro=<Client.handle_updates() done, defined at /workspace/venv/lib/python3.13/site-packages/pyrogram/client.py:535> exception=ValueError('Peer id invalid: -1002474305961')>
Traceback (most recent call last):
  File "/workspace/venv/lib/python3.13/site-packages/pyrogram/methods/advanced/resolve_peer.py", line 62, in resolve_peer
    return await self.storage.get_peer_by_id(peer_id)
           ^^^^^^^^^^^^^^^^^^^^^^^^^^^^^^^^^^^^^^^^^^
  File "/workspace/venv/lib/python3.13/site-packages/pyrogram/storage/sqlite_storage.py", line 142, in get_peer_by_id
    raise KeyError(f"ID not found: {peer_id}")
KeyError: 'ID not found: -1002474305961'

During handling of the above exception, another exception occurred:

Traceback (most recent call last):
  File "/workspace/venv/lib/python3.13/site-packages/pyrogram/client.py", line 569, in handle_updates
    channel=await self.resolve_peer(utils.get_channel_id(channel_id)),
            ^^^^^^^^^^^^^^^^^^^^^^^^^^^^^^^^^^^^^^^^^^^^^^^^^^^^^^^^^
  File "/workspace/venv/lib/python3.13/site-packages/pyrogram/methods/advanced/resolve_peer.py", line 89, in resolve_peer
    peer_type = utils.get_peer_type(peer_id)
  File "/workspace/venv/lib/python3.13/site-packages/pyrogram/utils.py", line 246, in get_peer_type
    raise ValueError(f"Peer id invalid: {peer_id}")
ValueError: Peer id invalid: -1002474305961
[16-Aug-25 03:11:54 - ERROR] - asyncio - Task exception was never retrieved
future: <Task finished name='Task-486' coro=<Client.handle_updates() done, defined at /workspace/venv/lib/python3.13/site-packages/pyrogram/client.py:535> exception=ValueError('Peer id invalid: -1002725376687')>
Traceback (most recent call last):
  File "/workspace/venv/lib/python3.13/site-packages/pyrogram/methods/advanced/resolve_peer.py", line 62, in resolve_peer
    return await self.storage.get_peer_by_id(peer_id)
           ^^^^^^^^^^^^^^^^^^^^^^^^^^^^^^^^^^^^^^^^^^
  File "/workspace/venv/lib/python3.13/site-packages/pyrogram/storage/sqlite_storage.py", line 142, in get_peer_by_id
    raise KeyError(f"ID not found: {peer_id}")
KeyError: 'ID not found: -1002725376687'

During handling of the above exception, another exception occurred:

Traceback (most recent call last):
  File "/workspace/venv/lib/python3.13/site-packages/pyrogram/client.py", line 569, in handle_updates
    channel=await self.resolve_peer(utils.get_channel_id(channel_id)),
            ^^^^^^^^^^^^^^^^^^^^^^^^^^^^^^^^^^^^^^^^^^^^^^^^^^^^^^^^^
  File "/workspace/venv/lib/python3.13/site-packages/pyrogram/methods/advanced/resolve_peer.py", line 89, in resolve_peer
    peer_type = utils.get_peer_type(peer_id)
  File "/workspace/venv/lib/python3.13/site-packages/pyrogram/utils.py", line 246, in get_peer_type
    raise ValueError(f"Peer id invalid: {peer_id}")
ValueError: Peer id invalid: -1002725376687
[16-Aug-25 03:11:55 - ERROR] - asyncio - Task exception was never retrieved
future: <Task finished name='Task-493' coro=<Client.handle_updates() done, defined at /workspace/venv/lib/python3.13/site-packages/pyrogram/client.py:535> exception=ValueError('Peer id invalid: -1002524216878')>
Traceback (most recent call last):
  File "/workspace/venv/lib/python3.13/site-packages/pyrogram/methods/advanced/resolve_peer.py", line 62, in resolve_peer
    return await self.storage.get_peer_by_id(peer_id)
           ^^^^^^^^^^^^^^^^^^^^^^^^^^^^^^^^^^^^^^^^^^
  File "/workspace/venv/lib/python3.13/site-packages/pyrogram/storage/sqlite_storage.py", line 142, in get_peer_by_id
    raise KeyError(f"ID not found: {peer_id}")
KeyError: 'ID not found: -1002524216878'

During handling of the above exception, another exception occurred:

Traceback (most recent call last):
  File "/workspace/venv/lib/python3.13/site-packages/pyrogram/client.py", line 569, in handle_updates
    channel=await self.resolve_peer(utils.get_channel_id(channel_id)),
            ^^^^^^^^^^^^^^^^^^^^^^^^^^^^^^^^^^^^^^^^^^^^^^^^^^^^^^^^^
  File "/workspace/venv/lib/python3.13/site-packages/pyrogram/methods/advanced/resolve_peer.py", line 89, in resolve_peer
    peer_type = utils.get_peer_type(peer_id)
  File "/workspace/venv/lib/python3.13/site-packages/pyrogram/utils.py", line 246, in get_peer_type
    raise ValueError(f"Peer id invalid: {peer_id}")
ValueError: Peer id invalid: -1002524216878
[16-Aug-25 03:11:56 - ERROR] - asyncio - Task exception was never retrieved
future: <Task finished name='Task-495' coro=<Client.handle_updates() done, defined at /workspace/venv/lib/python3.13/site-packages/pyrogram/client.py:535> exception=ValueError('Peer id invalid: -1002524216878')>
Traceback (most recent call last):
  File "/workspace/venv/lib/python3.13/site-packages/pyrogram/methods/advanced/resolve_peer.py", line 62, in resolve_peer
    return await self.storage.get_peer_by_id(peer_id)
           ^^^^^^^^^^^^^^^^^^^^^^^^^^^^^^^^^^^^^^^^^^
  File "/workspace/venv/lib/python3.13/site-packages/pyrogram/storage/sqlite_storage.py", line 142, in get_peer_by_id
    raise KeyError(f"ID not found: {peer_id}")
KeyError: 'ID not found: -1002524216878'

During handling of the above exception, another exception occurred:

Traceback (most recent call last):
  File "/workspace/venv/lib/python3.13/site-packages/pyrogram/client.py", line 569, in handle_updates
    channel=await self.resolve_peer(utils.get_channel_id(channel_id)),
            ^^^^^^^^^^^^^^^^^^^^^^^^^^^^^^^^^^^^^^^^^^^^^^^^^^^^^^^^^
  File "/workspace/venv/lib/python3.13/site-packages/pyrogram/methods/advanced/resolve_peer.py", line 89, in resolve_peer
    peer_type = utils.get_peer_type(peer_id)
  File "/workspace/venv/lib/python3.13/site-packages/pyrogram/utils.py", line 246, in get_peer_type
    raise ValueError(f"Peer id invalid: {peer_id}")
ValueError: Peer id invalid: -1002524216878
[16-Aug-25 03:11:56 - ERROR] - asyncio - Task exception was never retrieved
future: <Task finished name='Task-497' coro=<Client.handle_updates() done, defined at /workspace/venv/lib/python3.13/site-packages/pyrogram/client.py:535> exception=ValueError('Peer id invalid: -1002524216878')>
Traceback (most recent call last):
  File "/workspace/venv/lib/python3.13/site-packages/pyrogram/methods/advanced/resolve_peer.py", line 62, in resolve_peer
    return await self.storage.get_peer_by_id(peer_id)
           ^^^^^^^^^^^^^^^^^^^^^^^^^^^^^^^^^^^^^^^^^^
  File "/workspace/venv/lib/python3.13/site-packages/pyrogram/storage/sqlite_storage.py", line 142, in get_peer_by_id
    raise KeyError(f"ID not found: {peer_id}")
KeyError: 'ID not found: -1002524216878'

During handling of the above exception, another exception occurred:

Traceback (most recent call last):
  File "/workspace/venv/lib/python3.13/site-packages/pyrogram/client.py", line 569, in handle_updates
    channel=await self.resolve_peer(utils.get_channel_id(channel_id)),
            ^^^^^^^^^^^^^^^^^^^^^^^^^^^^^^^^^^^^^^^^^^^^^^^^^^^^^^^^^
  File "/workspace/venv/lib/python3.13/site-packages/pyrogram/methods/advanced/resolve_peer.py", line 89, in resolve_peer
    peer_type = utils.get_peer_type(peer_id)
  File "/workspace/venv/lib/python3.13/site-packages/pyrogram/utils.py", line 246, in get_peer_type
    raise ValueError(f"Peer id invalid: {peer_id}")
ValueError: Peer id invalid: -1002524216878
[16-Aug-25 03:11:56 - ERROR] - asyncio - Task exception was never retrieved
future: <Task finished name='Task-499' coro=<Client.handle_updates() done, defined at /workspace/venv/lib/python3.13/site-packages/pyrogram/client.py:535> exception=ValueError('Peer id invalid: -1002474305961')>
Traceback (most recent call last):
  File "/workspace/venv/lib/python3.13/site-packages/pyrogram/methods/advanced/resolve_peer.py", line 62, in resolve_peer
    return await self.storage.get_peer_by_id(peer_id)
           ^^^^^^^^^^^^^^^^^^^^^^^^^^^^^^^^^^^^^^^^^^
  File "/workspace/venv/lib/python3.13/site-packages/pyrogram/storage/sqlite_storage.py", line 142, in get_peer_by_id
    raise KeyError(f"ID not found: {peer_id}")
KeyError: 'ID not found: -1002474305961'

During handling of the above exception, another exception occurred:

Traceback (most recent call last):
  File "/workspace/venv/lib/python3.13/site-packages/pyrogram/client.py", line 569, in handle_updates
    channel=await self.resolve_peer(utils.get_channel_id(channel_id)),
            ^^^^^^^^^^^^^^^^^^^^^^^^^^^^^^^^^^^^^^^^^^^^^^^^^^^^^^^^^
  File "/workspace/venv/lib/python3.13/site-packages/pyrogram/methods/advanced/resolve_peer.py", line 89, in resolve_peer
    peer_type = utils.get_peer_type(peer_id)
  File "/workspace/venv/lib/python3.13/site-packages/pyrogram/utils.py", line 246, in get_peer_type
    raise ValueError(f"Peer id invalid: {peer_id}")
ValueError: Peer id invalid: -1002474305961
[16-Aug-25 03:11:59 - ERROR] - pyrogram.dispatcher - Peer id invalid: -1002474305961
Traceback (most recent call last):
  File "/workspace/venv/lib/python3.13/site-packages/pyrogram/methods/advanced/resolve_peer.py", line 62, in resolve_peer
    return await self.storage.get_peer_by_id(peer_id)
           ^^^^^^^^^^^^^^^^^^^^^^^^^^^^^^^^^^^^^^^^^^
  File "/workspace/venv/lib/python3.13/site-packages/pyrogram/storage/sqlite_storage.py", line 142, in get_peer_by_id
    raise KeyError(f"ID not found: {peer_id}")
KeyError: 'ID not found: -1002474305961'

During handling of the above exception, another exception occurred:

Traceback (most recent call last):
  File "/workspace/venv/lib/python3.13/site-packages/pyrogram/dispatcher.py", line 214, in handler_worker
    await parser(update, users, chats)
  File "/workspace/venv/lib/python3.13/site-packages/pyrogram/dispatcher.py", line 75, in edited_message_parser
    parsed, _ = await message_parser(update, users, chats)
                ^^^^^^^^^^^^^^^^^^^^^^^^^^^^^^^^^^^^^^^^^^
  File "/workspace/venv/lib/python3.13/site-packages/pyrogram/dispatcher.py", line 68, in message_parser
    await pyrogram.types.Message._parse(self.client, update.message, users, chats,
    ^^^^^^^^^^^^^^^^^^^^^^^^^^^^^^^^^^^^^^^^^^^^^^^^^^^^^^^^^^^^^^^^^^^^^^^^^^^^^^
                                        isinstance(update, UpdateNewScheduledMessage)),
                                        ^^^^^^^^^^^^^^^^^^^^^^^^^^^^^^^^^^^^^^^^^^^^^^
  File "/workspace/venv/lib/python3.13/site-packages/pyrogram/types/messages_and_media/message.py", line 836, in _parse
    reply_to_message = await client.get_messages(
                       ^^^^^^^^^^^^^^^^^^^^^^^^^^
    ...<3 lines>...
    )
    ^
  File "/workspace/venv/lib/python3.13/site-packages/pyrogram/methods/messages/get_messages.py", line 101, in get_messages
    peer = await self.resolve_peer(chat_id)
           ^^^^^^^^^^^^^^^^^^^^^^^^^^^^^^^^
  File "/workspace/venv/lib/python3.13/site-packages/pyrogram/methods/advanced/resolve_peer.py", line 89, in resolve_peer
    peer_type = utils.get_peer_type(peer_id)
  File "/workspace/venv/lib/python3.13/site-packages/pyrogram/utils.py", line 246, in get_peer_type
    raise ValueError(f"Peer id invalid: {peer_id}")
ValueError: Peer id invalid: -1002474305961
ERROR: [youtube] 6Q8e8tmKWMI: Sign in to confirm you’re not a bot. Use --cookies-from-browser or --cookies for the authentication. See  https://github.com/yt-dlp/yt-dlp/wiki/FAQ#how-do-i-pass-cookies-to-yt-dlp  for how to manually pass cookies. Also see  https://github.com/yt-dlp/yt-dlp/wiki/Extractors#exporting-youtube-cookies  for tips on effectively exporting YouTube cookies
[16-Aug-25 03:12:19 - ERROR] - asyncio - Task exception was never retrieved
future: <Task finished name='Task-558' coro=<Client.handle_updates() done, defined at /workspace/venv/lib/python3.13/site-packages/pyrogram/client.py:535> exception=ValueError('Peer id invalid: -1002430970946')>
Traceback (most recent call last):
  File "/workspace/venv/lib/python3.13/site-packages/pyrogram/methods/advanced/resolve_peer.py", line 62, in resolve_peer
    return await self.storage.get_peer_by_id(peer_id)
           ^^^^^^^^^^^^^^^^^^^^^^^^^^^^^^^^^^^^^^^^^^
  File "/workspace/venv/lib/python3.13/site-packages/pyrogram/storage/sqlite_storage.py", line 142, in get_peer_by_id
    raise KeyError(f"ID not found: {peer_id}")
KeyError: 'ID not found: -1002430970946'

During handling of the above exception, another exception occurred:

Traceback (most recent call last):
  File "/workspace/venv/lib/python3.13/site-packages/pyrogram/client.py", line 569, in handle_updates
    channel=await self.resolve_peer(utils.get_channel_id(channel_id)),
            ^^^^^^^^^^^^^^^^^^^^^^^^^^^^^^^^^^^^^^^^^^^^^^^^^^^^^^^^^
  File "/workspace/venv/lib/python3.13/site-packages/pyrogram/methods/advanced/resolve_peer.py", line 89, in resolve_peer
    peer_type = utils.get_peer_type(peer_id)
  File "/workspace/venv/lib/python3.13/site-packages/pyrogram/utils.py", line 246, in get_peer_type
    raise ValueError(f"Peer id invalid: {peer_id}")
ValueError: Peer id invalid: -1002430970946
[16-Aug-25 03:12:19 - ERROR] - asyncio - Task exception was never retrieved
future: <Task finished name='Task-559' coro=<Client.handle_updates() done, defined at /workspace/venv/lib/python3.13/site-packages/pyrogram/client.py:535> exception=ValueError('Peer id invalid: -1002430970946')>
Traceback (most recent call last):
  File "/workspace/venv/lib/python3.13/site-packages/pyrogram/methods/advanced/resolve_peer.py", line 62, in resolve_peer
    return await self.storage.get_peer_by_id(peer_id)
           ^^^^^^^^^^^^^^^^^^^^^^^^^^^^^^^^^^^^^^^^^^
  File "/workspace/venv/lib/python3.13/site-packages/pyrogram/storage/sqlite_storage.py", line 142, in get_peer_by_id
    raise KeyError(f"ID not found: {peer_id}")
KeyError: 'ID not found: -1002430970946'

During handling of the above exception, another exception occurred:

Traceback (most recent call last):
  File "/workspace/venv/lib/python3.13/site-packages/pyrogram/client.py", line 569, in handle_updates
    channel=await self.resolve_peer(utils.get_channel_id(channel_id)),
            ^^^^^^^^^^^^^^^^^^^^^^^^^^^^^^^^^^^^^^^^^^^^^^^^^^^^^^^^^
  File "/workspace/venv/lib/python3.13/site-packages/pyrogram/methods/advanced/resolve_peer.py", line 89, in resolve_peer
    peer_type = utils.get_peer_type(peer_id)
  File "/workspace/venv/lib/python3.13/site-packages/pyrogram/utils.py", line 246, in get_peer_type
    raise ValueError(f"Peer id invalid: {peer_id}")
ValueError: Peer id invalid: -1002430970946
[16-Aug-25 03:12:19 - ERROR] - asyncio - Task exception was never retrieved
future: <Task finished name='Task-560' coro=<Client.handle_updates() done, defined at /workspace/venv/lib/python3.13/site-packages/pyrogram/client.py:535> exception=ValueError('Peer id invalid: -1002474305961')>
Traceback (most recent call last):
  File "/workspace/venv/lib/python3.13/site-packages/pyrogram/methods/advanced/resolve_peer.py", line 62, in resolve_peer
    return await self.storage.get_peer_by_id(peer_id)
           ^^^^^^^^^^^^^^^^^^^^^^^^^^^^^^^^^^^^^^^^^^
  File "/workspace/venv/lib/python3.13/site-packages/pyrogram/storage/sqlite_storage.py", line 142, in get_peer_by_id
    raise KeyError(f"ID not found: {peer_id}")
KeyError: 'ID not found: -1002474305961'

During handling of the above exception, another exception occurred:

Traceback (most recent call last):
  File "/workspace/venv/lib/python3.13/site-packages/pyrogram/client.py", line 569, in handle_updates
    channel=await self.resolve_peer(utils.get_channel_id(channel_id)),
            ^^^^^^^^^^^^^^^^^^^^^^^^^^^^^^^^^^^^^^^^^^^^^^^^^^^^^^^^^
  File "/workspace/venv/lib/python3.13/site-packages/pyrogram/methods/advanced/resolve_peer.py", line 89, in resolve_peer
    peer_type = utils.get_peer_type(peer_id)
  File "/workspace/venv/lib/python3.13/site-packages/pyrogram/utils.py", line 246, in get_peer_type
    raise ValueError(f"Peer id invalid: {peer_id}")
ValueError: Peer id invalid: -1002474305961
[16-Aug-25 03:12:19 - ERROR] - asyncio - Task exception was never retrieved
future: <Task finished name='Task-561' coro=<Client.handle_updates() done, defined at /workspace/venv/lib/python3.13/site-packages/pyrogram/client.py:535> exception=ValueError('Peer id invalid: -1002725376687')>
Traceback (most recent call last):
  File "/workspace/venv/lib/python3.13/site-packages/pyrogram/methods/advanced/resolve_peer.py", line 62, in resolve_peer
    return await self.storage.get_peer_by_id(peer_id)
           ^^^^^^^^^^^^^^^^^^^^^^^^^^^^^^^^^^^^^^^^^^
  File "/workspace/venv/lib/python3.13/site-packages/pyrogram/storage/sqlite_storage.py", line 142, in get_peer_by_id
    raise KeyError(f"ID not found: {peer_id}")
KeyError: 'ID not found: -1002725376687'

During handling of the above exception, another exception occurred:

Traceback (most recent call last):
  File "/workspace/venv/lib/python3.13/site-packages/pyrogram/client.py", line 569, in handle_updates
    channel=await self.resolve_peer(utils.get_channel_id(channel_id)),
            ^^^^^^^^^^^^^^^^^^^^^^^^^^^^^^^^^^^^^^^^^^^^^^^^^^^^^^^^^
  File "/workspace/venv/lib/python3.13/site-packages/pyrogram/methods/advanced/resolve_peer.py", line 89, in resolve_peer
    peer_type = utils.get_peer_type(peer_id)
  File "/workspace/venv/lib/python3.13/site-packages/pyrogram/utils.py", line 246, in get_peer_type
    raise ValueError(f"Peer id invalid: {peer_id}")
ValueError: Peer id invalid: -1002725376687
[16-Aug-25 03:12:19 - ERROR] - asyncio - Task exception was never retrieved
future: <Task finished name='Task-580' coro=<Client.handle_updates() done, defined at /workspace/venv/lib/python3.13/site-packages/pyrogram/client.py:535> exception=ValueError('Peer id invalid: -1002474305961')>
Traceback (most recent call last):
  File "/workspace/venv/lib/python3.13/site-packages/pyrogram/methods/advanced/resolve_peer.py", line 62, in resolve_peer
    return await self.storage.get_peer_by_id(peer_id)
           ^^^^^^^^^^^^^^^^^^^^^^^^^^^^^^^^^^^^^^^^^^
  File "/workspace/venv/lib/python3.13/site-packages/pyrogram/storage/sqlite_storage.py", line 142, in get_peer_by_id
    raise KeyError(f"ID not found: {peer_id}")
KeyError: 'ID not found: -1002474305961'

During handling of the above exception, another exception occurred:

Traceback (most recent call last):
  File "/workspace/venv/lib/python3.13/site-packages/pyrogram/client.py", line 569, in handle_updates
    channel=await self.resolve_peer(utils.get_channel_id(channel_id)),
            ^^^^^^^^^^^^^^^^^^^^^^^^^^^^^^^^^^^^^^^^^^^^^^^^^^^^^^^^^
  File "/workspace/venv/lib/python3.13/site-packages/pyrogram/methods/advanced/resolve_peer.py", line 89, in resolve_peer
    peer_type = utils.get_peer_type(peer_id)
  File "/workspace/venv/lib/python3.13/site-packages/pyrogram/utils.py", line 246, in get_peer_type
    raise ValueError(f"Peer id invalid: {peer_id}")
ValueError: Peer id invalid: -1002474305961
[16-Aug-25 03:12:26 - ERROR] - asyncio - Task exception was never retrieved
future: <Task finished name='Task-592' coro=<Client.handle_updates() done, defined at /workspace/venv/lib/python3.13/site-packages/pyrogram/client.py:535> exception=ValueError('Peer id invalid: -1002725376687')>
Traceback (most recent call last):
  File "/workspace/venv/lib/python3.13/site-packages/pyrogram/methods/advanced/resolve_peer.py", line 62, in resolve_peer
    return await self.storage.get_peer_by_id(peer_id)
           ^^^^^^^^^^^^^^^^^^^^^^^^^^^^^^^^^^^^^^^^^^
  File "/workspace/venv/lib/python3.13/site-packages/pyrogram/storage/sqlite_storage.py", line 142, in get_peer_by_id
    raise KeyError(f"ID not found: {peer_id}")
KeyError: 'ID not found: -1002725376687'

During handling of the above exception, another exception occurred:

Traceback (most recent call last):
  File "/workspace/venv/lib/python3.13/site-packages/pyrogram/client.py", line 569, in handle_updates
    channel=await self.resolve_peer(utils.get_channel_id(channel_id)),
            ^^^^^^^^^^^^^^^^^^^^^^^^^^^^^^^^^^^^^^^^^^^^^^^^^^^^^^^^^
  File "/workspace/venv/lib/python3.13/site-packages/pyrogram/methods/advanced/resolve_peer.py", line 89, in resolve_peer
    peer_type = utils.get_peer_type(peer_id)
  File "/workspace/venv/lib/python3.13/site-packages/pyrogram/utils.py", line 246, in get_peer_type
    raise ValueError(f"Peer id invalid: {peer_id}")
ValueError: Peer id invalid: -1002725376687
[16-Aug-25 03:12:31 - ERROR] - asyncio - Task exception was never retrieved
future: <Task finished name='Task-610' coro=<Client.handle_updates() done, defined at /workspace/venv/lib/python3.13/site-packages/pyrogram/client.py:535> exception=ValueError('Peer id invalid: -1002701086502')>
Traceback (most recent call last):
  File "/workspace/venv/lib/python3.13/site-packages/pyrogram/methods/advanced/resolve_peer.py", line 62, in resolve_peer
    return await self.storage.get_peer_by_id(peer_id)
           ^^^^^^^^^^^^^^^^^^^^^^^^^^^^^^^^^^^^^^^^^^
  File "/workspace/venv/lib/python3.13/site-packages/pyrogram/storage/sqlite_storage.py", line 142, in get_peer_by_id
    raise KeyError(f"ID not found: {peer_id}")
KeyError: 'ID not found: -1002701086502'

During handling of the above exception, another exception occurred:

Traceback (most recent call last):
  File "/workspace/venv/lib/python3.13/site-packages/pyrogram/client.py", line 569, in handle_updates
    channel=await self.resolve_peer(utils.get_channel_id(channel_id)),
            ^^^^^^^^^^^^^^^^^^^^^^^^^^^^^^^^^^^^^^^^^^^^^^^^^^^^^^^^^
  File "/workspace/venv/lib/python3.13/site-packages/pyrogram/methods/advanced/resolve_peer.py", line 89, in resolve_peer
    peer_type = utils.get_peer_type(peer_id)
  File "/workspace/venv/lib/python3.13/site-packages/pyrogram/utils.py", line 246, in get_peer_type
    raise ValueError(f"Peer id invalid: {peer_id}")
ValueError: Peer id invalid: -1002701086502
[16-Aug-25 03:12:31 - ERROR] - asyncio - Task exception was never retrieved
future: <Task finished name='Task-614' coro=<Client.handle_updates() done, defined at /workspace/venv/lib/python3.13/site-packages/pyrogram/client.py:535> exception=ValueError('Peer id invalid: -1002701086502')>
Traceback (most recent call last):
  File "/workspace/venv/lib/python3.13/site-packages/pyrogram/methods/advanced/resolve_peer.py", line 62, in resolve_peer
    return await self.storage.get_peer_by_id(peer_id)
           ^^^^^^^^^^^^^^^^^^^^^^^^^^^^^^^^^^^^^^^^^^
  File "/workspace/venv/lib/python3.13/site-packages/pyrogram/storage/sqlite_storage.py", line 142, in get_peer_by_id
    raise KeyError(f"ID not found: {peer_id}")
KeyError: 'ID not found: -1002701086502'

During handling of the above exception, another exception occurred:

Traceback (most recent call last):
  File "/workspace/venv/lib/python3.13/site-packages/pyrogram/client.py", line 569, in handle_updates
    channel=await self.resolve_peer(utils.get_channel_id(channel_id)),
            ^^^^^^^^^^^^^^^^^^^^^^^^^^^^^^^^^^^^^^^^^^^^^^^^^^^^^^^^^
  File "/workspace/venv/lib/python3.13/site-packages/pyrogram/methods/advanced/resolve_peer.py", line 89, in resolve_peer
    peer_type = utils.get_peer_type(peer_id)
  File "/workspace/venv/lib/python3.13/site-packages/pyrogram/utils.py", line 246, in get_peer_type
    raise ValueError(f"Peer id invalid: {peer_id}")
ValueError: Peer id invalid: -1002701086502
[16-Aug-25 03:12:32 - ERROR] - asyncio - Task exception was never retrieved
future: <Task finished name='Task-616' coro=<Client.handle_updates() done, defined at /workspace/venv/lib/python3.13/site-packages/pyrogram/client.py:535> exception=ValueError('Peer id invalid: -1002701086502')>
Traceback (most recent call last):
  File "/workspace/venv/lib/python3.13/site-packages/pyrogram/methods/advanced/resolve_peer.py", line 62, in resolve_peer
    return await self.storage.get_peer_by_id(peer_id)
           ^^^^^^^^^^^^^^^^^^^^^^^^^^^^^^^^^^^^^^^^^^
  File "/workspace/venv/lib/python3.13/site-packages/pyrogram/storage/sqlite_storage.py", line 142, in get_peer_by_id
    raise KeyError(f"ID not found: {peer_id}")
KeyError: 'ID not found: -1002701086502'

During handling of the above exception, another exception occurred:

Traceback (most recent call last):
  File "/workspace/venv/lib/python3.13/site-packages/pyrogram/client.py", line 569, in handle_updates
    channel=await self.resolve_peer(utils.get_channel_id(channel_id)),
            ^^^^^^^^^^^^^^^^^^^^^^^^^^^^^^^^^^^^^^^^^^^^^^^^^^^^^^^^^
  File "/workspace/venv/lib/python3.13/site-packages/pyrogram/methods/advanced/resolve_peer.py", line 89, in resolve_peer
    peer_type = utils.get_peer_type(peer_id)
  File "/workspace/venv/lib/python3.13/site-packages/pyrogram/utils.py", line 246, in get_peer_type
    raise ValueError(f"Peer id invalid: {peer_id}")
ValueError: Peer id invalid: -1002701086502
[16-Aug-25 03:12:34 - ERROR] - asyncio - Task exception was never retrieved
future: <Task finished name='Task-622' coro=<Client.handle_updates() done, defined at /workspace/venv/lib/python3.13/site-packages/pyrogram/client.py:535> exception=ValueError('Peer id invalid: -1002430970946')>
Traceback (most recent call last):
  File "/workspace/venv/lib/python3.13/site-packages/pyrogram/methods/advanced/resolve_peer.py", line 62, in resolve_peer
    return await self.storage.get_peer_by_id(peer_id)
           ^^^^^^^^^^^^^^^^^^^^^^^^^^^^^^^^^^^^^^^^^^
  File "/workspace/venv/lib/python3.13/site-packages/pyrogram/storage/sqlite_storage.py", line 142, in get_peer_by_id
    raise KeyError(f"ID not found: {peer_id}")
KeyError: 'ID not found: -1002430970946'

During handling of the above exception, another exception occurred:

Traceback (most recent call last):
  File "/workspace/venv/lib/python3.13/site-packages/pyrogram/client.py", line 569, in handle_updates
    channel=await self.resolve_peer(utils.get_channel_id(channel_id)),
            ^^^^^^^^^^^^^^^^^^^^^^^^^^^^^^^^^^^^^^^^^^^^^^^^^^^^^^^^^
  File "/workspace/venv/lib/python3.13/site-packages/pyrogram/methods/advanced/resolve_peer.py", line 89, in resolve_peer
    peer_type = utils.get_peer_type(peer_id)
  File "/workspace/venv/lib/python3.13/site-packages/pyrogram/utils.py", line 246, in get_peer_type
    raise ValueError(f"Peer id invalid: {peer_id}")
ValueError: Peer id invalid: -1002430970946
[16-Aug-25 03:12:34 - ERROR] - asyncio - Task exception was never retrieved
future: <Task finished name='Task-625' coro=<Client.handle_updates() done, defined at /workspace/venv/lib/python3.13/site-packages/pyrogram/client.py:535> exception=ValueError('Peer id invalid: -1002430970946')>
Traceback (most recent call last):
  File "/workspace/venv/lib/python3.13/site-packages/pyrogram/methods/advanced/resolve_peer.py", line 62, in resolve_peer
    return await self.storage.get_peer_by_id(peer_id)
           ^^^^^^^^^^^^^^^^^^^^^^^^^^^^^^^^^^^^^^^^^^
  File "/workspace/venv/lib/python3.13/site-packages/pyrogram/storage/sqlite_storage.py", line 142, in get_peer_by_id
    raise KeyError(f"ID not found: {peer_id}")
KeyError: 'ID not found: -1002430970946'

During handling of the above exception, another exception occurred:

Traceback (most recent call last):
  File "/workspace/venv/lib/python3.13/site-packages/pyrogram/client.py", line 569, in handle_updates
    channel=await self.resolve_peer(utils.get_channel_id(channel_id)),
            ^^^^^^^^^^^^^^^^^^^^^^^^^^^^^^^^^^^^^^^^^^^^^^^^^^^^^^^^^
  File "/workspace/venv/lib/python3.13/site-packages/pyrogram/methods/advanced/resolve_peer.py", line 89, in resolve_peer
    peer_type = utils.get_peer_type(peer_id)
  File "/workspace/venv/lib/python3.13/site-packages/pyrogram/utils.py", line 246, in get_peer_type
    raise ValueError(f"Peer id invalid: {peer_id}")
ValueError: Peer id invalid: -1002430970946
[16-Aug-25 03:12:36 - ERROR] - asyncio - Task exception was never retrieved
future: <Task finished name='Task-630' coro=<Client.handle_updates() done, defined at /workspace/venv/lib/python3.13/site-packages/pyrogram/client.py:535> exception=ValueError('Peer id invalid: -1002725376687')>
Traceback (most recent call last):
  File "/workspace/venv/lib/python3.13/site-packages/pyrogram/methods/advanced/resolve_peer.py", line 62, in resolve_peer
    return await self.storage.get_peer_by_id(peer_id)
           ^^^^^^^^^^^^^^^^^^^^^^^^^^^^^^^^^^^^^^^^^^
  File "/workspace/venv/lib/python3.13/site-packages/pyrogram/storage/sqlite_storage.py", line 142, in get_peer_by_id
    raise KeyError(f"ID not found: {peer_id}")
KeyError: 'ID not found: -1002725376687'

During handling of the above exception, another exception occurred:

Traceback (most recent call last):
  File "/workspace/venv/lib/python3.13/site-packages/pyrogram/client.py", line 569, in handle_updates
    channel=await self.resolve_peer(utils.get_channel_id(channel_id)),
            ^^^^^^^^^^^^^^^^^^^^^^^^^^^^^^^^^^^^^^^^^^^^^^^^^^^^^^^^^
  File "/workspace/venv/lib/python3.13/site-packages/pyrogram/methods/advanced/resolve_peer.py", line 89, in resolve_peer
    peer_type = utils.get_peer_type(peer_id)
  File "/workspace/venv/lib/python3.13/site-packages/pyrogram/utils.py", line 246, in get_peer_type
    raise ValueError(f"Peer id invalid: {peer_id}")
ValueError: Peer id invalid: -1002725376687
[16-Aug-25 03:12:39 - ERROR] - asyncio - Task exception was never retrieved
future: <Task finished name='Task-644' coro=<Client.handle_updates() done, defined at /workspace/venv/lib/python3.13/site-packages/pyrogram/client.py:535> exception=ValueError('Peer id invalid: -1002430970946')>
Traceback (most recent call last):
  File "/workspace/venv/lib/python3.13/site-packages/pyrogram/methods/advanced/resolve_peer.py", line 62, in resolve_peer
    return await self.storage.get_peer_by_id(peer_id)
           ^^^^^^^^^^^^^^^^^^^^^^^^^^^^^^^^^^^^^^^^^^
  File "/workspace/venv/lib/python3.13/site-packages/pyrogram/storage/sqlite_storage.py", line 142, in get_peer_by_id
    raise KeyError(f"ID not found: {peer_id}")
KeyError: 'ID not found: -1002430970946'

During handling of the above exception, another exception occurred:

Traceback (most recent call last):
  File "/workspace/venv/lib/python3.13/site-packages/pyrogram/client.py", line 569, in handle_updates
    channel=await self.resolve_peer(utils.get_channel_id(channel_id)),
            ^^^^^^^^^^^^^^^^^^^^^^^^^^^^^^^^^^^^^^^^^^^^^^^^^^^^^^^^^
  File "/workspace/venv/lib/python3.13/site-packages/pyrogram/methods/advanced/resolve_peer.py", line 89, in resolve_peer
    peer_type = utils.get_peer_type(peer_id)
  File "/workspace/venv/lib/python3.13/site-packages/pyrogram/utils.py", line 246, in get_peer_type
    raise ValueError(f"Peer id invalid: {peer_id}")
ValueError: Peer id invalid: -1002430970946
[16-Aug-25 03:12:42 - ERROR] - asyncio - Task exception was never retrieved
future: <Task finished name='Task-649' coro=<Client.handle_updates() done, defined at /workspace/venv/lib/python3.13/site-packages/pyrogram/client.py:535> exception=ValueError('Peer id invalid: -1002524216878')>
Traceback (most recent call last):
  File "/workspace/venv/lib/python3.13/site-packages/pyrogram/methods/advanced/resolve_peer.py", line 62, in resolve_peer
    return await self.storage.get_peer_by_id(peer_id)
           ^^^^^^^^^^^^^^^^^^^^^^^^^^^^^^^^^^^^^^^^^^
  File "/workspace/venv/lib/python3.13/site-packages/pyrogram/storage/sqlite_storage.py", line 142, in get_peer_by_id
    raise KeyError(f"ID not found: {peer_id}")
KeyError: 'ID not found: -1002524216878'

During handling of the above exception, another exception occurred:

Traceback (most recent call last):
  File "/workspace/venv/lib/python3.13/site-packages/pyrogram/client.py", line 569, in handle_updates
    channel=await self.resolve_peer(utils.get_channel_id(channel_id)),
            ^^^^^^^^^^^^^^^^^^^^^^^^^^^^^^^^^^^^^^^^^^^^^^^^^^^^^^^^^
  File "/workspace/venv/lib/python3.13/site-packages/pyrogram/methods/advanced/resolve_peer.py", line 89, in resolve_peer
    peer_type = utils.get_peer_type(peer_id)
  File "/workspace/venv/lib/python3.13/site-packages/pyrogram/utils.py", line 246, in get_peer_type
    raise ValueError(f"Peer id invalid: {peer_id}")
ValueError: Peer id invalid: -1002524216878
[16-Aug-25 03:12:42 - ERROR] - asyncio - Task exception was never retrieved
future: <Task finished name='Task-651' coro=<Client.handle_updates() done, defined at /workspace/venv/lib/python3.13/site-packages/pyrogram/client.py:535> exception=ValueError('Peer id invalid: -1002524216878')>
Traceback (most recent call last):
  File "/workspace/venv/lib/python3.13/site-packages/pyrogram/methods/advanced/resolve_peer.py", line 62, in resolve_peer
    return await self.storage.get_peer_by_id(peer_id)
           ^^^^^^^^^^^^^^^^^^^^^^^^^^^^^^^^^^^^^^^^^^
  File "/workspace/venv/lib/python3.13/site-packages/pyrogram/storage/sqlite_storage.py", line 142, in get_peer_by_id
    raise KeyError(f"ID not found: {peer_id}")
KeyError: 'ID not found: -1002524216878'

During handling of the above exception, another exception occurred:

Traceback (most recent call last):
  File "/workspace/venv/lib/python3.13/site-packages/pyrogram/client.py", line 569, in handle_updates
    channel=await self.resolve_peer(utils.get_channel_id(channel_id)),
            ^^^^^^^^^^^^^^^^^^^^^^^^^^^^^^^^^^^^^^^^^^^^^^^^^^^^^^^^^
  File "/workspace/venv/lib/python3.13/site-packages/pyrogram/methods/advanced/resolve_peer.py", line 89, in resolve_peer
    peer_type = utils.get_peer_type(peer_id)
  File "/workspace/venv/lib/python3.13/site-packages/pyrogram/utils.py", line 246, in get_peer_type
    raise ValueError(f"Peer id invalid: {peer_id}")
ValueError: Peer id invalid: -1002524216878
[16-Aug-25 03:12:43 - ERROR] - asyncio - Task exception was never retrieved
future: <Task finished name='Task-655' coro=<Client.handle_updates() done, defined at /workspace/venv/lib/python3.13/site-packages/pyrogram/client.py:535> exception=ValueError('Peer id invalid: -1002524216878')>
Traceback (most recent call last):
  File "/workspace/venv/lib/python3.13/site-packages/pyrogram/methods/advanced/resolve_peer.py", line 62, in resolve_peer
    return await self.storage.get_peer_by_id(peer_id)
           ^^^^^^^^^^^^^^^^^^^^^^^^^^^^^^^^^^^^^^^^^^
  File "/workspace/venv/lib/python3.13/site-packages/pyrogram/storage/sqlite_storage.py", line 142, in get_peer_by_id
    raise KeyError(f"ID not found: {peer_id}")
KeyError: 'ID not found: -1002524216878'

During handling of the above exception, another exception occurred:

Traceback (most recent call last):
  File "/workspace/venv/lib/python3.13/site-packages/pyrogram/client.py", line 569, in handle_updates
    channel=await self.resolve_peer(utils.get_channel_id(channel_id)),
            ^^^^^^^^^^^^^^^^^^^^^^^^^^^^^^^^^^^^^^^^^^^^^^^^^^^^^^^^^
  File "/workspace/venv/lib/python3.13/site-packages/pyrogram/methods/advanced/resolve_peer.py", line 89, in resolve_peer
    peer_type = utils.get_peer_type(peer_id)
  File "/workspace/venv/lib/python3.13/site-packages/pyrogram/utils.py", line 246, in get_peer_type
    raise ValueError(f"Peer id invalid: {peer_id}")
ValueError: Peer id invalid: -1002524216878
[16-Aug-25 03:12:44 - ERROR] - asyncio - Task exception was never retrieved
future: <Task finished name='Task-659' coro=<Client.handle_updates() done, defined at /workspace/venv/lib/python3.13/site-packages/pyrogram/client.py:535> exception=ValueError('Peer id invalid: -1002701086502')>
Traceback (most recent call last):
  File "/workspace/venv/lib/python3.13/site-packages/pyrogram/methods/advanced/resolve_peer.py", line 62, in resolve_peer
    return await self.storage.get_peer_by_id(peer_id)
           ^^^^^^^^^^^^^^^^^^^^^^^^^^^^^^^^^^^^^^^^^^
  File "/workspace/venv/lib/python3.13/site-packages/pyrogram/storage/sqlite_storage.py", line 142, in get_peer_by_id
    raise KeyError(f"ID not found: {peer_id}")
KeyError: 'ID not found: -1002701086502'

During handling of the above exception, another exception occurred:

Traceback (most recent call last):
  File "/workspace/venv/lib/python3.13/site-packages/pyrogram/client.py", line 569, in handle_updates
    channel=await self.resolve_peer(utils.get_channel_id(channel_id)),
            ^^^^^^^^^^^^^^^^^^^^^^^^^^^^^^^^^^^^^^^^^^^^^^^^^^^^^^^^^
  File "/workspace/venv/lib/python3.13/site-packages/pyrogram/methods/advanced/resolve_peer.py", line 89, in resolve_peer
    peer_type = utils.get_peer_type(peer_id)
  File "/workspace/venv/lib/python3.13/site-packages/pyrogram/utils.py", line 246, in get_peer_type
    raise ValueError(f"Peer id invalid: {peer_id}")
ValueError: Peer id invalid: -1002701086502
[16-Aug-25 03:12:44 - ERROR] - asyncio - Task exception was never retrieved
future: <Task finished name='Task-662' coro=<Client.handle_updates() done, defined at /workspace/venv/lib/python3.13/site-packages/pyrogram/client.py:535> exception=ValueError('Peer id invalid: -1002701086502')>
Traceback (most recent call last):
  File "/workspace/venv/lib/python3.13/site-packages/pyrogram/methods/advanced/resolve_peer.py", line 62, in resolve_peer
    return await self.storage.get_peer_by_id(peer_id)
           ^^^^^^^^^^^^^^^^^^^^^^^^^^^^^^^^^^^^^^^^^^
  File "/workspace/venv/lib/python3.13/site-packages/pyrogram/storage/sqlite_storage.py", line 142, in get_peer_by_id
    raise KeyError(f"ID not found: {peer_id}")
KeyError: 'ID not found: -1002701086502'

During handling of the above exception, another exception occurred:

Traceback (most recent call last):
  File "/workspace/venv/lib/python3.13/site-packages/pyrogram/client.py", line 569, in handle_updates
    channel=await self.resolve_peer(utils.get_channel_id(channel_id)),
            ^^^^^^^^^^^^^^^^^^^^^^^^^^^^^^^^^^^^^^^^^^^^^^^^^^^^^^^^^
  File "/workspace/venv/lib/python3.13/site-packages/pyrogram/methods/advanced/resolve_peer.py", line 89, in resolve_peer
    peer_type = utils.get_peer_type(peer_id)
  File "/workspace/venv/lib/python3.13/site-packages/pyrogram/utils.py", line 246, in get_peer_type
    raise ValueError(f"Peer id invalid: {peer_id}")
ValueError: Peer id invalid: -1002701086502
[16-Aug-25 03:12:49 - ERROR] - pyrogram.dispatcher - Peer id invalid: -1002701086502
Traceback (most recent call last):
  File "/workspace/venv/lib/python3.13/site-packages/pyrogram/methods/advanced/resolve_peer.py", line 62, in resolve_peer
    return await self.storage.get_peer_by_id(peer_id)
           ^^^^^^^^^^^^^^^^^^^^^^^^^^^^^^^^^^^^^^^^^^
  File "/workspace/venv/lib/python3.13/site-packages/pyrogram/storage/sqlite_storage.py", line 142, in get_peer_by_id
    raise KeyError(f"ID not found: {peer_id}")
KeyError: 'ID not found: -1002701086502'

During handling of the above exception, another exception occurred:

Traceback (most recent call last):
  File "/workspace/venv/lib/python3.13/site-packages/pyrogram/dispatcher.py", line 214, in handler_worker
    await parser(update, users, chats)
  File "/workspace/venv/lib/python3.13/site-packages/pyrogram/dispatcher.py", line 75, in edited_message_parser
    parsed, _ = await message_parser(update, users, chats)
                ^^^^^^^^^^^^^^^^^^^^^^^^^^^^^^^^^^^^^^^^^^
  File "/workspace/venv/lib/python3.13/site-packages/pyrogram/dispatcher.py", line 68, in message_parser
    await pyrogram.types.Message._parse(self.client, update.message, users, chats,
    ^^^^^^^^^^^^^^^^^^^^^^^^^^^^^^^^^^^^^^^^^^^^^^^^^^^^^^^^^^^^^^^^^^^^^^^^^^^^^^
                                        isinstance(update, UpdateNewScheduledMessage)),
                                        ^^^^^^^^^^^^^^^^^^^^^^^^^^^^^^^^^^^^^^^^^^^^^^
  File "/workspace/venv/lib/python3.13/site-packages/pyrogram/types/messages_and_media/message.py", line 836, in _parse
    reply_to_message = await client.get_messages(
                       ^^^^^^^^^^^^^^^^^^^^^^^^^^
    ...<3 lines>...
    )
    ^
  File "/workspace/venv/lib/python3.13/site-packages/pyrogram/methods/messages/get_messages.py", line 101, in get_messages
    peer = await self.resolve_peer(chat_id)
           ^^^^^^^^^^^^^^^^^^^^^^^^^^^^^^^^
  File "/workspace/venv/lib/python3.13/site-packages/pyrogram/methods/advanced/resolve_peer.py", line 89, in resolve_peer
    peer_type = utils.get_peer_type(peer_id)
  File "/workspace/venv/lib/python3.13/site-packages/pyrogram/utils.py", line 246, in get_peer_type
    raise ValueError(f"Peer id invalid: {peer_id}")
ValueError: Peer id invalid: -1002701086502
[16-Aug-25 03:12:52 - ERROR] - pyrogram.dispatcher - Peer id invalid: -1002701086502
Traceback (most recent call last):
  File "/workspace/venv/lib/python3.13/site-packages/pyrogram/methods/advanced/resolve_peer.py", line 62, in resolve_peer
    return await self.storage.get_peer_by_id(peer_id)
           ^^^^^^^^^^^^^^^^^^^^^^^^^^^^^^^^^^^^^^^^^^
  File "/workspace/venv/lib/python3.13/site-packages/pyrogram/storage/sqlite_storage.py", line 142, in get_peer_by_id
    raise KeyError(f"ID not found: {peer_id}")
KeyError: 'ID not found: -1002701086502'

During handling of the above exception, another exception occurred:

Traceback (most recent call last):
  File "/workspace/venv/lib/python3.13/site-packages/pyrogram/dispatcher.py", line 214, in handler_worker
    await parser(update, users, chats)
  File "/workspace/venv/lib/python3.13/site-packages/pyrogram/dispatcher.py", line 75, in edited_message_parser
    parsed, _ = await message_parser(update, users, chats)
                ^^^^^^^^^^^^^^^^^^^^^^^^^^^^^^^^^^^^^^^^^^
  File "/workspace/venv/lib/python3.13/site-packages/pyrogram/dispatcher.py", line 68, in message_parser
    await pyrogram.types.Message._parse(self.client, update.message, users, chats,
    ^^^^^^^^^^^^^^^^^^^^^^^^^^^^^^^^^^^^^^^^^^^^^^^^^^^^^^^^^^^^^^^^^^^^^^^^^^^^^^
                                        isinstance(update, UpdateNewScheduledMessage)),
                                        ^^^^^^^^^^^^^^^^^^^^^^^^^^^^^^^^^^^^^^^^^^^^^^
  File "/workspace/venv/lib/python3.13/site-packages/pyrogram/types/messages_and_media/message.py", line 836, in _parse
    reply_to_message = await client.get_messages(
                       ^^^^^^^^^^^^^^^^^^^^^^^^^^
    ...<3 lines>...
    )
    ^
  File "/workspace/venv/lib/python3.13/site-packages/pyrogram/methods/messages/get_messages.py", line 101, in get_messages
    peer = await self.resolve_peer(chat_id)
           ^^^^^^^^^^^^^^^^^^^^^^^^^^^^^^^^
  File "/workspace/venv/lib/python3.13/site-packages/pyrogram/methods/advanced/resolve_peer.py", line 89, in resolve_peer
    peer_type = utils.get_peer_type(peer_id)
  File "/workspace/venv/lib/python3.13/site-packages/pyrogram/utils.py", line 246, in get_peer_type
    raise ValueError(f"Peer id invalid: {peer_id}")
ValueError: Peer id invalid: -1002701086502
[16-Aug-25 03:12:59 - ERROR] - pyrogram.dispatcher - Peer id invalid: -1002701086502
Traceback (most recent call last):
  File "/workspace/venv/lib/python3.13/site-packages/pyrogram/methods/advanced/resolve_peer.py", line 62, in resolve_peer
    return await self.storage.get_peer_by_id(peer_id)
           ^^^^^^^^^^^^^^^^^^^^^^^^^^^^^^^^^^^^^^^^^^
  File "/workspace/venv/lib/python3.13/site-packages/pyrogram/storage/sqlite_storage.py", line 142, in get_peer_by_id
    raise KeyError(f"ID not found: {peer_id}")
KeyError: 'ID not found: -1002701086502'

During handling of the above exception, another exception occurred:

Traceback (most recent call last):
  File "/workspace/venv/lib/python3.13/site-packages/pyrogram/dispatcher.py", line 214, in handler_worker
    await parser(update, users, chats)
  File "/workspace/venv/lib/python3.13/site-packages/pyrogram/dispatcher.py", line 75, in edited_message_parser
    parsed, _ = await message_parser(update, users, chats)
                ^^^^^^^^^^^^^^^^^^^^^^^^^^^^^^^^^^^^^^^^^^
  File "/workspace/venv/lib/python3.13/site-packages/pyrogram/dispatcher.py", line 68, in message_parser
    await pyrogram.types.Message._parse(self.client, update.message, users, chats,
    ^^^^^^^^^^^^^^^^^^^^^^^^^^^^^^^^^^^^^^^^^^^^^^^^^^^^^^^^^^^^^^^^^^^^^^^^^^^^^^
                                        isinstance(update, UpdateNewScheduledMessage)),
                                        ^^^^^^^^^^^^^^^^^^^^^^^^^^^^^^^^^^^^^^^^^^^^^^
  File "/workspace/venv/lib/python3.13/site-packages/pyrogram/types/messages_and_media/message.py", line 836, in _parse
    reply_to_message = await client.get_messages(
                       ^^^^^^^^^^^^^^^^^^^^^^^^^^
    ...<3 lines>...
    )
    ^
  File "/workspace/venv/lib/python3.13/site-packages/pyrogram/methods/messages/get_messages.py", line 101, in get_messages
    peer = await self.resolve_peer(chat_id)
           ^^^^^^^^^^^^^^^^^^^^^^^^^^^^^^^^
  File "/workspace/venv/lib/python3.13/site-packages/pyrogram/methods/advanced/resolve_peer.py", line 89, in resolve_peer
    peer_type = utils.get_peer_type(peer_id)
  File "/workspace/venv/lib/python3.13/site-packages/pyrogram/utils.py", line 246, in get_peer_type
    raise ValueError(f"Peer id invalid: {peer_id}")
ValueError: Peer id invalid: -1002701086502
[16-Aug-25 03:13:00 - ERROR] - asyncio - Task exception was never retrieved
future: <Task finished name='Task-691' coro=<Client.handle_updates() done, defined at /workspace/venv/lib/python3.13/site-packages/pyrogram/client.py:535> exception=ValueError('Peer id invalid: -1002701086502')>
Traceback (most recent call last):
  File "/workspace/venv/lib/python3.13/site-packages/pyrogram/methods/advanced/resolve_peer.py", line 62, in resolve_peer
    return await self.storage.get_peer_by_id(peer_id)
           ^^^^^^^^^^^^^^^^^^^^^^^^^^^^^^^^^^^^^^^^^^
  File "/workspace/venv/lib/python3.13/site-packages/pyrogram/storage/sqlite_storage.py", line 142, in get_peer_by_id
    raise KeyError(f"ID not found: {peer_id}")
KeyError: 'ID not found: -1002701086502'

During handling of the above exception, another exception occurred:

Traceback (most recent call last):
  File "/workspace/venv/lib/python3.13/site-packages/pyrogram/client.py", line 569, in handle_updates
    channel=await self.resolve_peer(utils.get_channel_id(channel_id)),
            ^^^^^^^^^^^^^^^^^^^^^^^^^^^^^^^^^^^^^^^^^^^^^^^^^^^^^^^^^
  File "/workspace/venv/lib/python3.13/site-packages/pyrogram/methods/advanced/resolve_peer.py", line 89, in resolve_peer
    peer_type = utils.get_peer_type(peer_id)
  File "/workspace/venv/lib/python3.13/site-packages/pyrogram/utils.py", line 246, in get_peer_type
    raise ValueError(f"Peer id invalid: {peer_id}")
ValueError: Peer id invalid: -1002701086502
[16-Aug-25 03:13:04 - ERROR] - asyncio - Task exception was never retrieved
future: <Task finished name='Task-706' coro=<Client.handle_updates() done, defined at /workspace/venv/lib/python3.13/site-packages/pyrogram/client.py:535> exception=ValueError('Peer id invalid: -1002725376687')>
Traceback (most recent call last):
  File "/workspace/venv/lib/python3.13/site-packages/pyrogram/methods/advanced/resolve_peer.py", line 62, in resolve_peer
    return await self.storage.get_peer_by_id(peer_id)
           ^^^^^^^^^^^^^^^^^^^^^^^^^^^^^^^^^^^^^^^^^^
  File "/workspace/venv/lib/python3.13/site-packages/pyrogram/storage/sqlite_storage.py", line 142, in get_peer_by_id
    raise KeyError(f"ID not found: {peer_id}")
KeyError: 'ID not found: -1002725376687'

During handling of the above exception, another exception occurred:

Traceback (most recent call last):
  File "/workspace/venv/lib/python3.13/site-packages/pyrogram/client.py", line 569, in handle_updates
    channel=await self.resolve_peer(utils.get_channel_id(channel_id)),
            ^^^^^^^^^^^^^^^^^^^^^^^^^^^^^^^^^^^^^^^^^^^^^^^^^^^^^^^^^
  File "/workspace/venv/lib/python3.13/site-packages/pyrogram/methods/advanced/resolve_peer.py", line 89, in resolve_peer
    peer_type = utils.get_peer_type(peer_id)
  File "/workspace/venv/lib/python3.13/site-packages/pyrogram/utils.py", line 246, in get_peer_type
    raise ValueError(f"Peer id invalid: {peer_id}")
ValueError: Peer id invalid: -1002725376687
[16-Aug-25 03:13:13 - ERROR] - asyncio - Task exception was never retrieved
future: <Task finished name='Task-720' coro=<Client.handle_updates() done, defined at /workspace/venv/lib/python3.13/site-packages/pyrogram/client.py:535> exception=ValueError('Peer id invalid: -1002475315714')>
Traceback (most recent call last):
  File "/workspace/venv/lib/python3.13/site-packages/pyrogram/methods/advanced/resolve_peer.py", line 62, in resolve_peer
    return await self.storage.get_peer_by_id(peer_id)
           ^^^^^^^^^^^^^^^^^^^^^^^^^^^^^^^^^^^^^^^^^^
  File "/workspace/venv/lib/python3.13/site-packages/pyrogram/storage/sqlite_storage.py", line 142, in get_peer_by_id
    raise KeyError(f"ID not found: {peer_id}")
KeyError: 'ID not found: -1002475315714'

During handling of the above exception, another exception occurred:

Traceback (most recent call last):
  File "/workspace/venv/lib/python3.13/site-packages/pyrogram/client.py", line 569, in handle_updates
    channel=await self.resolve_peer(utils.get_channel_id(channel_id)),
            ^^^^^^^^^^^^^^^^^^^^^^^^^^^^^^^^^^^^^^^^^^^^^^^^^^^^^^^^^
  File "/workspace/venv/lib/python3.13/site-packages/pyrogram/methods/advanced/resolve_peer.py", line 89, in resolve_peer
    peer_type = utils.get_peer_type(peer_id)
  File "/workspace/venv/lib/python3.13/site-packages/pyrogram/utils.py", line 246, in get_peer_type
    raise ValueError(f"Peer id invalid: {peer_id}")
ValueError: Peer id invalid: -1002475315714
[16-Aug-25 03:13:41 - ERROR] - asyncio - Task exception was never retrieved
future: <Task finished name='Task-762' coro=<Client.handle_updates() done, defined at /workspace/venv/lib/python3.13/site-packages/pyrogram/client.py:535> exception=ValueError('Peer id invalid: -1002725376687')>
Traceback (most recent call last):
  File "/workspace/venv/lib/python3.13/site-packages/pyrogram/methods/advanced/resolve_peer.py", line 62, in resolve_peer
    return await self.storage.get_peer_by_id(peer_id)
           ^^^^^^^^^^^^^^^^^^^^^^^^^^^^^^^^^^^^^^^^^^
  File "/workspace/venv/lib/python3.13/site-packages/pyrogram/storage/sqlite_storage.py", line 142, in get_peer_by_id
    raise KeyError(f"ID not found: {peer_id}")
KeyError: 'ID not found: -1002725376687'

During handling of the above exception, another exception occurred:

Traceback (most recent call last):
  File "/workspace/venv/lib/python3.13/site-packages/pyrogram/client.py", line 569, in handle_updates
    channel=await self.resolve_peer(utils.get_channel_id(channel_id)),
            ^^^^^^^^^^^^^^^^^^^^^^^^^^^^^^^^^^^^^^^^^^^^^^^^^^^^^^^^^
  File "/workspace/venv/lib/python3.13/site-packages/pyrogram/methods/advanced/resolve_peer.py", line 89, in resolve_peer
    peer_type = utils.get_peer_type(peer_id)
  File "/workspace/venv/lib/python3.13/site-packages/pyrogram/utils.py", line 246, in get_peer_type
    raise ValueError(f"Peer id invalid: {peer_id}")
ValueError: Peer id invalid: -1002725376687
[16-Aug-25 03:13:41 - ERROR] - asyncio - Task exception was never retrieved
future: <Task finished name='Task-764' coro=<Client.handle_updates() done, defined at /workspace/venv/lib/python3.13/site-packages/pyrogram/client.py:535> exception=ValueError('Peer id invalid: -1002725376687')>
Traceback (most recent call last):
  File "/workspace/venv/lib/python3.13/site-packages/pyrogram/methods/advanced/resolve_peer.py", line 62, in resolve_peer
    return await self.storage.get_peer_by_id(peer_id)
           ^^^^^^^^^^^^^^^^^^^^^^^^^^^^^^^^^^^^^^^^^^
  File "/workspace/venv/lib/python3.13/site-packages/pyrogram/storage/sqlite_storage.py", line 142, in get_peer_by_id
    raise KeyError(f"ID not found: {peer_id}")
KeyError: 'ID not found: -1002725376687'

During handling of the above exception, another exception occurred:

Traceback (most recent call last):
  File "/workspace/venv/lib/python3.13/site-packages/pyrogram/client.py", line 569, in handle_updates
    channel=await self.resolve_peer(utils.get_channel_id(channel_id)),
            ^^^^^^^^^^^^^^^^^^^^^^^^^^^^^^^^^^^^^^^^^^^^^^^^^^^^^^^^^
  File "/workspace/venv/lib/python3.13/site-packages/pyrogram/methods/advanced/resolve_peer.py", line 89, in resolve_peer
    peer_type = utils.get_peer_type(peer_id)
  File "/workspace/venv/lib/python3.13/site-packages/pyrogram/utils.py", line 246, in get_peer_type
    raise ValueError(f"Peer id invalid: {peer_id}")
ValueError: Peer id invalid: -1002725376687
[16-Aug-25 03:13:41 - ERROR] - asyncio - Task exception was never retrieved
future: <Task finished name='Task-766' coro=<Client.handle_updates() done, defined at /workspace/venv/lib/python3.13/site-packages/pyrogram/client.py:535> exception=ValueError('Peer id invalid: -1002725376687')>
Traceback (most recent call last):
  File "/workspace/venv/lib/python3.13/site-packages/pyrogram/methods/advanced/resolve_peer.py", line 62, in resolve_peer
    return await self.storage.get_peer_by_id(peer_id)
           ^^^^^^^^^^^^^^^^^^^^^^^^^^^^^^^^^^^^^^^^^^
  File "/workspace/venv/lib/python3.13/site-packages/pyrogram/storage/sqlite_storage.py", line 142, in get_peer_by_id
    raise KeyError(f"ID not found: {peer_id}")
KeyError: 'ID not found: -1002725376687'

During handling of the above exception, another exception occurred:

Traceback (most recent call last):
  File "/workspace/venv/lib/python3.13/site-packages/pyrogram/client.py", line 569, in handle_updates
    channel=await self.resolve_peer(utils.get_channel_id(channel_id)),
            ^^^^^^^^^^^^^^^^^^^^^^^^^^^^^^^^^^^^^^^^^^^^^^^^^^^^^^^^^
  File "/workspace/venv/lib/python3.13/site-packages/pyrogram/methods/advanced/resolve_peer.py", line 89, in resolve_peer
    peer_type = utils.get_peer_type(peer_id)
  File "/workspace/venv/lib/python3.13/site-packages/pyrogram/utils.py", line 246, in get_peer_type
    raise ValueError(f"Peer id invalid: {peer_id}")
ValueError: Peer id invalid: -1002725376687
[16-Aug-25 03:13:47 - ERROR] - asyncio - Task exception was never retrieved
future: <Task finished name='Task-778' coro=<Client.handle_updates() done, defined at /workspace/venv/lib/python3.13/site-packages/pyrogram/client.py:535> exception=ValueError('Peer id invalid: -1002725376687')>
Traceback (most recent call last):
  File "/workspace/venv/lib/python3.13/site-packages/pyrogram/methods/advanced/resolve_peer.py", line 62, in resolve_peer
    return await self.storage.get_peer_by_id(peer_id)
           ^^^^^^^^^^^^^^^^^^^^^^^^^^^^^^^^^^^^^^^^^^
  File "/workspace/venv/lib/python3.13/site-packages/pyrogram/storage/sqlite_storage.py", line 142, in get_peer_by_id
    raise KeyError(f"ID not found: {peer_id}")
KeyError: 'ID not found: -1002725376687'

During handling of the above exception, another exception occurred:

Traceback (most recent call last):
  File "/workspace/venv/lib/python3.13/site-packages/pyrogram/client.py", line 569, in handle_updates
    channel=await self.resolve_peer(utils.get_channel_id(channel_id)),
            ^^^^^^^^^^^^^^^^^^^^^^^^^^^^^^^^^^^^^^^^^^^^^^^^^^^^^^^^^
  File "/workspace/venv/lib/python3.13/site-packages/pyrogram/methods/advanced/resolve_peer.py", line 89, in resolve_peer
    peer_type = utils.get_peer_type(peer_id)
  File "/workspace/venv/lib/python3.13/site-packages/pyrogram/utils.py", line 246, in get_peer_type
    raise ValueError(f"Peer id invalid: {peer_id}")
ValueError: Peer id invalid: -1002725376687
[16-Aug-25 03:13:48 - ERROR] - asyncio - Task exception was never retrieved
future: <Task finished name='Task-782' coro=<Client.handle_updates() done, defined at /workspace/venv/lib/python3.13/site-packages/pyrogram/client.py:535> exception=ValueError('Peer id invalid: -1002725376687')>
Traceback (most recent call last):
  File "/workspace/venv/lib/python3.13/site-packages/pyrogram/methods/advanced/resolve_peer.py", line 62, in resolve_peer
    return await self.storage.get_peer_by_id(peer_id)
           ^^^^^^^^^^^^^^^^^^^^^^^^^^^^^^^^^^^^^^^^^^
  File "/workspace/venv/lib/python3.13/site-packages/pyrogram/storage/sqlite_storage.py", line 142, in get_peer_by_id
    raise KeyError(f"ID not found: {peer_id}")
KeyError: 'ID not found: -1002725376687'

During handling of the above exception, another exception occurred:

Traceback (most recent call last):
  File "/workspace/venv/lib/python3.13/site-packages/pyrogram/client.py", line 569, in handle_updates
    channel=await self.resolve_peer(utils.get_channel_id(channel_id)),
            ^^^^^^^^^^^^^^^^^^^^^^^^^^^^^^^^^^^^^^^^^^^^^^^^^^^^^^^^^
  File "/workspace/venv/lib/python3.13/site-packages/pyrogram/methods/advanced/resolve_peer.py", line 89, in resolve_peer
    peer_type = utils.get_peer_type(peer_id)
  File "/workspace/venv/lib/python3.13/site-packages/pyrogram/utils.py", line 246, in get_peer_type
    raise ValueError(f"Peer id invalid: {peer_id}")
ValueError: Peer id invalid: -1002725376687
[16-Aug-25 03:13:55 - ERROR] - asyncio - Task exception was never retrieved
future: <Task finished name='Task-796' coro=<Client.handle_updates() done, defined at /workspace/venv/lib/python3.13/site-packages/pyrogram/client.py:535> exception=ValueError('Peer id invalid: -1002725376687')>
Traceback (most recent call last):
  File "/workspace/venv/lib/python3.13/site-packages/pyrogram/methods/advanced/resolve_peer.py", line 62, in resolve_peer
    return await self.storage.get_peer_by_id(peer_id)
           ^^^^^^^^^^^^^^^^^^^^^^^^^^^^^^^^^^^^^^^^^^
  File "/workspace/venv/lib/python3.13/site-packages/pyrogram/storage/sqlite_storage.py", line 142, in get_peer_by_id
    raise KeyError(f"ID not found: {peer_id}")
KeyError: 'ID not found: -1002725376687'

During handling of the above exception, another exception occurred:

Traceback (most recent call last):
  File "/workspace/venv/lib/python3.13/site-packages/pyrogram/client.py", line 569, in handle_updates
    channel=await self.resolve_peer(utils.get_channel_id(channel_id)),
            ^^^^^^^^^^^^^^^^^^^^^^^^^^^^^^^^^^^^^^^^^^^^^^^^^^^^^^^^^
  File "/workspace/venv/lib/python3.13/site-packages/pyrogram/methods/advanced/resolve_peer.py", line 89, in resolve_peer
    peer_type = utils.get_peer_type(peer_id)
  File "/workspace/venv/lib/python3.13/site-packages/pyrogram/utils.py", line 246, in get_peer_type
    raise ValueError(f"Peer id invalid: {peer_id}")
ValueError: Peer id invalid: -1002725376687
[16-Aug-25 03:13:55 - ERROR] - asyncio - Task exception was never retrieved
future: <Task finished name='Task-798' coro=<Client.handle_updates() done, defined at /workspace/venv/lib/python3.13/site-packages/pyrogram/client.py:535> exception=ValueError('Peer id invalid: -1002725376687')>
Traceback (most recent call last):
  File "/workspace/venv/lib/python3.13/site-packages/pyrogram/methods/advanced/resolve_peer.py", line 62, in resolve_peer
    return await self.storage.get_peer_by_id(peer_id)
           ^^^^^^^^^^^^^^^^^^^^^^^^^^^^^^^^^^^^^^^^^^
  File "/workspace/venv/lib/python3.13/site-packages/pyrogram/storage/sqlite_storage.py", line 142, in get_peer_by_id
    raise KeyError(f"ID not found: {peer_id}")
KeyError: 'ID not found: -1002725376687'

During handling of the above exception, another exception occurred:

Traceback (most recent call last):
  File "/workspace/venv/lib/python3.13/site-packages/pyrogram/client.py", line 569, in handle_updates
    channel=await self.resolve_peer(utils.get_channel_id(channel_id)),
            ^^^^^^^^^^^^^^^^^^^^^^^^^^^^^^^^^^^^^^^^^^^^^^^^^^^^^^^^^
  File "/workspace/venv/lib/python3.13/site-packages/pyrogram/methods/advanced/resolve_peer.py", line 89, in resolve_peer
    peer_type = utils.get_peer_type(peer_id)
  File "/workspace/venv/lib/python3.13/site-packages/pyrogram/utils.py", line 246, in get_peer_type
    raise ValueError(f"Peer id invalid: {peer_id}")
ValueError: Peer id invalid: -1002725376687
[16-Aug-25 03:13:57 - ERROR] - asyncio - Task exception was never retrieved
future: <Task finished name='Task-800' coro=<Client.handle_updates() done, defined at /workspace/venv/lib/python3.13/site-packages/pyrogram/client.py:535> exception=ValueError('Peer id invalid: -1002725376687')>
Traceback (most recent call last):
  File "/workspace/venv/lib/python3.13/site-packages/pyrogram/methods/advanced/resolve_peer.py", line 62, in resolve_peer
    return await self.storage.get_peer_by_id(peer_id)
           ^^^^^^^^^^^^^^^^^^^^^^^^^^^^^^^^^^^^^^^^^^
  File "/workspace/venv/lib/python3.13/site-packages/pyrogram/storage/sqlite_storage.py", line 142, in get_peer_by_id
    raise KeyError(f"ID not found: {peer_id}")
KeyError: 'ID not found: -1002725376687'

During handling of the above exception, another exception occurred:

Traceback (most recent call last):
  File "/workspace/venv/lib/python3.13/site-packages/pyrogram/client.py", line 569, in handle_updates
    channel=await self.resolve_peer(utils.get_channel_id(channel_id)),
            ^^^^^^^^^^^^^^^^^^^^^^^^^^^^^^^^^^^^^^^^^^^^^^^^^^^^^^^^^
  File "/workspace/venv/lib/python3.13/site-packages/pyrogram/methods/advanced/resolve_peer.py", line 89, in resolve_peer
    peer_type = utils.get_peer_type(peer_id)
  File "/workspace/venv/lib/python3.13/site-packages/pyrogram/utils.py", line 246, in get_peer_type
    raise ValueError(f"Peer id invalid: {peer_id}")
ValueError: Peer id invalid: -1002725376687
[16-Aug-25 03:14:02 - ERROR] - asyncio - Task exception was never retrieved
future: <Task finished name='Task-807' coro=<Client.handle_updates() done, defined at /workspace/venv/lib/python3.13/site-packages/pyrogram/client.py:535> exception=ValueError('Peer id invalid: -1002725376687')>
Traceback (most recent call last):
  File "/workspace/venv/lib/python3.13/site-packages/pyrogram/methods/advanced/resolve_peer.py", line 62, in resolve_peer
    return await self.storage.get_peer_by_id(peer_id)
           ^^^^^^^^^^^^^^^^^^^^^^^^^^^^^^^^^^^^^^^^^^
  File "/workspace/venv/lib/python3.13/site-packages/pyrogram/storage/sqlite_storage.py", line 142, in get_peer_by_id
    raise KeyError(f"ID not found: {peer_id}")
KeyError: 'ID not found: -1002725376687'

During handling of the above exception, another exception occurred:

Traceback (most recent call last):
  File "/workspace/venv/lib/python3.13/site-packages/pyrogram/client.py", line 569, in handle_updates
    channel=await self.resolve_peer(utils.get_channel_id(channel_id)),
            ^^^^^^^^^^^^^^^^^^^^^^^^^^^^^^^^^^^^^^^^^^^^^^^^^^^^^^^^^
  File "/workspace/venv/lib/python3.13/site-packages/pyrogram/methods/advanced/resolve_peer.py", line 89, in resolve_peer
    peer_type = utils.get_peer_type(peer_id)
  File "/workspace/venv/lib/python3.13/site-packages/pyrogram/utils.py", line 246, in get_peer_type
    raise ValueError(f"Peer id invalid: {peer_id}")
ValueError: Peer id invalid: -1002725376687
[16-Aug-25 03:14:02 - ERROR] - asyncio - Task exception was never retrieved
future: <Task finished name='Task-811' coro=<Client.handle_updates() done, defined at /workspace/venv/lib/python3.13/site-packages/pyrogram/client.py:535> exception=ValueError('Peer id invalid: -1002725376687')>
Traceback (most recent call last):
  File "/workspace/venv/lib/python3.13/site-packages/pyrogram/methods/advanced/resolve_peer.py", line 62, in resolve_peer
    return await self.storage.get_peer_by_id(peer_id)
           ^^^^^^^^^^^^^^^^^^^^^^^^^^^^^^^^^^^^^^^^^^
  File "/workspace/venv/lib/python3.13/site-packages/pyrogram/storage/sqlite_storage.py", line 142, in get_peer_by_id
    raise KeyError(f"ID not found: {peer_id}")
KeyError: 'ID not found: -1002725376687'

During handling of the above exception, another exception occurred:

Traceback (most recent call last):
  File "/workspace/venv/lib/python3.13/site-packages/pyrogram/client.py", line 569, in handle_updates
    channel=await self.resolve_peer(utils.get_channel_id(channel_id)),
            ^^^^^^^^^^^^^^^^^^^^^^^^^^^^^^^^^^^^^^^^^^^^^^^^^^^^^^^^^
  File "/workspace/venv/lib/python3.13/site-packages/pyrogram/methods/advanced/resolve_peer.py", line 89, in resolve_peer
    peer_type = utils.get_peer_type(peer_id)
  File "/workspace/venv/lib/python3.13/site-packages/pyrogram/utils.py", line 246, in get_peer_type
    raise ValueError(f"Peer id invalid: {peer_id}")
ValueError: Peer id invalid: -1002725376687
[16-Aug-25 03:14:03 - ERROR] - asyncio - Task exception was never retrieved
future: <Task finished name='Task-815' coro=<Client.handle_updates() done, defined at /workspace/venv/lib/python3.13/site-packages/pyrogram/client.py:535> exception=ValueError('Peer id invalid: -1002725376687')>
Traceback (most recent call last):
  File "/workspace/venv/lib/python3.13/site-packages/pyrogram/methods/advanced/resolve_peer.py", line 62, in resolve_peer
    return await self.storage.get_peer_by_id(peer_id)
           ^^^^^^^^^^^^^^^^^^^^^^^^^^^^^^^^^^^^^^^^^^
  File "/workspace/venv/lib/python3.13/site-packages/pyrogram/storage/sqlite_storage.py", line 142, in get_peer_by_id
    raise KeyError(f"ID not found: {peer_id}")
KeyError: 'ID not found: -1002725376687'

During handling of the above exception, another exception occurred:

Traceback (most recent call last):
  File "/workspace/venv/lib/python3.13/site-packages/pyrogram/client.py", line 569, in handle_updates
    channel=await self.resolve_peer(utils.get_channel_id(channel_id)),
            ^^^^^^^^^^^^^^^^^^^^^^^^^^^^^^^^^^^^^^^^^^^^^^^^^^^^^^^^^
  File "/workspace/venv/lib/python3.13/site-packages/pyrogram/methods/advanced/resolve_peer.py", line 89, in resolve_peer
    peer_type = utils.get_peer_type(peer_id)
  File "/workspace/venv/lib/python3.13/site-packages/pyrogram/utils.py", line 246, in get_peer_type
    raise ValueError(f"Peer id invalid: {peer_id}")
ValueError: Peer id invalid: -1002725376687
[16-Aug-25 03:14:07 - ERROR] - asyncio - Task exception was never retrieved
future: <Task finished name='Task-822' coro=<Client.handle_updates() done, defined at /workspace/venv/lib/python3.13/site-packages/pyrogram/client.py:535> exception=ValueError('Peer id invalid: -1002725376687')>
Traceback (most recent call last):
  File "/workspace/venv/lib/python3.13/site-packages/pyrogram/methods/advanced/resolve_peer.py", line 62, in resolve_peer
    return await self.storage.get_peer_by_id(peer_id)
           ^^^^^^^^^^^^^^^^^^^^^^^^^^^^^^^^^^^^^^^^^^
  File "/workspace/venv/lib/python3.13/site-packages/pyrogram/storage/sqlite_storage.py", line 142, in get_peer_by_id
    raise KeyError(f"ID not found: {peer_id}")
KeyError: 'ID not found: -1002725376687'

During handling of the above exception, another exception occurred:

Traceback (most recent call last):
  File "/workspace/venv/lib/python3.13/site-packages/pyrogram/client.py", line 569, in handle_updates
    channel=await self.resolve_peer(utils.get_channel_id(channel_id)),
            ^^^^^^^^^^^^^^^^^^^^^^^^^^^^^^^^^^^^^^^^^^^^^^^^^^^^^^^^^
  File "/workspace/venv/lib/python3.13/site-packages/pyrogram/methods/advanced/resolve_peer.py", line 89, in resolve_peer
    peer_type = utils.get_peer_type(peer_id)
  File "/workspace/venv/lib/python3.13/site-packages/pyrogram/utils.py", line 246, in get_peer_type
    raise ValueError(f"Peer id invalid: {peer_id}")
ValueError: Peer id invalid: -1002725376687
[16-Aug-25 03:14:08 - ERROR] - asyncio - Task exception was never retrieved
future: <Task finished name='Task-824' coro=<Client.handle_updates() done, defined at /workspace/venv/lib/python3.13/site-packages/pyrogram/client.py:535> exception=ValueError('Peer id invalid: -1002725376687')>
Traceback (most recent call last):
  File "/workspace/venv/lib/python3.13/site-packages/pyrogram/methods/advanced/resolve_peer.py", line 62, in resolve_peer
    return await self.storage.get_peer_by_id(peer_id)
           ^^^^^^^^^^^^^^^^^^^^^^^^^^^^^^^^^^^^^^^^^^
  File "/workspace/venv/lib/python3.13/site-packages/pyrogram/storage/sqlite_storage.py", line 142, in get_peer_by_id
    raise KeyError(f"ID not found: {peer_id}")
KeyError: 'ID not found: -1002725376687'

During handling of the above exception, another exception occurred:

Traceback (most recent call last):
  File "/workspace/venv/lib/python3.13/site-packages/pyrogram/client.py", line 569, in handle_updates
    channel=await self.resolve_peer(utils.get_channel_id(channel_id)),
            ^^^^^^^^^^^^^^^^^^^^^^^^^^^^^^^^^^^^^^^^^^^^^^^^^^^^^^^^^
  File "/workspace/venv/lib/python3.13/site-packages/pyrogram/methods/advanced/resolve_peer.py", line 89, in resolve_peer
    peer_type = utils.get_peer_type(peer_id)
  File "/workspace/venv/lib/python3.13/site-packages/pyrogram/utils.py", line 246, in get_peer_type
    raise ValueError(f"Peer id invalid: {peer_id}")
ValueError: Peer id invalid: -1002725376687
[16-Aug-25 03:14:27 - ERROR] - asyncio - Task exception was never retrieved
future: <Task finished name='Task-854' coro=<Client.handle_updates() done, defined at /workspace/venv/lib/python3.13/site-packages/pyrogram/client.py:535> exception=ValueError('Peer id invalid: -1002725376687')>
Traceback (most recent call last):
  File "/workspace/venv/lib/python3.13/site-packages/pyrogram/methods/advanced/resolve_peer.py", line 62, in resolve_peer
    return await self.storage.get_peer_by_id(peer_id)
           ^^^^^^^^^^^^^^^^^^^^^^^^^^^^^^^^^^^^^^^^^^
  File "/workspace/venv/lib/python3.13/site-packages/pyrogram/storage/sqlite_storage.py", line 142, in get_peer_by_id
    raise KeyError(f"ID not found: {peer_id}")
KeyError: 'ID not found: -1002725376687'

During handling of the above exception, another exception occurred:

Traceback (most recent call last):
  File "/workspace/venv/lib/python3.13/site-packages/pyrogram/client.py", line 569, in handle_updates
    channel=await self.resolve_peer(utils.get_channel_id(channel_id)),
            ^^^^^^^^^^^^^^^^^^^^^^^^^^^^^^^^^^^^^^^^^^^^^^^^^^^^^^^^^
  File "/workspace/venv/lib/python3.13/site-packages/pyrogram/methods/advanced/resolve_peer.py", line 89, in resolve_peer
    peer_type = utils.get_peer_type(peer_id)
  File "/workspace/venv/lib/python3.13/site-packages/pyrogram/utils.py", line 246, in get_peer_type
    raise ValueError(f"Peer id invalid: {peer_id}")
ValueError: Peer id invalid: -1002725376687
[16-Aug-25 03:14:36 - ERROR] - asyncio - Task exception was never retrieved
future: <Task finished name='Task-872' coro=<Client.handle_updates() done, defined at /workspace/venv/lib/python3.13/site-packages/pyrogram/client.py:535> exception=ValueError('Peer id invalid: -1002725376687')>
Traceback (most recent call last):
  File "/workspace/venv/lib/python3.13/site-packages/pyrogram/methods/advanced/resolve_peer.py", line 62, in resolve_peer
    return await self.storage.get_peer_by_id(peer_id)
           ^^^^^^^^^^^^^^^^^^^^^^^^^^^^^^^^^^^^^^^^^^
  File "/workspace/venv/lib/python3.13/site-packages/pyrogram/storage/sqlite_storage.py", line 142, in get_peer_by_id
    raise KeyError(f"ID not found: {peer_id}")
KeyError: 'ID not found: -1002725376687'

During handling of the above exception, another exception occurred:

Traceback (most recent call last):
  File "/workspace/venv/lib/python3.13/site-packages/pyrogram/client.py", line 569, in handle_updates
    channel=await self.resolve_peer(utils.get_channel_id(channel_id)),
            ^^^^^^^^^^^^^^^^^^^^^^^^^^^^^^^^^^^^^^^^^^^^^^^^^^^^^^^^^
  File "/workspace/venv/lib/python3.13/site-packages/pyrogram/methods/advanced/resolve_peer.py", line 89, in resolve_peer
    peer_type = utils.get_peer_type(peer_id)
  File "/workspace/venv/lib/python3.13/site-packages/pyrogram/utils.py", line 246, in get_peer_type
    raise ValueError(f"Peer id invalid: {peer_id}")
ValueError: Peer id invalid: -1002725376687
[16-Aug-25 03:14:48 - ERROR] - asyncio - Task exception was never retrieved
future: <Task finished name='Task-941' coro=<Client.handle_updates() done, defined at /workspace/venv/lib/python3.13/site-packages/pyrogram/client.py:535> exception=ValueError('Peer id invalid: -1002725376687')>
Traceback (most recent call last):
  File "/workspace/venv/lib/python3.13/site-packages/pyrogram/methods/advanced/resolve_peer.py", line 62, in resolve_peer
    return await self.storage.get_peer_by_id(peer_id)
           ^^^^^^^^^^^^^^^^^^^^^^^^^^^^^^^^^^^^^^^^^^
  File "/workspace/venv/lib/python3.13/site-packages/pyrogram/storage/sqlite_storage.py", line 142, in get_peer_by_id
    raise KeyError(f"ID not found: {peer_id}")
KeyError: 'ID not found: -1002725376687'

During handling of the above exception, another exception occurred:

Traceback (most recent call last):
  File "/workspace/venv/lib/python3.13/site-packages/pyrogram/client.py", line 569, in handle_updates
    channel=await self.resolve_peer(utils.get_channel_id(channel_id)),
            ^^^^^^^^^^^^^^^^^^^^^^^^^^^^^^^^^^^^^^^^^^^^^^^^^^^^^^^^^
  File "/workspace/venv/lib/python3.13/site-packages/pyrogram/methods/advanced/resolve_peer.py", line 89, in resolve_peer
    peer_type = utils.get_peer_type(peer_id)
  File "/workspace/venv/lib/python3.13/site-packages/pyrogram/utils.py", line 246, in get_peer_type
    raise ValueError(f"Peer id invalid: {peer_id}")
ValueError: Peer id invalid: -1002725376687
[16-Aug-25 03:14:50 - ERROR] - asyncio - Task exception was never retrieved
future: <Task finished name='Task-955' coro=<Client.handle_updates() done, defined at /workspace/venv/lib/python3.13/site-packages/pyrogram/client.py:535> exception=ValueError('Peer id invalid: -1002524216878')>
Traceback (most recent call last):
  File "/workspace/venv/lib/python3.13/site-packages/pyrogram/methods/advanced/resolve_peer.py", line 62, in resolve_peer
    return await self.storage.get_peer_by_id(peer_id)
           ^^^^^^^^^^^^^^^^^^^^^^^^^^^^^^^^^^^^^^^^^^
  File "/workspace/venv/lib/python3.13/site-packages/pyrogram/storage/sqlite_storage.py", line 142, in get_peer_by_id
    raise KeyError(f"ID not found: {peer_id}")
KeyError: 'ID not found: -1002524216878'

During handling of the above exception, another exception occurred:

Traceback (most recent call last):
  File "/workspace/venv/lib/python3.13/site-packages/pyrogram/client.py", line 569, in handle_updates
    channel=await self.resolve_peer(utils.get_channel_id(channel_id)),
            ^^^^^^^^^^^^^^^^^^^^^^^^^^^^^^^^^^^^^^^^^^^^^^^^^^^^^^^^^
  File "/workspace/venv/lib/python3.13/site-packages/pyrogram/methods/advanced/resolve_peer.py", line 89, in resolve_peer
    peer_type = utils.get_peer_type(peer_id)
  File "/workspace/venv/lib/python3.13/site-packages/pyrogram/utils.py", line 246, in get_peer_type
    raise ValueError(f"Peer id invalid: {peer_id}")
ValueError: Peer id invalid: -1002524216878
[16-Aug-25 03:14:50 - ERROR] - asyncio - Task exception was never retrieved
future: <Task finished name='Task-957' coro=<Client.handle_updates() done, defined at /workspace/venv/lib/python3.13/site-packages/pyrogram/client.py:535> exception=ValueError('Peer id invalid: -1002524216878')>
Traceback (most recent call last):
  File "/workspace/venv/lib/python3.13/site-packages/pyrogram/methods/advanced/resolve_peer.py", line 62, in resolve_peer
    return await self.storage.get_peer_by_id(peer_id)
           ^^^^^^^^^^^^^^^^^^^^^^^^^^^^^^^^^^^^^^^^^^
  File "/workspace/venv/lib/python3.13/site-packages/pyrogram/storage/sqlite_storage.py", line 142, in get_peer_by_id
    raise KeyError(f"ID not found: {peer_id}")
KeyError: 'ID not found: -1002524216878'

During handling of the above exception, another exception occurred:

Traceback (most recent call last):
  File "/workspace/venv/lib/python3.13/site-packages/pyrogram/client.py", line 569, in handle_updates
    channel=await self.resolve_peer(utils.get_channel_id(channel_id)),
            ^^^^^^^^^^^^^^^^^^^^^^^^^^^^^^^^^^^^^^^^^^^^^^^^^^^^^^^^^
  File "/workspace/venv/lib/python3.13/site-packages/pyrogram/methods/advanced/resolve_peer.py", line 89, in resolve_peer
    peer_type = utils.get_peer_type(peer_id)
  File "/workspace/venv/lib/python3.13/site-packages/pyrogram/utils.py", line 246, in get_peer_type
    raise ValueError(f"Peer id invalid: {peer_id}")
ValueError: Peer id invalid: -1002524216878
[16-Aug-25 03:14:50 - ERROR] - asyncio - Task exception was never retrieved
future: <Task finished name='Task-959' coro=<Client.handle_updates() done, defined at /workspace/venv/lib/python3.13/site-packages/pyrogram/client.py:535> exception=ValueError('Peer id invalid: -1002524216878')>
Traceback (most recent call last):
  File "/workspace/venv/lib/python3.13/site-packages/pyrogram/methods/advanced/resolve_peer.py", line 62, in resolve_peer
    return await self.storage.get_peer_by_id(peer_id)
           ^^^^^^^^^^^^^^^^^^^^^^^^^^^^^^^^^^^^^^^^^^
  File "/workspace/venv/lib/python3.13/site-packages/pyrogram/storage/sqlite_storage.py", line 142, in get_peer_by_id
    raise KeyError(f"ID not found: {peer_id}")
KeyError: 'ID not found: -1002524216878'

During handling of the above exception, another exception occurred:

Traceback (most recent call last):
  File "/workspace/venv/lib/python3.13/site-packages/pyrogram/client.py", line 569, in handle_updates
    channel=await self.resolve_peer(utils.get_channel_id(channel_id)),
            ^^^^^^^^^^^^^^^^^^^^^^^^^^^^^^^^^^^^^^^^^^^^^^^^^^^^^^^^^
  File "/workspace/venv/lib/python3.13/site-packages/pyrogram/methods/advanced/resolve_peer.py", line 89, in resolve_peer
    peer_type = utils.get_peer_type(peer_id)
  File "/workspace/venv/lib/python3.13/site-packages/pyrogram/utils.py", line 246, in get_peer_type
    raise ValueError(f"Peer id invalid: {peer_id}")
ValueError: Peer id invalid: -1002524216878
[16-Aug-25 03:14:50 - ERROR] - asyncio - Task exception was never retrieved
future: <Task finished name='Task-961' coro=<Client.handle_updates() done, defined at /workspace/venv/lib/python3.13/site-packages/pyrogram/client.py:535> exception=ValueError('Peer id invalid: -1002524216878')>
Traceback (most recent call last):
  File "/workspace/venv/lib/python3.13/site-packages/pyrogram/methods/advanced/resolve_peer.py", line 62, in resolve_peer
    return await self.storage.get_peer_by_id(peer_id)
           ^^^^^^^^^^^^^^^^^^^^^^^^^^^^^^^^^^^^^^^^^^
  File "/workspace/venv/lib/python3.13/site-packages/pyrogram/storage/sqlite_storage.py", line 142, in get_peer_by_id
    raise KeyError(f"ID not found: {peer_id}")
KeyError: 'ID not found: -1002524216878'

During handling of the above exception, another exception occurred:

Traceback (most recent call last):
  File "/workspace/venv/lib/python3.13/site-packages/pyrogram/client.py", line 569, in handle_updates
    channel=await self.resolve_peer(utils.get_channel_id(channel_id)),
            ^^^^^^^^^^^^^^^^^^^^^^^^^^^^^^^^^^^^^^^^^^^^^^^^^^^^^^^^^
  File "/workspace/venv/lib/python3.13/site-packages/pyrogram/methods/advanced/resolve_peer.py", line 89, in resolve_peer
    peer_type = utils.get_peer_type(peer_id)
  File "/workspace/venv/lib/python3.13/site-packages/pyrogram/utils.py", line 246, in get_peer_type
    raise ValueError(f"Peer id invalid: {peer_id}")
ValueError: Peer id invalid: -1002524216878
[16-Aug-25 03:14:59 - ERROR] - asyncio - Task exception was never retrieved
future: <Task finished name='Task-1008' coro=<Client.handle_updates() done, defined at /workspace/venv/lib/python3.13/site-packages/pyrogram/client.py:535> exception=ValueError('Peer id invalid: -1002725376687')>
Traceback (most recent call last):
  File "/workspace/venv/lib/python3.13/site-packages/pyrogram/methods/advanced/resolve_peer.py", line 62, in resolve_peer
    return await self.storage.get_peer_by_id(peer_id)
           ^^^^^^^^^^^^^^^^^^^^^^^^^^^^^^^^^^^^^^^^^^
  File "/workspace/venv/lib/python3.13/site-packages/pyrogram/storage/sqlite_storage.py", line 142, in get_peer_by_id
    raise KeyError(f"ID not found: {peer_id}")
KeyError: 'ID not found: -1002725376687'

During handling of the above exception, another exception occurred:

Traceback (most recent call last):
  File "/workspace/venv/lib/python3.13/site-packages/pyrogram/client.py", line 569, in handle_updates
    channel=await self.resolve_peer(utils.get_channel_id(channel_id)),
            ^^^^^^^^^^^^^^^^^^^^^^^^^^^^^^^^^^^^^^^^^^^^^^^^^^^^^^^^^
  File "/workspace/venv/lib/python3.13/site-packages/pyrogram/methods/advanced/resolve_peer.py", line 89, in resolve_peer
    peer_type = utils.get_peer_type(peer_id)
  File "/workspace/venv/lib/python3.13/site-packages/pyrogram/utils.py", line 246, in get_peer_type
    raise ValueError(f"Peer id invalid: {peer_id}")
ValueError: Peer id invalid: -1002725376687
[16-Aug-25 03:15:00 - ERROR] - asyncio - Task exception was never retrieved
future: <Task finished name='Task-1018' coro=<Client.handle_updates() done, defined at /workspace/venv/lib/python3.13/site-packages/pyrogram/client.py:535> exception=ValueError('Peer id invalid: -1002725376687')>
Traceback (most recent call last):
  File "/workspace/venv/lib/python3.13/site-packages/pyrogram/methods/advanced/resolve_peer.py", line 62, in resolve_peer
    return await self.storage.get_peer_by_id(peer_id)
           ^^^^^^^^^^^^^^^^^^^^^^^^^^^^^^^^^^^^^^^^^^
  File "/workspace/venv/lib/python3.13/site-packages/pyrogram/storage/sqlite_storage.py", line 142, in get_peer_by_id
    raise KeyError(f"ID not found: {peer_id}")
KeyError: 'ID not found: -1002725376687'

During handling of the above exception, another exception occurred:

Traceback (most recent call last):
  File "/workspace/venv/lib/python3.13/site-packages/pyrogram/client.py", line 569, in handle_updates
    channel=await self.resolve_peer(utils.get_channel_id(channel_id)),
            ^^^^^^^^^^^^^^^^^^^^^^^^^^^^^^^^^^^^^^^^^^^^^^^^^^^^^^^^^
  File "/workspace/venv/lib/python3.13/site-packages/pyrogram/methods/advanced/resolve_peer.py", line 89, in resolve_peer
    peer_type = utils.get_peer_type(peer_id)
  File "/workspace/venv/lib/python3.13/site-packages/pyrogram/utils.py", line 246, in get_peer_type
    raise ValueError(f"Peer id invalid: {peer_id}")
ValueError: Peer id invalid: -1002725376687
[16-Aug-25 03:15:14 - ERROR] - asyncio - Task exception was never retrieved
future: <Task finished name='Task-1038' coro=<Client.handle_updates() done, defined at /workspace/venv/lib/python3.13/site-packages/pyrogram/client.py:535> exception=ValueError('Peer id invalid: -1002725376687')>
Traceback (most recent call last):
  File "/workspace/venv/lib/python3.13/site-packages/pyrogram/methods/advanced/resolve_peer.py", line 62, in resolve_peer
    return await self.storage.get_peer_by_id(peer_id)
           ^^^^^^^^^^^^^^^^^^^^^^^^^^^^^^^^^^^^^^^^^^
  File "/workspace/venv/lib/python3.13/site-packages/pyrogram/storage/sqlite_storage.py", line 142, in get_peer_by_id
    raise KeyError(f"ID not found: {peer_id}")
KeyError: 'ID not found: -1002725376687'

During handling of the above exception, another exception occurred:

Traceback (most recent call last):
  File "/workspace/venv/lib/python3.13/site-packages/pyrogram/client.py", line 569, in handle_updates
    channel=await self.resolve_peer(utils.get_channel_id(channel_id)),
            ^^^^^^^^^^^^^^^^^^^^^^^^^^^^^^^^^^^^^^^^^^^^^^^^^^^^^^^^^
  File "/workspace/venv/lib/python3.13/site-packages/pyrogram/methods/advanced/resolve_peer.py", line 89, in resolve_peer
    peer_type = utils.get_peer_type(peer_id)
  File "/workspace/venv/lib/python3.13/site-packages/pyrogram/utils.py", line 246, in get_peer_type
    raise ValueError(f"Peer id invalid: {peer_id}")
ValueError: Peer id invalid: -1002725376687
[16-Aug-25 03:15:19 - ERROR] - asyncio - Task exception was never retrieved
future: <Task finished name='Task-1047' coro=<Client.handle_updates() done, defined at /workspace/venv/lib/python3.13/site-packages/pyrogram/client.py:535> exception=ValueError('Peer id invalid: -1002590071792')>
Traceback (most recent call last):
  File "/workspace/venv/lib/python3.13/site-packages/pyrogram/methods/advanced/resolve_peer.py", line 62, in resolve_peer
    return await self.storage.get_peer_by_id(peer_id)
           ^^^^^^^^^^^^^^^^^^^^^^^^^^^^^^^^^^^^^^^^^^
  File "/workspace/venv/lib/python3.13/site-packages/pyrogram/storage/sqlite_storage.py", line 142, in get_peer_by_id
    raise KeyError(f"ID not found: {peer_id}")
KeyError: 'ID not found: -1002590071792'

During handling of the above exception, another exception occurred:

Traceback (most recent call last):
  File "/workspace/venv/lib/python3.13/site-packages/pyrogram/client.py", line 569, in handle_updates
    channel=await self.resolve_peer(utils.get_channel_id(channel_id)),
            ^^^^^^^^^^^^^^^^^^^^^^^^^^^^^^^^^^^^^^^^^^^^^^^^^^^^^^^^^
  File "/workspace/venv/lib/python3.13/site-packages/pyrogram/methods/advanced/resolve_peer.py", line 89, in resolve_peer
    peer_type = utils.get_peer_type(peer_id)
  File "/workspace/venv/lib/python3.13/site-packages/pyrogram/utils.py", line 246, in get_peer_type
    raise ValueError(f"Peer id invalid: {peer_id}")
ValueError: Peer id invalid: -1002590071792
[16-Aug-25 03:15:19 - ERROR] - asyncio - Task exception was never retrieved
future: <Task finished name='Task-1049' coro=<Client.handle_updates() done, defined at /workspace/venv/lib/python3.13/site-packages/pyrogram/client.py:535> exception=ValueError('Peer id invalid: -1002590071792')>
Traceback (most recent call last):
  File "/workspace/venv/lib/python3.13/site-packages/pyrogram/methods/advanced/resolve_peer.py", line 62, in resolve_peer
    return await self.storage.get_peer_by_id(peer_id)
           ^^^^^^^^^^^^^^^^^^^^^^^^^^^^^^^^^^^^^^^^^^
  File "/workspace/venv/lib/python3.13/site-packages/pyrogram/storage/sqlite_storage.py", line 142, in get_peer_by_id
    raise KeyError(f"ID not found: {peer_id}")
KeyError: 'ID not found: -1002590071792'

During handling of the above exception, another exception occurred:

Traceback (most recent call last):
  File "/workspace/venv/lib/python3.13/site-packages/pyrogram/client.py", line 569, in handle_updates
    channel=await self.resolve_peer(utils.get_channel_id(channel_id)),
            ^^^^^^^^^^^^^^^^^^^^^^^^^^^^^^^^^^^^^^^^^^^^^^^^^^^^^^^^^
  File "/workspace/venv/lib/python3.13/site-packages/pyrogram/methods/advanced/resolve_peer.py", line 89, in resolve_peer
    peer_type = utils.get_peer_type(peer_id)
  File "/workspace/venv/lib/python3.13/site-packages/pyrogram/utils.py", line 246, in get_peer_type
    raise ValueError(f"Peer id invalid: {peer_id}")
ValueError: Peer id invalid: -1002590071792
[16-Aug-25 03:15:19 - ERROR] - asyncio - Task exception was never retrieved
future: <Task finished name='Task-1054' coro=<Client.handle_updates() done, defined at /workspace/venv/lib/python3.13/site-packages/pyrogram/client.py:535> exception=ValueError('Peer id invalid: -1002725376687')>
Traceback (most recent call last):
  File "/workspace/venv/lib/python3.13/site-packages/pyrogram/methods/advanced/resolve_peer.py", line 62, in resolve_peer
    return await self.storage.get_peer_by_id(peer_id)
           ^^^^^^^^^^^^^^^^^^^^^^^^^^^^^^^^^^^^^^^^^^
  File "/workspace/venv/lib/python3.13/site-packages/pyrogram/storage/sqlite_storage.py", line 142, in get_peer_by_id
    raise KeyError(f"ID not found: {peer_id}")
KeyError: 'ID not found: -1002725376687'

During handling of the above exception, another exception occurred:

Traceback (most recent call last):
  File "/workspace/venv/lib/python3.13/site-packages/pyrogram/client.py", line 569, in handle_updates
    channel=await self.resolve_peer(utils.get_channel_id(channel_id)),
            ^^^^^^^^^^^^^^^^^^^^^^^^^^^^^^^^^^^^^^^^^^^^^^^^^^^^^^^^^
  File "/workspace/venv/lib/python3.13/site-packages/pyrogram/methods/advanced/resolve_peer.py", line 89, in resolve_peer
    peer_type = utils.get_peer_type(peer_id)
  File "/workspace/venv/lib/python3.13/site-packages/pyrogram/utils.py", line 246, in get_peer_type
    raise ValueError(f"Peer id invalid: {peer_id}")
ValueError: Peer id invalid: -1002725376687
[16-Aug-25 03:15:19 - ERROR] - asyncio - Task exception was never retrieved
future: <Task finished name='Task-1056' coro=<Client.handle_updates() done, defined at /workspace/venv/lib/python3.13/site-packages/pyrogram/client.py:535> exception=ValueError('Peer id invalid: -1002725376687')>
Traceback (most recent call last):
  File "/workspace/venv/lib/python3.13/site-packages/pyrogram/methods/advanced/resolve_peer.py", line 62, in resolve_peer
    return await self.storage.get_peer_by_id(peer_id)
           ^^^^^^^^^^^^^^^^^^^^^^^^^^^^^^^^^^^^^^^^^^
  File "/workspace/venv/lib/python3.13/site-packages/pyrogram/storage/sqlite_storage.py", line 142, in get_peer_by_id
    raise KeyError(f"ID not found: {peer_id}")
KeyError: 'ID not found: -1002725376687'

During handling of the above exception, another exception occurred:

Traceback (most recent call last):
  File "/workspace/venv/lib/python3.13/site-packages/pyrogram/client.py", line 569, in handle_updates
    channel=await self.resolve_peer(utils.get_channel_id(channel_id)),
            ^^^^^^^^^^^^^^^^^^^^^^^^^^^^^^^^^^^^^^^^^^^^^^^^^^^^^^^^^
  File "/workspace/venv/lib/python3.13/site-packages/pyrogram/methods/advanced/resolve_peer.py", line 89, in resolve_peer
    peer_type = utils.get_peer_type(peer_id)
  File "/workspace/venv/lib/python3.13/site-packages/pyrogram/utils.py", line 246, in get_peer_type
    raise ValueError(f"Peer id invalid: {peer_id}")
ValueError: Peer id invalid: -1002725376687
[16-Aug-25 03:15:32 - ERROR] - asyncio - Task exception was never retrieved
future: <Task finished name='Task-1079' coro=<Client.handle_updates() done, defined at /workspace/venv/lib/python3.13/site-packages/pyrogram/client.py:535> exception=ValueError('Peer id invalid: -1002725376687')>
Traceback (most recent call last):
  File "/workspace/venv/lib/python3.13/site-packages/pyrogram/methods/advanced/resolve_peer.py", line 62, in resolve_peer
    return await self.storage.get_peer_by_id(peer_id)
           ^^^^^^^^^^^^^^^^^^^^^^^^^^^^^^^^^^^^^^^^^^
  File "/workspace/venv/lib/python3.13/site-packages/pyrogram/storage/sqlite_storage.py", line 142, in get_peer_by_id
    raise KeyError(f"ID not found: {peer_id}")
KeyError: 'ID not found: -1002725376687'

During handling of the above exception, another exception occurred:

Traceback (most recent call last):
  File "/workspace/venv/lib/python3.13/site-packages/pyrogram/client.py", line 569, in handle_updates
    channel=await self.resolve_peer(utils.get_channel_id(channel_id)),
            ^^^^^^^^^^^^^^^^^^^^^^^^^^^^^^^^^^^^^^^^^^^^^^^^^^^^^^^^^
  File "/workspace/venv/lib/python3.13/site-packages/pyrogram/methods/advanced/resolve_peer.py", line 89, in resolve_peer
    peer_type = utils.get_peer_type(peer_id)
  File "/workspace/venv/lib/python3.13/site-packages/pyrogram/utils.py", line 246, in get_peer_type
    raise ValueError(f"Peer id invalid: {peer_id}")
ValueError: Peer id invalid: -1002725376687
[16-Aug-25 03:15:37 - ERROR] - asyncio - Task exception was never retrieved
future: <Task finished name='Task-1089' coro=<Client.handle_updates() done, defined at /workspace/venv/lib/python3.13/site-packages/pyrogram/client.py:535> exception=ValueError('Peer id invalid: -1002725376687')>
Traceback (most recent call last):
  File "/workspace/venv/lib/python3.13/site-packages/pyrogram/methods/advanced/resolve_peer.py", line 62, in resolve_peer
    return await self.storage.get_peer_by_id(peer_id)
           ^^^^^^^^^^^^^^^^^^^^^^^^^^^^^^^^^^^^^^^^^^
  File "/workspace/venv/lib/python3.13/site-packages/pyrogram/storage/sqlite_storage.py", line 142, in get_peer_by_id
    raise KeyError(f"ID not found: {peer_id}")
KeyError: 'ID not found: -1002725376687'

During handling of the above exception, another exception occurred:

Traceback (most recent call last):
  File "/workspace/venv/lib/python3.13/site-packages/pyrogram/client.py", line 569, in handle_updates
    channel=await self.resolve_peer(utils.get_channel_id(channel_id)),
            ^^^^^^^^^^^^^^^^^^^^^^^^^^^^^^^^^^^^^^^^^^^^^^^^^^^^^^^^^
  File "/workspace/venv/lib/python3.13/site-packages/pyrogram/methods/advanced/resolve_peer.py", line 89, in resolve_peer
    peer_type = utils.get_peer_type(peer_id)
  File "/workspace/venv/lib/python3.13/site-packages/pyrogram/utils.py", line 246, in get_peer_type
    raise ValueError(f"Peer id invalid: {peer_id}")
ValueError: Peer id invalid: -1002725376687
[16-Aug-25 03:15:46 - ERROR] - asyncio - Task exception was never retrieved
future: <Task finished name='Task-1105' coro=<Client.handle_updates() done, defined at /workspace/venv/lib/python3.13/site-packages/pyrogram/client.py:535> exception=ValueError('Peer id invalid: -1002704003307')>
Traceback (most recent call last):
  File "/workspace/venv/lib/python3.13/site-packages/pyrogram/methods/advanced/resolve_peer.py", line 62, in resolve_peer
    return await self.storage.get_peer_by_id(peer_id)
           ^^^^^^^^^^^^^^^^^^^^^^^^^^^^^^^^^^^^^^^^^^
  File "/workspace/venv/lib/python3.13/site-packages/pyrogram/storage/sqlite_storage.py", line 142, in get_peer_by_id
    raise KeyError(f"ID not found: {peer_id}")
KeyError: 'ID not found: -1002704003307'

During handling of the above exception, another exception occurred:

Traceback (most recent call last):
  File "/workspace/venv/lib/python3.13/site-packages/pyrogram/client.py", line 569, in handle_updates
    channel=await self.resolve_peer(utils.get_channel_id(channel_id)),
            ^^^^^^^^^^^^^^^^^^^^^^^^^^^^^^^^^^^^^^^^^^^^^^^^^^^^^^^^^
  File "/workspace/venv/lib/python3.13/site-packages/pyrogram/methods/advanced/resolve_peer.py", line 89, in resolve_peer
    peer_type = utils.get_peer_type(peer_id)
  File "/workspace/venv/lib/python3.13/site-packages/pyrogram/utils.py", line 246, in get_peer_type
    raise ValueError(f"Peer id invalid: {peer_id}")
ValueError: Peer id invalid: -1002704003307
[16-Aug-25 03:15:47 - ERROR] - asyncio - Task exception was never retrieved
future: <Task finished name='Task-1113' coro=<Client.handle_updates() done, defined at /workspace/venv/lib/python3.13/site-packages/pyrogram/client.py:535> exception=ValueError('Peer id invalid: -1002704003307')>
Traceback (most recent call last):
  File "/workspace/venv/lib/python3.13/site-packages/pyrogram/methods/advanced/resolve_peer.py", line 62, in resolve_peer
    return await self.storage.get_peer_by_id(peer_id)
           ^^^^^^^^^^^^^^^^^^^^^^^^^^^^^^^^^^^^^^^^^^
  File "/workspace/venv/lib/python3.13/site-packages/pyrogram/storage/sqlite_storage.py", line 142, in get_peer_by_id
    raise KeyError(f"ID not found: {peer_id}")
KeyError: 'ID not found: -1002704003307'

During handling of the above exception, another exception occurred:

Traceback (most recent call last):
  File "/workspace/venv/lib/python3.13/site-packages/pyrogram/client.py", line 569, in handle_updates
    channel=await self.resolve_peer(utils.get_channel_id(channel_id)),
            ^^^^^^^^^^^^^^^^^^^^^^^^^^^^^^^^^^^^^^^^^^^^^^^^^^^^^^^^^
  File "/workspace/venv/lib/python3.13/site-packages/pyrogram/methods/advanced/resolve_peer.py", line 89, in resolve_peer
    peer_type = utils.get_peer_type(peer_id)
  File "/workspace/venv/lib/python3.13/site-packages/pyrogram/utils.py", line 246, in get_peer_type
    raise ValueError(f"Peer id invalid: {peer_id}")
ValueError: Peer id invalid: -1002704003307
[16-Aug-25 03:15:47 - ERROR] - asyncio - Task exception was never retrieved
future: <Task finished name='Task-1115' coro=<Client.handle_updates() done, defined at /workspace/venv/lib/python3.13/site-packages/pyrogram/client.py:535> exception=ValueError('Peer id invalid: -1002704003307')>
Traceback (most recent call last):
  File "/workspace/venv/lib/python3.13/site-packages/pyrogram/methods/advanced/resolve_peer.py", line 62, in resolve_peer
    return await self.storage.get_peer_by_id(peer_id)
           ^^^^^^^^^^^^^^^^^^^^^^^^^^^^^^^^^^^^^^^^^^
  File "/workspace/venv/lib/python3.13/site-packages/pyrogram/storage/sqlite_storage.py", line 142, in get_peer_by_id
    raise KeyError(f"ID not found: {peer_id}")
KeyError: 'ID not found: -1002704003307'

During handling of the above exception, another exception occurred:

Traceback (most recent call last):
  File "/workspace/venv/lib/python3.13/site-packages/pyrogram/client.py", line 569, in handle_updates
    channel=await self.resolve_peer(utils.get_channel_id(channel_id)),
            ^^^^^^^^^^^^^^^^^^^^^^^^^^^^^^^^^^^^^^^^^^^^^^^^^^^^^^^^^
  File "/workspace/venv/lib/python3.13/site-packages/pyrogram/methods/advanced/resolve_peer.py", line 89, in resolve_peer
    peer_type = utils.get_peer_type(peer_id)
  File "/workspace/venv/lib/python3.13/site-packages/pyrogram/utils.py", line 246, in get_peer_type
    raise ValueError(f"Peer id invalid: {peer_id}")
ValueError: Peer id invalid: -1002704003307
[16-Aug-25 03:15:47 - ERROR] - asyncio - Task exception was never retrieved
future: <Task finished name='Task-1117' coro=<Client.handle_updates() done, defined at /workspace/venv/lib/python3.13/site-packages/pyrogram/client.py:535> exception=ValueError('Peer id invalid: -1002725376687')>
Traceback (most recent call last):
  File "/workspace/venv/lib/python3.13/site-packages/pyrogram/methods/advanced/resolve_peer.py", line 62, in resolve_peer
    return await self.storage.get_peer_by_id(peer_id)
           ^^^^^^^^^^^^^^^^^^^^^^^^^^^^^^^^^^^^^^^^^^
  File "/workspace/venv/lib/python3.13/site-packages/pyrogram/storage/sqlite_storage.py", line 142, in get_peer_by_id
    raise KeyError(f"ID not found: {peer_id}")
KeyError: 'ID not found: -1002725376687'

During handling of the above exception, another exception occurred:

Traceback (most recent call last):
  File "/workspace/venv/lib/python3.13/site-packages/pyrogram/client.py", line 569, in handle_updates
    channel=await self.resolve_peer(utils.get_channel_id(channel_id)),
            ^^^^^^^^^^^^^^^^^^^^^^^^^^^^^^^^^^^^^^^^^^^^^^^^^^^^^^^^^
  File "/workspace/venv/lib/python3.13/site-packages/pyrogram/methods/advanced/resolve_peer.py", line 89, in resolve_peer
    peer_type = utils.get_peer_type(peer_id)
  File "/workspace/venv/lib/python3.13/site-packages/pyrogram/utils.py", line 246, in get_peer_type
    raise ValueError(f"Peer id invalid: {peer_id}")
ValueError: Peer id invalid: -1002725376687
[16-Aug-25 03:15:53 - ERROR] - asyncio - Task exception was never retrieved
future: <Task finished name='Task-1126' coro=<Client.handle_updates() done, defined at /workspace/venv/lib/python3.13/site-packages/pyrogram/client.py:535> exception=ValueError('Peer id invalid: -1002725376687')>
Traceback (most recent call last):
  File "/workspace/venv/lib/python3.13/site-packages/pyrogram/methods/advanced/resolve_peer.py", line 62, in resolve_peer
    return await self.storage.get_peer_by_id(peer_id)
           ^^^^^^^^^^^^^^^^^^^^^^^^^^^^^^^^^^^^^^^^^^
  File "/workspace/venv/lib/python3.13/site-packages/pyrogram/storage/sqlite_storage.py", line 142, in get_peer_by_id
    raise KeyError(f"ID not found: {peer_id}")
KeyError: 'ID not found: -1002725376687'

During handling of the above exception, another exception occurred:

Traceback (most recent call last):
  File "/workspace/venv/lib/python3.13/site-packages/pyrogram/client.py", line 569, in handle_updates
    channel=await self.resolve_peer(utils.get_channel_id(channel_id)),
            ^^^^^^^^^^^^^^^^^^^^^^^^^^^^^^^^^^^^^^^^^^^^^^^^^^^^^^^^^
  File "/workspace/venv/lib/python3.13/site-packages/pyrogram/methods/advanced/resolve_peer.py", line 89, in resolve_peer
    peer_type = utils.get_peer_type(peer_id)
  File "/workspace/venv/lib/python3.13/site-packages/pyrogram/utils.py", line 246, in get_peer_type
    raise ValueError(f"Peer id invalid: {peer_id}")
ValueError: Peer id invalid: -1002725376687
[16-Aug-25 03:16:08 - ERROR] - asyncio - Task exception was never retrieved
future: <Task finished name='Task-1147' coro=<Client.handle_updates() done, defined at /workspace/venv/lib/python3.13/site-packages/pyrogram/client.py:535> exception=ValueError('Peer id invalid: -1002725376687')>
Traceback (most recent call last):
  File "/workspace/venv/lib/python3.13/site-packages/pyrogram/methods/advanced/resolve_peer.py", line 62, in resolve_peer
    return await self.storage.get_peer_by_id(peer_id)
           ^^^^^^^^^^^^^^^^^^^^^^^^^^^^^^^^^^^^^^^^^^
  File "/workspace/venv/lib/python3.13/site-packages/pyrogram/storage/sqlite_storage.py", line 142, in get_peer_by_id
    raise KeyError(f"ID not found: {peer_id}")
KeyError: 'ID not found: -1002725376687'

During handling of the above exception, another exception occurred:

Traceback (most recent call last):
  File "/workspace/venv/lib/python3.13/site-packages/pyrogram/client.py", line 569, in handle_updates
    channel=await self.resolve_peer(utils.get_channel_id(channel_id)),
            ^^^^^^^^^^^^^^^^^^^^^^^^^^^^^^^^^^^^^^^^^^^^^^^^^^^^^^^^^
  File "/workspace/venv/lib/python3.13/site-packages/pyrogram/methods/advanced/resolve_peer.py", line 89, in resolve_peer
    peer_type = utils.get_peer_type(peer_id)
  File "/workspace/venv/lib/python3.13/site-packages/pyrogram/utils.py", line 246, in get_peer_type
    raise ValueError(f"Peer id invalid: {peer_id}")
ValueError: Peer id invalid: -1002725376687
[16-Aug-25 03:16:09 - ERROR] - asyncio - Task exception was never retrieved
future: <Task finished name='Task-1149' coro=<Client.handle_updates() done, defined at /workspace/venv/lib/python3.13/site-packages/pyrogram/client.py:535> exception=ValueError('Peer id invalid: -1002725376687')>
Traceback (most recent call last):
  File "/workspace/venv/lib/python3.13/site-packages/pyrogram/methods/advanced/resolve_peer.py", line 62, in resolve_peer
    return await self.storage.get_peer_by_id(peer_id)
           ^^^^^^^^^^^^^^^^^^^^^^^^^^^^^^^^^^^^^^^^^^
  File "/workspace/venv/lib/python3.13/site-packages/pyrogram/storage/sqlite_storage.py", line 142, in get_peer_by_id
    raise KeyError(f"ID not found: {peer_id}")
KeyError: 'ID not found: -1002725376687'

During handling of the above exception, another exception occurred:

Traceback (most recent call last):
  File "/workspace/venv/lib/python3.13/site-packages/pyrogram/client.py", line 569, in handle_updates
    channel=await self.resolve_peer(utils.get_channel_id(channel_id)),
            ^^^^^^^^^^^^^^^^^^^^^^^^^^^^^^^^^^^^^^^^^^^^^^^^^^^^^^^^^
  File "/workspace/venv/lib/python3.13/site-packages/pyrogram/methods/advanced/resolve_peer.py", line 89, in resolve_peer
    peer_type = utils.get_peer_type(peer_id)
  File "/workspace/venv/lib/python3.13/site-packages/pyrogram/utils.py", line 246, in get_peer_type
    raise ValueError(f"Peer id invalid: {peer_id}")
ValueError: Peer id invalid: -1002725376687
[16-Aug-25 03:16:18 - ERROR] - asyncio - Task exception was never retrieved
future: <Task finished name='Task-1171' coro=<Client.handle_updates() done, defined at /workspace/venv/lib/python3.13/site-packages/pyrogram/client.py:535> exception=ValueError('Peer id invalid: -1002725376687')>
Traceback (most recent call last):
  File "/workspace/venv/lib/python3.13/site-packages/pyrogram/methods/advanced/resolve_peer.py", line 62, in resolve_peer
    return await self.storage.get_peer_by_id(peer_id)
           ^^^^^^^^^^^^^^^^^^^^^^^^^^^^^^^^^^^^^^^^^^
  File "/workspace/venv/lib/python3.13/site-packages/pyrogram/storage/sqlite_storage.py", line 142, in get_peer_by_id
    raise KeyError(f"ID not found: {peer_id}")
KeyError: 'ID not found: -1002725376687'

During handling of the above exception, another exception occurred:

Traceback (most recent call last):
  File "/workspace/venv/lib/python3.13/site-packages/pyrogram/client.py", line 569, in handle_updates
    channel=await self.resolve_peer(utils.get_channel_id(channel_id)),
            ^^^^^^^^^^^^^^^^^^^^^^^^^^^^^^^^^^^^^^^^^^^^^^^^^^^^^^^^^
  File "/workspace/venv/lib/python3.13/site-packages/pyrogram/methods/advanced/resolve_peer.py", line 89, in resolve_peer
    peer_type = utils.get_peer_type(peer_id)
  File "/workspace/venv/lib/python3.13/site-packages/pyrogram/utils.py", line 246, in get_peer_type
    raise ValueError(f"Peer id invalid: {peer_id}")
ValueError: Peer id invalid: -1002725376687
[16-Aug-25 03:16:25 - ERROR] - asyncio - Task exception was never retrieved
future: <Task finished name='Task-1181' coro=<Client.handle_updates() done, defined at /workspace/venv/lib/python3.13/site-packages/pyrogram/client.py:535> exception=ValueError('Peer id invalid: -1002725376687')>
Traceback (most recent call last):
  File "/workspace/venv/lib/python3.13/site-packages/pyrogram/methods/advanced/resolve_peer.py", line 62, in resolve_peer
    return await self.storage.get_peer_by_id(peer_id)
           ^^^^^^^^^^^^^^^^^^^^^^^^^^^^^^^^^^^^^^^^^^
  File "/workspace/venv/lib/python3.13/site-packages/pyrogram/storage/sqlite_storage.py", line 142, in get_peer_by_id
    raise KeyError(f"ID not found: {peer_id}")
KeyError: 'ID not found: -1002725376687'

During handling of the above exception, another exception occurred:

Traceback (most recent call last):
  File "/workspace/venv/lib/python3.13/site-packages/pyrogram/client.py", line 569, in handle_updates
    channel=await self.resolve_peer(utils.get_channel_id(channel_id)),
            ^^^^^^^^^^^^^^^^^^^^^^^^^^^^^^^^^^^^^^^^^^^^^^^^^^^^^^^^^
  File "/workspace/venv/lib/python3.13/site-packages/pyrogram/methods/advanced/resolve_peer.py", line 89, in resolve_peer
    peer_type = utils.get_peer_type(peer_id)
  File "/workspace/venv/lib/python3.13/site-packages/pyrogram/utils.py", line 246, in get_peer_type
    raise ValueError(f"Peer id invalid: {peer_id}")
ValueError: Peer id invalid: -1002725376687
[16-Aug-25 03:16:25 - ERROR] - asyncio - Task exception was never retrieved
future: <Task finished name='Task-1183' coro=<Client.handle_updates() done, defined at /workspace/venv/lib/python3.13/site-packages/pyrogram/client.py:535> exception=ValueError('Peer id invalid: -1002725376687')>
Traceback (most recent call last):
  File "/workspace/venv/lib/python3.13/site-packages/pyrogram/methods/advanced/resolve_peer.py", line 62, in resolve_peer
    return await self.storage.get_peer_by_id(peer_id)
           ^^^^^^^^^^^^^^^^^^^^^^^^^^^^^^^^^^^^^^^^^^
  File "/workspace/venv/lib/python3.13/site-packages/pyrogram/storage/sqlite_storage.py", line 142, in get_peer_by_id
    raise KeyError(f"ID not found: {peer_id}")
KeyError: 'ID not found: -1002725376687'

During handling of the above exception, another exception occurred:

Traceback (most recent call last):
  File "/workspace/venv/lib/python3.13/site-packages/pyrogram/client.py", line 569, in handle_updates
    channel=await self.resolve_peer(utils.get_channel_id(channel_id)),
            ^^^^^^^^^^^^^^^^^^^^^^^^^^^^^^^^^^^^^^^^^^^^^^^^^^^^^^^^^
  File "/workspace/venv/lib/python3.13/site-packages/pyrogram/methods/advanced/resolve_peer.py", line 89, in resolve_peer
    peer_type = utils.get_peer_type(peer_id)
  File "/workspace/venv/lib/python3.13/site-packages/pyrogram/utils.py", line 246, in get_peer_type
    raise ValueError(f"Peer id invalid: {peer_id}")
ValueError: Peer id invalid: -1002725376687
[16-Aug-25 03:16:39 - ERROR] - asyncio - Task exception was never retrieved
future: <Task finished name='Task-1206' coro=<Client.handle_updates() done, defined at /workspace/venv/lib/python3.13/site-packages/pyrogram/client.py:535> exception=ValueError('Peer id invalid: -1002725376687')>
Traceback (most recent call last):
  File "/workspace/venv/lib/python3.13/site-packages/pyrogram/methods/advanced/resolve_peer.py", line 62, in resolve_peer
    return await self.storage.get_peer_by_id(peer_id)
           ^^^^^^^^^^^^^^^^^^^^^^^^^^^^^^^^^^^^^^^^^^
  File "/workspace/venv/lib/python3.13/site-packages/pyrogram/storage/sqlite_storage.py", line 142, in get_peer_by_id
    raise KeyError(f"ID not found: {peer_id}")
KeyError: 'ID not found: -1002725376687'

During handling of the above exception, another exception occurred:

Traceback (most recent call last):
  File "/workspace/venv/lib/python3.13/site-packages/pyrogram/client.py", line 569, in handle_updates
    channel=await self.resolve_peer(utils.get_channel_id(channel_id)),
            ^^^^^^^^^^^^^^^^^^^^^^^^^^^^^^^^^^^^^^^^^^^^^^^^^^^^^^^^^
  File "/workspace/venv/lib/python3.13/site-packages/pyrogram/methods/advanced/resolve_peer.py", line 89, in resolve_peer
    peer_type = utils.get_peer_type(peer_id)
  File "/workspace/venv/lib/python3.13/site-packages/pyrogram/utils.py", line 246, in get_peer_type
    raise ValueError(f"Peer id invalid: {peer_id}")
ValueError: Peer id invalid: -1002725376687
[16-Aug-25 03:16:45 - ERROR] - asyncio - Task exception was never retrieved
future: <Task finished name='Task-1218' coro=<Client.handle_updates() done, defined at /workspace/venv/lib/python3.13/site-packages/pyrogram/client.py:535> exception=ValueError('Peer id invalid: -1002701086502')>
Traceback (most recent call last):
  File "/workspace/venv/lib/python3.13/site-packages/pyrogram/methods/advanced/resolve_peer.py", line 62, in resolve_peer
    return await self.storage.get_peer_by_id(peer_id)
           ^^^^^^^^^^^^^^^^^^^^^^^^^^^^^^^^^^^^^^^^^^
  File "/workspace/venv/lib/python3.13/site-packages/pyrogram/storage/sqlite_storage.py", line 142, in get_peer_by_id
    raise KeyError(f"ID not found: {peer_id}")
KeyError: 'ID not found: -1002701086502'

During handling of the above exception, another exception occurred:

Traceback (most recent call last):
  File "/workspace/venv/lib/python3.13/site-packages/pyrogram/client.py", line 569, in handle_updates
    channel=await self.resolve_peer(utils.get_channel_id(channel_id)),
            ^^^^^^^^^^^^^^^^^^^^^^^^^^^^^^^^^^^^^^^^^^^^^^^^^^^^^^^^^
  File "/workspace/venv/lib/python3.13/site-packages/pyrogram/methods/advanced/resolve_peer.py", line 89, in resolve_peer
    peer_type = utils.get_peer_type(peer_id)
  File "/workspace/venv/lib/python3.13/site-packages/pyrogram/utils.py", line 246, in get_peer_type
    raise ValueError(f"Peer id invalid: {peer_id}")
ValueError: Peer id invalid: -1002701086502
[16-Aug-25 03:16:45 - ERROR] - asyncio - Task exception was never retrieved
future: <Task finished name='Task-1220' coro=<Client.handle_updates() done, defined at /workspace/venv/lib/python3.13/site-packages/pyrogram/client.py:535> exception=ValueError('Peer id invalid: -1002701086502')>
Traceback (most recent call last):
  File "/workspace/venv/lib/python3.13/site-packages/pyrogram/methods/advanced/resolve_peer.py", line 62, in resolve_peer
    return await self.storage.get_peer_by_id(peer_id)
           ^^^^^^^^^^^^^^^^^^^^^^^^^^^^^^^^^^^^^^^^^^
  File "/workspace/venv/lib/python3.13/site-packages/pyrogram/storage/sqlite_storage.py", line 142, in get_peer_by_id
    raise KeyError(f"ID not found: {peer_id}")
KeyError: 'ID not found: -1002701086502'

During handling of the above exception, another exception occurred:

Traceback (most recent call last):
  File "/workspace/venv/lib/python3.13/site-packages/pyrogram/client.py", line 569, in handle_updates
    channel=await self.resolve_peer(utils.get_channel_id(channel_id)),
            ^^^^^^^^^^^^^^^^^^^^^^^^^^^^^^^^^^^^^^^^^^^^^^^^^^^^^^^^^
  File "/workspace/venv/lib/python3.13/site-packages/pyrogram/methods/advanced/resolve_peer.py", line 89, in resolve_peer
    peer_type = utils.get_peer_type(peer_id)
  File "/workspace/venv/lib/python3.13/site-packages/pyrogram/utils.py", line 246, in get_peer_type
    raise ValueError(f"Peer id invalid: {peer_id}")
ValueError: Peer id invalid: -1002701086502
[16-Aug-25 03:16:47 - ERROR] - asyncio - Task exception was never retrieved
future: <Task finished name='Task-1225' coro=<Client.handle_updates() done, defined at /workspace/venv/lib/python3.13/site-packages/pyrogram/client.py:535> exception=ValueError('Peer id invalid: -1002402484000')>
Traceback (most recent call last):
  File "/workspace/venv/lib/python3.13/site-packages/pyrogram/methods/advanced/resolve_peer.py", line 62, in resolve_peer
    return await self.storage.get_peer_by_id(peer_id)
           ^^^^^^^^^^^^^^^^^^^^^^^^^^^^^^^^^^^^^^^^^^
  File "/workspace/venv/lib/python3.13/site-packages/pyrogram/storage/sqlite_storage.py", line 142, in get_peer_by_id
    raise KeyError(f"ID not found: {peer_id}")
KeyError: 'ID not found: -1002402484000'

During handling of the above exception, another exception occurred:

Traceback (most recent call last):
  File "/workspace/venv/lib/python3.13/site-packages/pyrogram/client.py", line 569, in handle_updates
    channel=await self.resolve_peer(utils.get_channel_id(channel_id)),
            ^^^^^^^^^^^^^^^^^^^^^^^^^^^^^^^^^^^^^^^^^^^^^^^^^^^^^^^^^
  File "/workspace/venv/lib/python3.13/site-packages/pyrogram/methods/advanced/resolve_peer.py", line 89, in resolve_peer
    peer_type = utils.get_peer_type(peer_id)
  File "/workspace/venv/lib/python3.13/site-packages/pyrogram/utils.py", line 246, in get_peer_type
    raise ValueError(f"Peer id invalid: {peer_id}")
ValueError: Peer id invalid: -1002402484000
[16-Aug-25 03:16:55 - ERROR] - asyncio - Task exception was never retrieved
future: <Task finished name='Task-1244' coro=<Client.handle_updates() done, defined at /workspace/venv/lib/python3.13/site-packages/pyrogram/client.py:535> exception=ValueError('Peer id invalid: -1002402484000')>
Traceback (most recent call last):
  File "/workspace/venv/lib/python3.13/site-packages/pyrogram/methods/advanced/resolve_peer.py", line 62, in resolve_peer
    return await self.storage.get_peer_by_id(peer_id)
           ^^^^^^^^^^^^^^^^^^^^^^^^^^^^^^^^^^^^^^^^^^
  File "/workspace/venv/lib/python3.13/site-packages/pyrogram/storage/sqlite_storage.py", line 142, in get_peer_by_id
    raise KeyError(f"ID not found: {peer_id}")
KeyError: 'ID not found: -1002402484000'

During handling of the above exception, another exception occurred:

Traceback (most recent call last):
  File "/workspace/venv/lib/python3.13/site-packages/pyrogram/client.py", line 569, in handle_updates
    channel=await self.resolve_peer(utils.get_channel_id(channel_id)),
            ^^^^^^^^^^^^^^^^^^^^^^^^^^^^^^^^^^^^^^^^^^^^^^^^^^^^^^^^^
  File "/workspace/venv/lib/python3.13/site-packages/pyrogram/methods/advanced/resolve_peer.py", line 89, in resolve_peer
    peer_type = utils.get_peer_type(peer_id)
  File "/workspace/venv/lib/python3.13/site-packages/pyrogram/utils.py", line 246, in get_peer_type
    raise ValueError(f"Peer id invalid: {peer_id}")
ValueError: Peer id invalid: -1002402484000
[16-Aug-25 03:17:00 - ERROR] - asyncio - Task exception was never retrieved
future: <Task finished name='Task-1260' coro=<Client.handle_updates() done, defined at /workspace/venv/lib/python3.13/site-packages/pyrogram/client.py:535> exception=ValueError('Peer id invalid: -1002402484000')>
Traceback (most recent call last):
  File "/workspace/venv/lib/python3.13/site-packages/pyrogram/methods/advanced/resolve_peer.py", line 62, in resolve_peer
    return await self.storage.get_peer_by_id(peer_id)
           ^^^^^^^^^^^^^^^^^^^^^^^^^^^^^^^^^^^^^^^^^^
  File "/workspace/venv/lib/python3.13/site-packages/pyrogram/storage/sqlite_storage.py", line 142, in get_peer_by_id
    raise KeyError(f"ID not found: {peer_id}")
KeyError: 'ID not found: -1002402484000'

During handling of the above exception, another exception occurred:

Traceback (most recent call last):
  File "/workspace/venv/lib/python3.13/site-packages/pyrogram/client.py", line 569, in handle_updates
    channel=await self.resolve_peer(utils.get_channel_id(channel_id)),
            ^^^^^^^^^^^^^^^^^^^^^^^^^^^^^^^^^^^^^^^^^^^^^^^^^^^^^^^^^
  File "/workspace/venv/lib/python3.13/site-packages/pyrogram/methods/advanced/resolve_peer.py", line 89, in resolve_peer
    peer_type = utils.get_peer_type(peer_id)
  File "/workspace/venv/lib/python3.13/site-packages/pyrogram/utils.py", line 246, in get_peer_type
    raise ValueError(f"Peer id invalid: {peer_id}")
ValueError: Peer id invalid: -1002402484000
[16-Aug-25 03:17:00 - ERROR] - asyncio - Task exception was never retrieved
future: <Task finished name='Task-1262' coro=<Client.handle_updates() done, defined at /workspace/venv/lib/python3.13/site-packages/pyrogram/client.py:535> exception=ValueError('Peer id invalid: -1002402484000')>
Traceback (most recent call last):
  File "/workspace/venv/lib/python3.13/site-packages/pyrogram/methods/advanced/resolve_peer.py", line 62, in resolve_peer
    return await self.storage.get_peer_by_id(peer_id)
           ^^^^^^^^^^^^^^^^^^^^^^^^^^^^^^^^^^^^^^^^^^
  File "/workspace/venv/lib/python3.13/site-packages/pyrogram/storage/sqlite_storage.py", line 142, in get_peer_by_id
    raise KeyError(f"ID not found: {peer_id}")
KeyError: 'ID not found: -1002402484000'

During handling of the above exception, another exception occurred:

Traceback (most recent call last):
  File "/workspace/venv/lib/python3.13/site-packages/pyrogram/client.py", line 569, in handle_updates
    channel=await self.resolve_peer(utils.get_channel_id(channel_id)),
            ^^^^^^^^^^^^^^^^^^^^^^^^^^^^^^^^^^^^^^^^^^^^^^^^^^^^^^^^^
  File "/workspace/venv/lib/python3.13/site-packages/pyrogram/methods/advanced/resolve_peer.py", line 89, in resolve_peer
    peer_type = utils.get_peer_type(peer_id)
  File "/workspace/venv/lib/python3.13/site-packages/pyrogram/utils.py", line 246, in get_peer_type
    raise ValueError(f"Peer id invalid: {peer_id}")
ValueError: Peer id invalid: -1002402484000
[16-Aug-25 03:17:01 - ERROR] - asyncio - Task exception was never retrieved
future: <Task finished name='Task-1264' coro=<Client.handle_updates() done, defined at /workspace/venv/lib/python3.13/site-packages/pyrogram/client.py:535> exception=ValueError('Peer id invalid: -1002725376687')>
Traceback (most recent call last):
  File "/workspace/venv/lib/python3.13/site-packages/pyrogram/methods/advanced/resolve_peer.py", line 62, in resolve_peer
    return await self.storage.get_peer_by_id(peer_id)
           ^^^^^^^^^^^^^^^^^^^^^^^^^^^^^^^^^^^^^^^^^^
  File "/workspace/venv/lib/python3.13/site-packages/pyrogram/storage/sqlite_storage.py", line 142, in get_peer_by_id
    raise KeyError(f"ID not found: {peer_id}")
KeyError: 'ID not found: -1002725376687'

During handling of the above exception, another exception occurred:

Traceback (most recent call last):
  File "/workspace/venv/lib/python3.13/site-packages/pyrogram/client.py", line 569, in handle_updates
    channel=await self.resolve_peer(utils.get_channel_id(channel_id)),
            ^^^^^^^^^^^^^^^^^^^^^^^^^^^^^^^^^^^^^^^^^^^^^^^^^^^^^^^^^
  File "/workspace/venv/lib/python3.13/site-packages/pyrogram/methods/advanced/resolve_peer.py", line 89, in resolve_peer
    peer_type = utils.get_peer_type(peer_id)
  File "/workspace/venv/lib/python3.13/site-packages/pyrogram/utils.py", line 246, in get_peer_type
    raise ValueError(f"Peer id invalid: {peer_id}")
ValueError: Peer id invalid: -1002725376687
[16-Aug-25 03:17:04 - ERROR] - asyncio - Task exception was never retrieved
future: <Task finished name='Task-1280' coro=<Client.handle_updates() done, defined at /workspace/venv/lib/python3.13/site-packages/pyrogram/client.py:535> exception=ValueError('Peer id invalid: -1002725376687')>
Traceback (most recent call last):
  File "/workspace/venv/lib/python3.13/site-packages/pyrogram/methods/advanced/resolve_peer.py", line 62, in resolve_peer
    return await self.storage.get_peer_by_id(peer_id)
           ^^^^^^^^^^^^^^^^^^^^^^^^^^^^^^^^^^^^^^^^^^
  File "/workspace/venv/lib/python3.13/site-packages/pyrogram/storage/sqlite_storage.py", line 142, in get_peer_by_id
    raise KeyError(f"ID not found: {peer_id}")
KeyError: 'ID not found: -1002725376687'

During handling of the above exception, another exception occurred:

Traceback (most recent call last):
  File "/workspace/venv/lib/python3.13/site-packages/pyrogram/client.py", line 569, in handle_updates
    channel=await self.resolve_peer(utils.get_channel_id(channel_id)),
            ^^^^^^^^^^^^^^^^^^^^^^^^^^^^^^^^^^^^^^^^^^^^^^^^^^^^^^^^^
  File "/workspace/venv/lib/python3.13/site-packages/pyrogram/methods/advanced/resolve_peer.py", line 89, in resolve_peer
    peer_type = utils.get_peer_type(peer_id)
  File "/workspace/venv/lib/python3.13/site-packages/pyrogram/utils.py", line 246, in get_peer_type
    raise ValueError(f"Peer id invalid: {peer_id}")
ValueError: Peer id invalid: -1002725376687
[16-Aug-25 03:17:12 - ERROR] - asyncio - Task exception was never retrieved
future: <Task finished name='Task-1301' coro=<Client.handle_updates() done, defined at /workspace/venv/lib/python3.13/site-packages/pyrogram/client.py:535> exception=ValueError('Peer id invalid: -1002725376687')>
Traceback (most recent call last):
  File "/workspace/venv/lib/python3.13/site-packages/pyrogram/methods/advanced/resolve_peer.py", line 62, in resolve_peer
    return await self.storage.get_peer_by_id(peer_id)
           ^^^^^^^^^^^^^^^^^^^^^^^^^^^^^^^^^^^^^^^^^^
  File "/workspace/venv/lib/python3.13/site-packages/pyrogram/storage/sqlite_storage.py", line 142, in get_peer_by_id
    raise KeyError(f"ID not found: {peer_id}")
KeyError: 'ID not found: -1002725376687'

During handling of the above exception, another exception occurred:

Traceback (most recent call last):
  File "/workspace/venv/lib/python3.13/site-packages/pyrogram/client.py", line 569, in handle_updates
    channel=await self.resolve_peer(utils.get_channel_id(channel_id)),
            ^^^^^^^^^^^^^^^^^^^^^^^^^^^^^^^^^^^^^^^^^^^^^^^^^^^^^^^^^
  File "/workspace/venv/lib/python3.13/site-packages/pyrogram/methods/advanced/resolve_peer.py", line 89, in resolve_peer
    peer_type = utils.get_peer_type(peer_id)
  File "/workspace/venv/lib/python3.13/site-packages/pyrogram/utils.py", line 246, in get_peer_type
    raise ValueError(f"Peer id invalid: {peer_id}")
ValueError: Peer id invalid: -1002725376687
[16-Aug-25 03:17:25 - ERROR] - asyncio - Task exception was never retrieved
future: <Task finished name='Task-1322' coro=<Client.handle_updates() done, defined at /workspace/venv/lib/python3.13/site-packages/pyrogram/client.py:535> exception=ValueError('Peer id invalid: -1002738424718')>
Traceback (most recent call last):
  File "/workspace/venv/lib/python3.13/site-packages/pyrogram/methods/advanced/resolve_peer.py", line 62, in resolve_peer
    return await self.storage.get_peer_by_id(peer_id)
           ^^^^^^^^^^^^^^^^^^^^^^^^^^^^^^^^^^^^^^^^^^
  File "/workspace/venv/lib/python3.13/site-packages/pyrogram/storage/sqlite_storage.py", line 142, in get_peer_by_id
    raise KeyError(f"ID not found: {peer_id}")
KeyError: 'ID not found: -1002738424718'

During handling of the above exception, another exception occurred:

Traceback (most recent call last):
  File "/workspace/venv/lib/python3.13/site-packages/pyrogram/client.py", line 569, in handle_updates
    channel=await self.resolve_peer(utils.get_channel_id(channel_id)),
            ^^^^^^^^^^^^^^^^^^^^^^^^^^^^^^^^^^^^^^^^^^^^^^^^^^^^^^^^^
  File "/workspace/venv/lib/python3.13/site-packages/pyrogram/methods/advanced/resolve_peer.py", line 89, in resolve_peer
    peer_type = utils.get_peer_type(peer_id)
  File "/workspace/venv/lib/python3.13/site-packages/pyrogram/utils.py", line 246, in get_peer_type
    raise ValueError(f"Peer id invalid: {peer_id}")
ValueError: Peer id invalid: -1002738424718
[16-Aug-25 03:17:29 - ERROR] - asyncio - Task exception was never retrieved
future: <Task finished name='Task-1328' coro=<Client.handle_updates() done, defined at /workspace/venv/lib/python3.13/site-packages/pyrogram/client.py:535> exception=ValueError('Peer id invalid: -1002725376687')>
Traceback (most recent call last):
  File "/workspace/venv/lib/python3.13/site-packages/pyrogram/methods/advanced/resolve_peer.py", line 62, in resolve_peer
    return await self.storage.get_peer_by_id(peer_id)
           ^^^^^^^^^^^^^^^^^^^^^^^^^^^^^^^^^^^^^^^^^^
  File "/workspace/venv/lib/python3.13/site-packages/pyrogram/storage/sqlite_storage.py", line 142, in get_peer_by_id
    raise KeyError(f"ID not found: {peer_id}")
KeyError: 'ID not found: -1002725376687'

During handling of the above exception, another exception occurred:

Traceback (most recent call last):
  File "/workspace/venv/lib/python3.13/site-packages/pyrogram/client.py", line 569, in handle_updates
    channel=await self.resolve_peer(utils.get_channel_id(channel_id)),
            ^^^^^^^^^^^^^^^^^^^^^^^^^^^^^^^^^^^^^^^^^^^^^^^^^^^^^^^^^
  File "/workspace/venv/lib/python3.13/site-packages/pyrogram/methods/advanced/resolve_peer.py", line 89, in resolve_peer
    peer_type = utils.get_peer_type(peer_id)
  File "/workspace/venv/lib/python3.13/site-packages/pyrogram/utils.py", line 246, in get_peer_type
    raise ValueError(f"Peer id invalid: {peer_id}")
ValueError: Peer id invalid: -1002725376687
[16-Aug-25 03:17:35 - ERROR] - asyncio - Task exception was never retrieved
future: <Task finished name='Task-1338' coro=<Client.handle_updates() done, defined at /workspace/venv/lib/python3.13/site-packages/pyrogram/client.py:535> exception=ValueError('Peer id invalid: -1002725376687')>
Traceback (most recent call last):
  File "/workspace/venv/lib/python3.13/site-packages/pyrogram/methods/advanced/resolve_peer.py", line 62, in resolve_peer
    return await self.storage.get_peer_by_id(peer_id)
           ^^^^^^^^^^^^^^^^^^^^^^^^^^^^^^^^^^^^^^^^^^
  File "/workspace/venv/lib/python3.13/site-packages/pyrogram/storage/sqlite_storage.py", line 142, in get_peer_by_id
    raise KeyError(f"ID not found: {peer_id}")
KeyError: 'ID not found: -1002725376687'

During handling of the above exception, another exception occurred:

Traceback (most recent call last):
  File "/workspace/venv/lib/python3.13/site-packages/pyrogram/client.py", line 569, in handle_updates
    channel=await self.resolve_peer(utils.get_channel_id(channel_id)),
            ^^^^^^^^^^^^^^^^^^^^^^^^^^^^^^^^^^^^^^^^^^^^^^^^^^^^^^^^^
  File "/workspace/venv/lib/python3.13/site-packages/pyrogram/methods/advanced/resolve_peer.py", line 89, in resolve_peer
    peer_type = utils.get_peer_type(peer_id)
  File "/workspace/venv/lib/python3.13/site-packages/pyrogram/utils.py", line 246, in get_peer_type
    raise ValueError(f"Peer id invalid: {peer_id}")
ValueError: Peer id invalid: -1002725376687
[16-Aug-25 03:17:43 - ERROR] - asyncio - Task exception was never retrieved
future: <Task finished name='Task-1346' coro=<Client.handle_updates() done, defined at /workspace/venv/lib/python3.13/site-packages/pyrogram/client.py:535> exception=ValueError('Peer id invalid: -1002725376687')>
Traceback (most recent call last):
  File "/workspace/venv/lib/python3.13/site-packages/pyrogram/methods/advanced/resolve_peer.py", line 62, in resolve_peer
    return await self.storage.get_peer_by_id(peer_id)
           ^^^^^^^^^^^^^^^^^^^^^^^^^^^^^^^^^^^^^^^^^^
  File "/workspace/venv/lib/python3.13/site-packages/pyrogram/storage/sqlite_storage.py", line 142, in get_peer_by_id
    raise KeyError(f"ID not found: {peer_id}")
KeyError: 'ID not found: -1002725376687'

During handling of the above exception, another exception occurred:

Traceback (most recent call last):
  File "/workspace/venv/lib/python3.13/site-packages/pyrogram/client.py", line 569, in handle_updates
    channel=await self.resolve_peer(utils.get_channel_id(channel_id)),
            ^^^^^^^^^^^^^^^^^^^^^^^^^^^^^^^^^^^^^^^^^^^^^^^^^^^^^^^^^
  File "/workspace/venv/lib/python3.13/site-packages/pyrogram/methods/advanced/resolve_peer.py", line 89, in resolve_peer
    peer_type = utils.get_peer_type(peer_id)
  File "/workspace/venv/lib/python3.13/site-packages/pyrogram/utils.py", line 246, in get_peer_type
    raise ValueError(f"Peer id invalid: {peer_id}")
ValueError: Peer id invalid: -1002725376687
[16-Aug-25 03:17:49 - ERROR] - asyncio - Task exception was never retrieved
future: <Task finished name='Task-1361' coro=<Client.handle_updates() done, defined at /workspace/venv/lib/python3.13/site-packages/pyrogram/client.py:535> exception=ValueError('Peer id invalid: -1002474305961')>
Traceback (most recent call last):
  File "/workspace/venv/lib/python3.13/site-packages/pyrogram/methods/advanced/resolve_peer.py", line 62, in resolve_peer
    return await self.storage.get_peer_by_id(peer_id)
           ^^^^^^^^^^^^^^^^^^^^^^^^^^^^^^^^^^^^^^^^^^
  File "/workspace/venv/lib/python3.13/site-packages/pyrogram/storage/sqlite_storage.py", line 142, in get_peer_by_id
    raise KeyError(f"ID not found: {peer_id}")
KeyError: 'ID not found: -1002474305961'

During handling of the above exception, another exception occurred:

Traceback (most recent call last):
  File "/workspace/venv/lib/python3.13/site-packages/pyrogram/client.py", line 569, in handle_updates
    channel=await self.resolve_peer(utils.get_channel_id(channel_id)),
            ^^^^^^^^^^^^^^^^^^^^^^^^^^^^^^^^^^^^^^^^^^^^^^^^^^^^^^^^^
  File "/workspace/venv/lib/python3.13/site-packages/pyrogram/methods/advanced/resolve_peer.py", line 89, in resolve_peer
    peer_type = utils.get_peer_type(peer_id)
  File "/workspace/venv/lib/python3.13/site-packages/pyrogram/utils.py", line 246, in get_peer_type
    raise ValueError(f"Peer id invalid: {peer_id}")
ValueError: Peer id invalid: -1002474305961
